2022-11-24 03:15:50,314 INFO org.apache.hadoop.yarn.server.resourcemanager.ResourceManager: STARTUP_MSG: 
/************************************************************
STARTUP_MSG: Starting ResourceManager
STARTUP_MSG:   host = ip-172-31-11-48/172.31.11.48
STARTUP_MSG:   args = []
STARTUP_MSG:   version = 2.6.5
STARTUP_MSG:   build = https://github.com/apache/hadoop.git -r e8c9fe0b4c252caf2ebf1464220599650f119997; compiled by 'sjlee' on 2016-10-02T23:43Z
STARTUP_MSG:   java = 1.8.0_352
************************************************************/
2022-11-24 03:15:50,321 INFO org.apache.hadoop.yarn.server.resourcemanager.ResourceManager: registered UNIX signal handlers for [TERM, HUP, INT]
2022-11-24 03:15:50,560 INFO org.apache.hadoop.conf.Configuration: found resource core-site.xml at file:/usr/local/hadoop/etc/hadoop/core-site.xml
2022-11-24 03:15:50,619 INFO org.apache.hadoop.security.Groups: clearing userToGroupsMap cache
2022-11-24 03:15:50,674 INFO org.apache.hadoop.conf.Configuration: found resource yarn-site.xml at file:/usr/local/hadoop/etc/hadoop/yarn-site.xml
2022-11-24 03:15:50,851 INFO org.apache.hadoop.yarn.event.AsyncDispatcher: Registering class org.apache.hadoop.yarn.server.resourcemanager.RMFatalEventType for class org.apache.hadoop.yarn.server.resourcemanager.ResourceManager$RMFatalEventDispatcher
2022-11-24 03:15:50,895 INFO org.apache.hadoop.yarn.server.resourcemanager.security.NMTokenSecretManagerInRM: NMTokenKeyRollingInterval: 86400000ms and NMTokenKeyActivationDelay: 900000ms
2022-11-24 03:15:50,902 INFO org.apache.hadoop.yarn.server.resourcemanager.security.RMContainerTokenSecretManager: ContainerTokenKeyRollingInterval: 86400000ms and ContainerTokenKeyActivationDelay: 900000ms
2022-11-24 03:15:50,906 INFO org.apache.hadoop.yarn.server.resourcemanager.security.AMRMTokenSecretManager: AMRMTokenKeyRollingInterval: 86400000ms and AMRMTokenKeyActivationDelay: 900000 ms
2022-11-24 03:15:50,929 INFO org.apache.hadoop.yarn.event.AsyncDispatcher: Registering class org.apache.hadoop.yarn.server.resourcemanager.recovery.RMStateStoreEventType for class org.apache.hadoop.yarn.server.resourcemanager.recovery.RMStateStore$ForwardingEventHandler
2022-11-24 03:15:50,930 INFO org.apache.hadoop.yarn.event.AsyncDispatcher: Registering class org.apache.hadoop.yarn.server.resourcemanager.NodesListManagerEventType for class org.apache.hadoop.yarn.server.resourcemanager.NodesListManager
2022-11-24 03:15:50,930 INFO org.apache.hadoop.yarn.server.resourcemanager.ResourceManager: Using Scheduler: org.apache.hadoop.yarn.server.resourcemanager.scheduler.capacity.CapacityScheduler
2022-11-24 03:15:50,944 INFO org.apache.hadoop.yarn.event.AsyncDispatcher: Registering class org.apache.hadoop.yarn.server.resourcemanager.scheduler.event.SchedulerEventType for class org.apache.hadoop.yarn.server.resourcemanager.ResourceManager$SchedulerEventDispatcher
2022-11-24 03:15:50,947 INFO org.apache.hadoop.yarn.event.AsyncDispatcher: Registering class org.apache.hadoop.yarn.server.resourcemanager.rmapp.RMAppEventType for class org.apache.hadoop.yarn.server.resourcemanager.ResourceManager$ApplicationEventDispatcher
2022-11-24 03:15:50,947 INFO org.apache.hadoop.yarn.event.AsyncDispatcher: Registering class org.apache.hadoop.yarn.server.resourcemanager.rmapp.attempt.RMAppAttemptEventType for class org.apache.hadoop.yarn.server.resourcemanager.ResourceManager$ApplicationAttemptEventDispatcher
2022-11-24 03:15:50,948 INFO org.apache.hadoop.yarn.event.AsyncDispatcher: Registering class org.apache.hadoop.yarn.server.resourcemanager.rmnode.RMNodeEventType for class org.apache.hadoop.yarn.server.resourcemanager.ResourceManager$NodeEventDispatcher
2022-11-24 03:15:51,011 INFO org.apache.hadoop.metrics2.impl.MetricsConfig: loaded properties from hadoop-metrics2.properties
2022-11-24 03:15:51,114 INFO org.apache.hadoop.metrics2.impl.MetricsSystemImpl: Scheduled snapshot period at 10 second(s).
2022-11-24 03:15:51,114 INFO org.apache.hadoop.metrics2.impl.MetricsSystemImpl: ResourceManager metrics system started
2022-11-24 03:15:51,128 INFO org.apache.hadoop.yarn.event.AsyncDispatcher: Registering class org.apache.hadoop.yarn.server.resourcemanager.RMAppManagerEventType for class org.apache.hadoop.yarn.server.resourcemanager.RMAppManager
2022-11-24 03:15:51,150 INFO org.apache.hadoop.yarn.event.AsyncDispatcher: Registering class org.apache.hadoop.yarn.server.resourcemanager.amlauncher.AMLauncherEventType for class org.apache.hadoop.yarn.server.resourcemanager.amlauncher.ApplicationMasterLauncher
2022-11-24 03:15:51,151 INFO org.apache.hadoop.yarn.server.resourcemanager.RMNMInfo: Registered RMNMInfo MBean
2022-11-24 03:15:51,153 INFO org.apache.hadoop.util.HostsFileReader: Refreshing hosts (include/exclude) list
2022-11-24 03:15:51,156 INFO org.apache.hadoop.conf.Configuration: found resource capacity-scheduler.xml at file:/usr/local/hadoop/etc/hadoop/capacity-scheduler.xml
2022-11-24 03:15:51,214 INFO org.apache.hadoop.yarn.server.resourcemanager.scheduler.capacity.ParentQueue: root, capacity=1.0, asboluteCapacity=1.0, maxCapacity=1.0, asboluteMaxCapacity=1.0, state=RUNNING, acls=SUBMIT_APPLICATIONS:*ADMINISTER_QUEUE:*, labels=*,
, reservationsContinueLooking=true
2022-11-24 03:15:51,214 INFO org.apache.hadoop.yarn.server.resourcemanager.scheduler.capacity.ParentQueue: Initialized parent-queue root name=root, fullname=root
2022-11-24 03:15:51,223 INFO org.apache.hadoop.yarn.server.resourcemanager.scheduler.capacity.LeafQueue: Initializing default
capacity = 1.0 [= (float) configuredCapacity / 100 ]
asboluteCapacity = 1.0 [= parentAbsoluteCapacity * capacity ]
maxCapacity = 1.0 [= configuredMaxCapacity ]
absoluteMaxCapacity = 1.0 [= 1.0 maximumCapacity undefined, (parentAbsoluteMaxCapacity * maximumCapacity) / 100 otherwise ]
userLimit = 100 [= configuredUserLimit ]
userLimitFactor = 1.0 [= configuredUserLimitFactor ]
maxApplications = 10000 [= configuredMaximumSystemApplicationsPerQueue or (int)(configuredMaximumSystemApplications * absoluteCapacity)]
maxApplicationsPerUser = 10000 [= (int)(maxApplications * (userLimit / 100.0f) * userLimitFactor) ]
usedCapacity = 0.0 [= usedResourcesMemory / (clusterResourceMemory * absoluteCapacity)]
absoluteUsedCapacity = 0.0 [= usedResourcesMemory / clusterResourceMemory]
maxAMResourcePerQueuePercent = 0.1 [= configuredMaximumAMResourcePercent ]
minimumAllocationFactor = 0.875 [= (float)(maximumAllocationMemory - minimumAllocationMemory) / maximumAllocationMemory ]
numContainers = 0 [= currentNumContainers ]
state = RUNNING [= configuredState ]
acls = SUBMIT_APPLICATIONS:*ADMINISTER_QUEUE:* [= configuredAcls ]
nodeLocalityDelay = 40
labels=*,
nodeLocalityDelay = 40
reservationsContinueLooking = true

2022-11-24 03:15:51,223 INFO org.apache.hadoop.yarn.server.resourcemanager.scheduler.capacity.CapacityScheduler: Initialized queue: default: capacity=1.0, absoluteCapacity=1.0, usedResources=<memory:0, vCores:0>, usedCapacity=0.0, absoluteUsedCapacity=0.0, numApps=0, numContainers=0
2022-11-24 03:15:51,223 INFO org.apache.hadoop.yarn.server.resourcemanager.scheduler.capacity.CapacityScheduler: Initialized queue: root: numChildQueue= 1, capacity=1.0, absoluteCapacity=1.0, usedResources=<memory:0, vCores:0>usedCapacity=0.0, numApps=0, numContainers=0
2022-11-24 03:15:51,224 INFO org.apache.hadoop.yarn.server.resourcemanager.scheduler.capacity.CapacityScheduler: Initialized root queue root: numChildQueue= 1, capacity=1.0, absoluteCapacity=1.0, usedResources=<memory:0, vCores:0>usedCapacity=0.0, numApps=0, numContainers=0
2022-11-24 03:15:51,224 INFO org.apache.hadoop.yarn.server.resourcemanager.scheduler.capacity.CapacityScheduler: Initialized queue mappings, override: false
2022-11-24 03:15:51,225 INFO org.apache.hadoop.yarn.server.resourcemanager.scheduler.capacity.CapacityScheduler: Initialized CapacityScheduler with calculator=class org.apache.hadoop.yarn.util.resource.DefaultResourceCalculator, minimumAllocation=<<memory:1024, vCores:1>>, maximumAllocation=<<memory:8192, vCores:32>>, asynchronousScheduling=false, asyncScheduleInterval=5ms
2022-11-24 03:15:51,233 INFO org.apache.hadoop.yarn.server.resourcemanager.metrics.SystemMetricsPublisher: YARN system metrics publishing service is not enabled
2022-11-24 03:15:51,233 INFO org.apache.hadoop.yarn.server.resourcemanager.ResourceManager: Transitioning to active state
2022-11-24 03:15:51,245 INFO org.apache.hadoop.yarn.server.resourcemanager.security.RMContainerTokenSecretManager: Rolling master-key for container-tokens
2022-11-24 03:15:51,245 INFO org.apache.hadoop.yarn.server.resourcemanager.security.NMTokenSecretManagerInRM: Rolling master-key for nm-tokens
2022-11-24 03:15:51,245 INFO org.apache.hadoop.security.token.delegation.AbstractDelegationTokenSecretManager: Updating the current master key for generating delegation tokens
2022-11-24 03:15:51,246 INFO org.apache.hadoop.yarn.server.resourcemanager.security.RMDelegationTokenSecretManager: storing master key with keyID 1
2022-11-24 03:15:51,248 INFO org.apache.hadoop.security.token.delegation.AbstractDelegationTokenSecretManager: Starting expired delegation token remover thread, tokenRemoverScanInterval=60 min(s)
2022-11-24 03:15:51,248 INFO org.apache.hadoop.security.token.delegation.AbstractDelegationTokenSecretManager: Updating the current master key for generating delegation tokens
2022-11-24 03:15:51,248 INFO org.apache.hadoop.yarn.server.resourcemanager.security.RMDelegationTokenSecretManager: storing master key with keyID 2
2022-11-24 03:15:51,271 INFO org.apache.hadoop.ipc.CallQueueManager: Using callQueue: class java.util.concurrent.LinkedBlockingQueue queueCapacity: 5000
2022-11-24 03:15:51,282 INFO org.apache.hadoop.ipc.Server: Starting Socket Reader #1 for port 8031
2022-11-24 03:15:51,299 INFO org.apache.hadoop.yarn.factories.impl.pb.RpcServerFactoryPBImpl: Adding protocol org.apache.hadoop.yarn.server.api.ResourceTrackerPB to the server
2022-11-24 03:15:51,302 INFO org.apache.hadoop.ipc.Server: IPC Server Responder: starting
2022-11-24 03:15:51,305 INFO org.apache.hadoop.ipc.Server: IPC Server listener on 8031: starting
2022-11-24 03:15:51,330 INFO org.apache.hadoop.ipc.CallQueueManager: Using callQueue: class java.util.concurrent.LinkedBlockingQueue queueCapacity: 5000
2022-11-24 03:15:51,335 INFO org.apache.hadoop.ipc.Server: Starting Socket Reader #1 for port 8030
2022-11-24 03:15:51,343 INFO org.apache.hadoop.yarn.factories.impl.pb.RpcServerFactoryPBImpl: Adding protocol org.apache.hadoop.yarn.api.ApplicationMasterProtocolPB to the server
2022-11-24 03:15:51,343 INFO org.apache.hadoop.ipc.Server: IPC Server Responder: starting
2022-11-24 03:15:51,344 INFO org.apache.hadoop.ipc.Server: IPC Server listener on 8030: starting
2022-11-24 03:15:51,404 INFO org.apache.hadoop.ipc.CallQueueManager: Using callQueue: class java.util.concurrent.LinkedBlockingQueue queueCapacity: 5000
2022-11-24 03:15:51,405 INFO org.apache.hadoop.ipc.Server: Starting Socket Reader #1 for port 8032
2022-11-24 03:15:51,406 INFO org.apache.hadoop.yarn.factories.impl.pb.RpcServerFactoryPBImpl: Adding protocol org.apache.hadoop.yarn.api.ApplicationClientProtocolPB to the server
2022-11-24 03:15:51,407 INFO org.apache.hadoop.ipc.Server: IPC Server Responder: starting
2022-11-24 03:15:51,407 INFO org.apache.hadoop.ipc.Server: IPC Server listener on 8032: starting
2022-11-24 03:15:51,422 INFO org.apache.hadoop.yarn.server.resourcemanager.ResourceManager: Transitioned to active state
2022-11-24 03:15:51,473 INFO org.mortbay.log: Logging to org.slf4j.impl.Log4jLoggerAdapter(org.mortbay.log) via org.mortbay.log.Slf4jLog
2022-11-24 03:15:51,476 INFO org.apache.hadoop.http.HttpRequestLog: Http request log for http.requests.resourcemanager is not defined
2022-11-24 03:15:51,485 INFO org.apache.hadoop.http.HttpServer2: Added global filter 'safety' (class=org.apache.hadoop.http.HttpServer2$QuotingInputFilter)
2022-11-24 03:15:51,491 INFO org.apache.hadoop.http.HttpServer2: Added filter RMAuthenticationFilter (class=org.apache.hadoop.yarn.server.security.http.RMAuthenticationFilter) to context cluster
2022-11-24 03:15:51,491 INFO org.apache.hadoop.http.HttpServer2: Added filter RMAuthenticationFilter (class=org.apache.hadoop.yarn.server.security.http.RMAuthenticationFilter) to context static
2022-11-24 03:15:51,491 INFO org.apache.hadoop.http.HttpServer2: Added filter RMAuthenticationFilter (class=org.apache.hadoop.yarn.server.security.http.RMAuthenticationFilter) to context logs
2022-11-24 03:15:51,492 INFO org.apache.hadoop.http.HttpServer2: Added filter static_user_filter (class=org.apache.hadoop.http.lib.StaticUserWebFilter$StaticUserFilter) to context cluster
2022-11-24 03:15:51,492 INFO org.apache.hadoop.http.HttpServer2: Added filter static_user_filter (class=org.apache.hadoop.http.lib.StaticUserWebFilter$StaticUserFilter) to context static
2022-11-24 03:15:51,492 INFO org.apache.hadoop.http.HttpServer2: Added filter static_user_filter (class=org.apache.hadoop.http.lib.StaticUserWebFilter$StaticUserFilter) to context logs
2022-11-24 03:15:51,495 INFO org.apache.hadoop.http.HttpServer2: adding path spec: /cluster/*
2022-11-24 03:15:51,495 INFO org.apache.hadoop.http.HttpServer2: adding path spec: /ws/*
2022-11-24 03:15:51,504 INFO org.apache.hadoop.http.HttpServer2: Jetty bound to port 8088
2022-11-24 03:15:51,504 INFO org.mortbay.log: jetty-6.1.26
2022-11-24 03:15:51,525 INFO org.mortbay.log: Extract jar:file:/usr/local/hadoop/share/hadoop/yarn/hadoop-yarn-common-2.6.5.jar!/webapps/cluster to /tmp/Jetty_172_31_11_48_8088_cluster____.cj96d9/webapp
2022-11-24 03:15:51,670 INFO org.apache.hadoop.security.token.delegation.AbstractDelegationTokenSecretManager: Updating the current master key for generating delegation tokens
2022-11-24 03:15:51,670 INFO org.apache.hadoop.security.token.delegation.AbstractDelegationTokenSecretManager: Starting expired delegation token remover thread, tokenRemoverScanInterval=60 min(s)
2022-11-24 03:15:51,671 INFO org.apache.hadoop.security.token.delegation.AbstractDelegationTokenSecretManager: Updating the current master key for generating delegation tokens
2022-11-24 03:15:51,695 INFO org.apache.hadoop.security.token.delegation.AbstractDelegationTokenSecretManager: Updating the current master key for generating delegation tokens
2022-11-24 03:15:51,695 INFO org.apache.hadoop.security.token.delegation.AbstractDelegationTokenSecretManager: Starting expired delegation token remover thread, tokenRemoverScanInterval=60 min(s)
2022-11-24 03:15:51,696 INFO org.apache.hadoop.security.token.delegation.AbstractDelegationTokenSecretManager: Updating the current master key for generating delegation tokens
2022-11-24 03:15:51,698 INFO org.apache.hadoop.security.token.delegation.AbstractDelegationTokenSecretManager: Updating the current master key for generating delegation tokens
2022-11-24 03:15:51,699 INFO org.apache.hadoop.security.token.delegation.AbstractDelegationTokenSecretManager: Starting expired delegation token remover thread, tokenRemoverScanInterval=60 min(s)
2022-11-24 03:15:51,699 INFO org.apache.hadoop.security.token.delegation.AbstractDelegationTokenSecretManager: Updating the current master key for generating delegation tokens
2022-11-24 03:15:51,707 INFO org.mortbay.log: Started HttpServer2$SelectChannelConnectorWithSafeStartup@172.31.11.48:8088
2022-11-24 03:15:51,707 INFO org.apache.hadoop.yarn.webapp.WebApps: Web app /cluster started at 8088
2022-11-24 03:15:52,052 INFO org.apache.hadoop.yarn.webapp.WebApps: Registered webapp guice modules
2022-11-24 03:15:52,072 INFO org.apache.hadoop.ipc.CallQueueManager: Using callQueue: class java.util.concurrent.LinkedBlockingQueue queueCapacity: 100
2022-11-24 03:15:52,078 INFO org.apache.hadoop.ipc.Server: Starting Socket Reader #1 for port 8033
2022-11-24 03:15:52,079 INFO org.apache.hadoop.yarn.factories.impl.pb.RpcServerFactoryPBImpl: Adding protocol org.apache.hadoop.yarn.server.api.ResourceManagerAdministrationProtocolPB to the server
2022-11-24 03:15:52,080 INFO org.apache.hadoop.ipc.Server: IPC Server Responder: starting
2022-11-24 03:15:52,080 INFO org.apache.hadoop.ipc.Server: IPC Server listener on 8033: starting
2022-11-24 03:17:33,926 ERROR org.apache.hadoop.yarn.server.resourcemanager.ResourceManager: RECEIVED SIGNAL 15: SIGTERM
2022-11-24 03:17:33,929 ERROR org.apache.hadoop.security.token.delegation.AbstractDelegationTokenSecretManager: ExpiredTokenRemover received java.lang.InterruptedException: sleep interrupted
2022-11-24 03:17:33,931 INFO org.mortbay.log: Stopped HttpServer2$SelectChannelConnectorWithSafeStartup@172.31.11.48:8088
2022-11-24 03:17:33,931 ERROR org.apache.hadoop.security.token.delegation.AbstractDelegationTokenSecretManager: ExpiredTokenRemover received java.lang.InterruptedException: sleep interrupted
2022-11-24 03:17:33,931 ERROR org.apache.hadoop.security.token.delegation.AbstractDelegationTokenSecretManager: ExpiredTokenRemover received java.lang.InterruptedException: sleep interrupted
2022-11-24 03:17:34,032 INFO org.apache.hadoop.ipc.Server: Stopping server on 8032
2022-11-24 03:17:34,034 INFO org.apache.hadoop.ipc.Server: Stopping server on 8033
2022-11-24 03:17:34,034 INFO org.apache.hadoop.ipc.Server: Stopping IPC Server listener on 8033
2022-11-24 03:17:34,037 INFO org.apache.hadoop.ipc.Server: Stopping IPC Server Responder
2022-11-24 03:17:34,037 INFO org.apache.hadoop.ipc.Server: Stopping IPC Server Responder
2022-11-24 03:17:34,037 INFO org.apache.hadoop.ipc.Server: Stopping IPC Server listener on 8032
2022-11-24 03:17:34,038 INFO org.apache.hadoop.yarn.server.resourcemanager.ResourceManager: Transitioning to standby state
2022-11-24 03:17:34,038 WARN org.apache.hadoop.yarn.server.resourcemanager.amlauncher.ApplicationMasterLauncher: org.apache.hadoop.yarn.server.resourcemanager.amlauncher.ApplicationMasterLauncher$LauncherThread interrupted. Returning.
2022-11-24 03:17:34,039 INFO org.apache.hadoop.ipc.Server: Stopping server on 8030
2022-11-24 03:17:34,041 INFO org.apache.hadoop.ipc.Server: Stopping IPC Server listener on 8030
2022-11-24 03:17:34,043 INFO org.apache.hadoop.ipc.Server: Stopping server on 8031
2022-11-24 03:17:34,044 INFO org.apache.hadoop.ipc.Server: Stopping IPC Server Responder
2022-11-24 03:17:34,048 INFO org.apache.hadoop.ipc.Server: Stopping IPC Server listener on 8031
2022-11-24 03:17:34,048 INFO org.apache.hadoop.ipc.Server: Stopping IPC Server Responder
2022-11-24 03:17:34,049 INFO org.apache.hadoop.yarn.util.AbstractLivelinessMonitor: NMLivelinessMonitor thread interrupted
2022-11-24 03:17:34,050 ERROR org.apache.hadoop.yarn.server.resourcemanager.ResourceManager: Returning, interrupted : java.lang.InterruptedException
2022-11-24 03:17:34,050 INFO org.apache.hadoop.yarn.util.AbstractLivelinessMonitor: AMLivelinessMonitor thread interrupted
2022-11-24 03:17:34,050 INFO org.apache.hadoop.yarn.util.AbstractLivelinessMonitor: AMLivelinessMonitor thread interrupted
2022-11-24 03:17:34,050 INFO org.apache.hadoop.yarn.util.AbstractLivelinessMonitor: org.apache.hadoop.yarn.server.resourcemanager.rmcontainer.ContainerAllocationExpirer thread interrupted
2022-11-24 03:17:34,050 ERROR org.apache.hadoop.security.token.delegation.AbstractDelegationTokenSecretManager: ExpiredTokenRemover received java.lang.InterruptedException: sleep interrupted
2022-11-24 03:17:34,052 INFO org.apache.hadoop.metrics2.impl.MetricsSystemImpl: Stopping ResourceManager metrics system...
2022-11-24 03:17:34,053 INFO org.apache.hadoop.metrics2.impl.MetricsSystemImpl: ResourceManager metrics system stopped.
2022-11-24 03:17:34,053 INFO org.apache.hadoop.metrics2.impl.MetricsSystemImpl: ResourceManager metrics system shutdown complete.
2022-11-24 03:17:34,053 INFO org.apache.hadoop.yarn.event.AsyncDispatcher: AsyncDispatcher is draining to stop, igonring any new events.
2022-11-24 03:17:34,054 INFO org.apache.hadoop.yarn.server.resourcemanager.ResourceManager: Transitioned to standby state
2022-11-24 03:17:34,054 INFO org.apache.hadoop.yarn.server.resourcemanager.ResourceManager: SHUTDOWN_MSG: 
/************************************************************
SHUTDOWN_MSG: Shutting down ResourceManager at ip-172-31-11-48/172.31.11.48
************************************************************/
2022-11-24 03:37:26,610 INFO org.apache.hadoop.yarn.server.resourcemanager.ResourceManager: STARTUP_MSG: 
/************************************************************
STARTUP_MSG: Starting ResourceManager
STARTUP_MSG:   host = ip-172-31-11-48/172.31.11.48
STARTUP_MSG:   args = []
STARTUP_MSG:   version = 2.6.5
STARTUP_MSG:   build = https://github.com/apache/hadoop.git -r e8c9fe0b4c252caf2ebf1464220599650f119997; compiled by 'sjlee' on 2016-10-02T23:43Z
STARTUP_MSG:   java = 1.8.0_352
************************************************************/
2022-11-24 03:37:26,621 INFO org.apache.hadoop.yarn.server.resourcemanager.ResourceManager: registered UNIX signal handlers for [TERM, HUP, INT]
2022-11-24 03:37:26,867 INFO org.apache.hadoop.conf.Configuration: found resource core-site.xml at file:/usr/local/hadoop/etc/hadoop/core-site.xml
2022-11-24 03:37:26,939 INFO org.apache.hadoop.security.Groups: clearing userToGroupsMap cache
2022-11-24 03:37:27,043 INFO org.apache.hadoop.conf.Configuration: found resource yarn-site.xml at file:/usr/local/hadoop/etc/hadoop/yarn-site.xml
2022-11-24 03:37:27,225 INFO org.apache.hadoop.yarn.event.AsyncDispatcher: Registering class org.apache.hadoop.yarn.server.resourcemanager.RMFatalEventType for class org.apache.hadoop.yarn.server.resourcemanager.ResourceManager$RMFatalEventDispatcher
2022-11-24 03:37:27,310 INFO org.apache.hadoop.yarn.server.resourcemanager.security.NMTokenSecretManagerInRM: NMTokenKeyRollingInterval: 86400000ms and NMTokenKeyActivationDelay: 900000ms
2022-11-24 03:37:27,313 INFO org.apache.hadoop.yarn.server.resourcemanager.security.RMContainerTokenSecretManager: ContainerTokenKeyRollingInterval: 86400000ms and ContainerTokenKeyActivationDelay: 900000ms
2022-11-24 03:37:27,317 INFO org.apache.hadoop.yarn.server.resourcemanager.security.AMRMTokenSecretManager: AMRMTokenKeyRollingInterval: 86400000ms and AMRMTokenKeyActivationDelay: 900000 ms
2022-11-24 03:37:27,344 INFO org.apache.hadoop.yarn.event.AsyncDispatcher: Registering class org.apache.hadoop.yarn.server.resourcemanager.recovery.RMStateStoreEventType for class org.apache.hadoop.yarn.server.resourcemanager.recovery.RMStateStore$ForwardingEventHandler
2022-11-24 03:37:27,347 INFO org.apache.hadoop.yarn.event.AsyncDispatcher: Registering class org.apache.hadoop.yarn.server.resourcemanager.NodesListManagerEventType for class org.apache.hadoop.yarn.server.resourcemanager.NodesListManager
2022-11-24 03:37:27,347 INFO org.apache.hadoop.yarn.server.resourcemanager.ResourceManager: Using Scheduler: org.apache.hadoop.yarn.server.resourcemanager.scheduler.capacity.CapacityScheduler
2022-11-24 03:37:27,360 INFO org.apache.hadoop.yarn.event.AsyncDispatcher: Registering class org.apache.hadoop.yarn.server.resourcemanager.scheduler.event.SchedulerEventType for class org.apache.hadoop.yarn.server.resourcemanager.ResourceManager$SchedulerEventDispatcher
2022-11-24 03:37:27,363 INFO org.apache.hadoop.yarn.event.AsyncDispatcher: Registering class org.apache.hadoop.yarn.server.resourcemanager.rmapp.RMAppEventType for class org.apache.hadoop.yarn.server.resourcemanager.ResourceManager$ApplicationEventDispatcher
2022-11-24 03:37:27,364 INFO org.apache.hadoop.yarn.event.AsyncDispatcher: Registering class org.apache.hadoop.yarn.server.resourcemanager.rmapp.attempt.RMAppAttemptEventType for class org.apache.hadoop.yarn.server.resourcemanager.ResourceManager$ApplicationAttemptEventDispatcher
2022-11-24 03:37:27,374 INFO org.apache.hadoop.yarn.event.AsyncDispatcher: Registering class org.apache.hadoop.yarn.server.resourcemanager.rmnode.RMNodeEventType for class org.apache.hadoop.yarn.server.resourcemanager.ResourceManager$NodeEventDispatcher
2022-11-24 03:37:27,458 INFO org.apache.hadoop.metrics2.impl.MetricsConfig: loaded properties from hadoop-metrics2.properties
2022-11-24 03:37:27,545 INFO org.apache.hadoop.metrics2.impl.MetricsSystemImpl: Scheduled snapshot period at 10 second(s).
2022-11-24 03:37:27,545 INFO org.apache.hadoop.metrics2.impl.MetricsSystemImpl: ResourceManager metrics system started
2022-11-24 03:37:27,559 INFO org.apache.hadoop.yarn.event.AsyncDispatcher: Registering class org.apache.hadoop.yarn.server.resourcemanager.RMAppManagerEventType for class org.apache.hadoop.yarn.server.resourcemanager.RMAppManager
2022-11-24 03:37:27,573 INFO org.apache.hadoop.yarn.event.AsyncDispatcher: Registering class org.apache.hadoop.yarn.server.resourcemanager.amlauncher.AMLauncherEventType for class org.apache.hadoop.yarn.server.resourcemanager.amlauncher.ApplicationMasterLauncher
2022-11-24 03:37:27,575 INFO org.apache.hadoop.yarn.server.resourcemanager.RMNMInfo: Registered RMNMInfo MBean
2022-11-24 03:37:27,576 INFO org.apache.hadoop.util.HostsFileReader: Refreshing hosts (include/exclude) list
2022-11-24 03:37:27,578 INFO org.apache.hadoop.conf.Configuration: found resource capacity-scheduler.xml at file:/usr/local/hadoop/etc/hadoop/capacity-scheduler.xml
2022-11-24 03:37:27,614 INFO org.apache.hadoop.yarn.server.resourcemanager.scheduler.capacity.ParentQueue: root, capacity=1.0, asboluteCapacity=1.0, maxCapacity=1.0, asboluteMaxCapacity=1.0, state=RUNNING, acls=SUBMIT_APPLICATIONS:*ADMINISTER_QUEUE:*, labels=*,
, reservationsContinueLooking=true
2022-11-24 03:37:27,615 INFO org.apache.hadoop.yarn.server.resourcemanager.scheduler.capacity.ParentQueue: Initialized parent-queue root name=root, fullname=root
2022-11-24 03:37:27,622 INFO org.apache.hadoop.yarn.server.resourcemanager.scheduler.capacity.LeafQueue: Initializing default
capacity = 1.0 [= (float) configuredCapacity / 100 ]
asboluteCapacity = 1.0 [= parentAbsoluteCapacity * capacity ]
maxCapacity = 1.0 [= configuredMaxCapacity ]
absoluteMaxCapacity = 1.0 [= 1.0 maximumCapacity undefined, (parentAbsoluteMaxCapacity * maximumCapacity) / 100 otherwise ]
userLimit = 100 [= configuredUserLimit ]
userLimitFactor = 1.0 [= configuredUserLimitFactor ]
maxApplications = 10000 [= configuredMaximumSystemApplicationsPerQueue or (int)(configuredMaximumSystemApplications * absoluteCapacity)]
maxApplicationsPerUser = 10000 [= (int)(maxApplications * (userLimit / 100.0f) * userLimitFactor) ]
usedCapacity = 0.0 [= usedResourcesMemory / (clusterResourceMemory * absoluteCapacity)]
absoluteUsedCapacity = 0.0 [= usedResourcesMemory / clusterResourceMemory]
maxAMResourcePerQueuePercent = 0.1 [= configuredMaximumAMResourcePercent ]
minimumAllocationFactor = 0.875 [= (float)(maximumAllocationMemory - minimumAllocationMemory) / maximumAllocationMemory ]
numContainers = 0 [= currentNumContainers ]
state = RUNNING [= configuredState ]
acls = SUBMIT_APPLICATIONS:*ADMINISTER_QUEUE:* [= configuredAcls ]
nodeLocalityDelay = 40
labels=*,
nodeLocalityDelay = 40
reservationsContinueLooking = true

2022-11-24 03:37:27,623 INFO org.apache.hadoop.yarn.server.resourcemanager.scheduler.capacity.CapacityScheduler: Initialized queue: default: capacity=1.0, absoluteCapacity=1.0, usedResources=<memory:0, vCores:0>, usedCapacity=0.0, absoluteUsedCapacity=0.0, numApps=0, numContainers=0
2022-11-24 03:37:27,623 INFO org.apache.hadoop.yarn.server.resourcemanager.scheduler.capacity.CapacityScheduler: Initialized queue: root: numChildQueue= 1, capacity=1.0, absoluteCapacity=1.0, usedResources=<memory:0, vCores:0>usedCapacity=0.0, numApps=0, numContainers=0
2022-11-24 03:37:27,624 INFO org.apache.hadoop.yarn.server.resourcemanager.scheduler.capacity.CapacityScheduler: Initialized root queue root: numChildQueue= 1, capacity=1.0, absoluteCapacity=1.0, usedResources=<memory:0, vCores:0>usedCapacity=0.0, numApps=0, numContainers=0
2022-11-24 03:37:27,624 INFO org.apache.hadoop.yarn.server.resourcemanager.scheduler.capacity.CapacityScheduler: Initialized queue mappings, override: false
2022-11-24 03:37:27,624 INFO org.apache.hadoop.yarn.server.resourcemanager.scheduler.capacity.CapacityScheduler: Initialized CapacityScheduler with calculator=class org.apache.hadoop.yarn.util.resource.DefaultResourceCalculator, minimumAllocation=<<memory:1024, vCores:1>>, maximumAllocation=<<memory:8192, vCores:32>>, asynchronousScheduling=false, asyncScheduleInterval=5ms
2022-11-24 03:37:27,643 INFO org.apache.hadoop.yarn.server.resourcemanager.metrics.SystemMetricsPublisher: YARN system metrics publishing service is not enabled
2022-11-24 03:37:27,643 INFO org.apache.hadoop.yarn.server.resourcemanager.ResourceManager: Transitioning to active state
2022-11-24 03:37:27,675 INFO org.apache.hadoop.yarn.server.resourcemanager.security.RMContainerTokenSecretManager: Rolling master-key for container-tokens
2022-11-24 03:37:27,675 INFO org.apache.hadoop.yarn.server.resourcemanager.security.NMTokenSecretManagerInRM: Rolling master-key for nm-tokens
2022-11-24 03:37:27,675 INFO org.apache.hadoop.security.token.delegation.AbstractDelegationTokenSecretManager: Updating the current master key for generating delegation tokens
2022-11-24 03:37:27,676 INFO org.apache.hadoop.yarn.server.resourcemanager.security.RMDelegationTokenSecretManager: storing master key with keyID 1
2022-11-24 03:37:27,677 INFO org.apache.hadoop.security.token.delegation.AbstractDelegationTokenSecretManager: Starting expired delegation token remover thread, tokenRemoverScanInterval=60 min(s)
2022-11-24 03:37:27,677 INFO org.apache.hadoop.security.token.delegation.AbstractDelegationTokenSecretManager: Updating the current master key for generating delegation tokens
2022-11-24 03:37:27,677 INFO org.apache.hadoop.yarn.server.resourcemanager.security.RMDelegationTokenSecretManager: storing master key with keyID 2
2022-11-24 03:37:27,709 INFO org.apache.hadoop.ipc.CallQueueManager: Using callQueue: class java.util.concurrent.LinkedBlockingQueue queueCapacity: 5000
2022-11-24 03:37:27,720 INFO org.apache.hadoop.ipc.Server: Starting Socket Reader #1 for port 8031
2022-11-24 03:37:27,735 INFO org.apache.hadoop.yarn.factories.impl.pb.RpcServerFactoryPBImpl: Adding protocol org.apache.hadoop.yarn.server.api.ResourceTrackerPB to the server
2022-11-24 03:37:27,735 INFO org.apache.hadoop.ipc.Server: IPC Server Responder: starting
2022-11-24 03:37:27,736 INFO org.apache.hadoop.ipc.Server: IPC Server listener on 8031: starting
2022-11-24 03:37:27,792 INFO org.apache.hadoop.ipc.CallQueueManager: Using callQueue: class java.util.concurrent.LinkedBlockingQueue queueCapacity: 5000
2022-11-24 03:37:27,798 INFO org.apache.hadoop.ipc.Server: Starting Socket Reader #1 for port 8030
2022-11-24 03:37:27,805 INFO org.apache.hadoop.yarn.factories.impl.pb.RpcServerFactoryPBImpl: Adding protocol org.apache.hadoop.yarn.api.ApplicationMasterProtocolPB to the server
2022-11-24 03:37:27,805 INFO org.apache.hadoop.ipc.Server: IPC Server Responder: starting
2022-11-24 03:37:27,806 INFO org.apache.hadoop.ipc.Server: IPC Server listener on 8030: starting
2022-11-24 03:37:27,880 INFO org.apache.hadoop.ipc.CallQueueManager: Using callQueue: class java.util.concurrent.LinkedBlockingQueue queueCapacity: 5000
2022-11-24 03:37:27,880 INFO org.apache.hadoop.ipc.Server: Starting Socket Reader #1 for port 8032
2022-11-24 03:37:27,882 INFO org.apache.hadoop.yarn.factories.impl.pb.RpcServerFactoryPBImpl: Adding protocol org.apache.hadoop.yarn.api.ApplicationClientProtocolPB to the server
2022-11-24 03:37:27,882 INFO org.apache.hadoop.ipc.Server: IPC Server Responder: starting
2022-11-24 03:37:27,883 INFO org.apache.hadoop.ipc.Server: IPC Server listener on 8032: starting
2022-11-24 03:37:27,900 INFO org.apache.hadoop.yarn.server.resourcemanager.ResourceManager: Transitioned to active state
2022-11-24 03:37:27,953 INFO org.mortbay.log: Logging to org.slf4j.impl.Log4jLoggerAdapter(org.mortbay.log) via org.mortbay.log.Slf4jLog
2022-11-24 03:37:27,956 INFO org.apache.hadoop.http.HttpRequestLog: Http request log for http.requests.resourcemanager is not defined
2022-11-24 03:37:27,964 INFO org.apache.hadoop.http.HttpServer2: Added global filter 'safety' (class=org.apache.hadoop.http.HttpServer2$QuotingInputFilter)
2022-11-24 03:37:27,971 INFO org.apache.hadoop.http.HttpServer2: Added filter RMAuthenticationFilter (class=org.apache.hadoop.yarn.server.security.http.RMAuthenticationFilter) to context cluster
2022-11-24 03:37:27,971 INFO org.apache.hadoop.http.HttpServer2: Added filter RMAuthenticationFilter (class=org.apache.hadoop.yarn.server.security.http.RMAuthenticationFilter) to context static
2022-11-24 03:37:27,971 INFO org.apache.hadoop.http.HttpServer2: Added filter RMAuthenticationFilter (class=org.apache.hadoop.yarn.server.security.http.RMAuthenticationFilter) to context logs
2022-11-24 03:37:27,971 INFO org.apache.hadoop.http.HttpServer2: Added filter static_user_filter (class=org.apache.hadoop.http.lib.StaticUserWebFilter$StaticUserFilter) to context cluster
2022-11-24 03:37:27,971 INFO org.apache.hadoop.http.HttpServer2: Added filter static_user_filter (class=org.apache.hadoop.http.lib.StaticUserWebFilter$StaticUserFilter) to context static
2022-11-24 03:37:27,971 INFO org.apache.hadoop.http.HttpServer2: Added filter static_user_filter (class=org.apache.hadoop.http.lib.StaticUserWebFilter$StaticUserFilter) to context logs
2022-11-24 03:37:27,974 INFO org.apache.hadoop.http.HttpServer2: adding path spec: /cluster/*
2022-11-24 03:37:27,974 INFO org.apache.hadoop.http.HttpServer2: adding path spec: /ws/*
2022-11-24 03:37:27,983 INFO org.apache.hadoop.http.HttpServer2: Jetty bound to port 8088
2022-11-24 03:37:27,983 INFO org.mortbay.log: jetty-6.1.26
2022-11-24 03:37:28,011 INFO org.mortbay.log: Extract jar:file:/usr/local/hadoop/share/hadoop/yarn/hadoop-yarn-common-2.6.5.jar!/webapps/cluster to /tmp/Jetty_172_31_11_48_8088_cluster____.cj96d9/webapp
2022-11-24 03:37:28,165 INFO org.apache.hadoop.security.token.delegation.AbstractDelegationTokenSecretManager: Updating the current master key for generating delegation tokens
2022-11-24 03:37:28,169 INFO org.apache.hadoop.security.token.delegation.AbstractDelegationTokenSecretManager: Starting expired delegation token remover thread, tokenRemoverScanInterval=60 min(s)
2022-11-24 03:37:28,170 INFO org.apache.hadoop.security.token.delegation.AbstractDelegationTokenSecretManager: Updating the current master key for generating delegation tokens
2022-11-24 03:37:28,193 INFO org.apache.hadoop.security.token.delegation.AbstractDelegationTokenSecretManager: Updating the current master key for generating delegation tokens
2022-11-24 03:37:28,194 INFO org.apache.hadoop.security.token.delegation.AbstractDelegationTokenSecretManager: Starting expired delegation token remover thread, tokenRemoverScanInterval=60 min(s)
2022-11-24 03:37:28,194 INFO org.apache.hadoop.security.token.delegation.AbstractDelegationTokenSecretManager: Updating the current master key for generating delegation tokens
2022-11-24 03:37:28,194 INFO org.apache.hadoop.security.token.delegation.AbstractDelegationTokenSecretManager: Updating the current master key for generating delegation tokens
2022-11-24 03:37:28,195 INFO org.apache.hadoop.security.token.delegation.AbstractDelegationTokenSecretManager: Starting expired delegation token remover thread, tokenRemoverScanInterval=60 min(s)
2022-11-24 03:37:28,195 INFO org.apache.hadoop.security.token.delegation.AbstractDelegationTokenSecretManager: Updating the current master key for generating delegation tokens
2022-11-24 03:37:28,203 INFO org.mortbay.log: Started HttpServer2$SelectChannelConnectorWithSafeStartup@172.31.11.48:8088
2022-11-24 03:37:28,203 INFO org.apache.hadoop.yarn.webapp.WebApps: Web app /cluster started at 8088
2022-11-24 03:37:28,617 INFO org.apache.hadoop.yarn.webapp.WebApps: Registered webapp guice modules
2022-11-24 03:37:28,637 INFO org.apache.hadoop.ipc.CallQueueManager: Using callQueue: class java.util.concurrent.LinkedBlockingQueue queueCapacity: 100
2022-11-24 03:37:28,637 INFO org.apache.hadoop.ipc.Server: Starting Socket Reader #1 for port 8033
2022-11-24 03:37:28,639 INFO org.apache.hadoop.yarn.factories.impl.pb.RpcServerFactoryPBImpl: Adding protocol org.apache.hadoop.yarn.server.api.ResourceManagerAdministrationProtocolPB to the server
2022-11-24 03:37:28,639 INFO org.apache.hadoop.ipc.Server: IPC Server Responder: starting
2022-11-24 03:37:28,639 INFO org.apache.hadoop.ipc.Server: IPC Server listener on 8033: starting
2022-11-24 03:37:29,977 INFO org.apache.hadoop.yarn.util.RackResolver: Resolved ip-172-31-0-65.ec2.internal to /default-rack
2022-11-24 03:37:29,980 INFO org.apache.hadoop.yarn.server.resourcemanager.rmnode.RMNodeImpl: ip-172-31-0-65.ec2.internal:34785 Node Transitioned from NEW to RUNNING
2022-11-24 03:37:29,982 INFO org.apache.hadoop.yarn.server.resourcemanager.scheduler.capacity.CapacityScheduler: Added node ip-172-31-0-65.ec2.internal:34785 clusterResource: <memory:8192, vCores:8>
2022-11-24 03:37:29,983 INFO org.apache.hadoop.yarn.server.resourcemanager.ResourceTrackerService: NodeManager from node ip-172-31-0-65.ec2.internal(cmPort: 34785 httpPort: 8042) registered with capability: <memory:8192, vCores:8>, assigned nodeId ip-172-31-0-65.ec2.internal:34785
2022-11-24 03:37:31,661 INFO org.apache.hadoop.yarn.util.RackResolver: Resolved ip-172-31-3-214.ec2.internal to /default-rack
2022-11-24 03:37:31,661 INFO org.apache.hadoop.yarn.server.resourcemanager.ResourceTrackerService: NodeManager from node ip-172-31-3-214.ec2.internal(cmPort: 41855 httpPort: 8042) registered with capability: <memory:8192, vCores:8>, assigned nodeId ip-172-31-3-214.ec2.internal:41855
2022-11-24 03:37:31,661 INFO org.apache.hadoop.yarn.server.resourcemanager.rmnode.RMNodeImpl: ip-172-31-3-214.ec2.internal:41855 Node Transitioned from NEW to RUNNING
2022-11-24 03:37:31,663 INFO org.apache.hadoop.yarn.server.resourcemanager.scheduler.capacity.CapacityScheduler: Added node ip-172-31-3-214.ec2.internal:41855 clusterResource: <memory:16384, vCores:16>
2022-11-24 03:47:27,626 INFO org.apache.hadoop.yarn.server.resourcemanager.scheduler.AbstractYarnScheduler: Release request cache is cleaned up
2022-11-24 03:49:25,150 INFO org.apache.hadoop.yarn.server.resourcemanager.ClientRMService: Allocated new applicationId: 1
2022-11-24 03:59:25,163 INFO org.apache.hadoop.yarn.server.resourcemanager.ClientRMService: Allocated new applicationId: 2
2022-11-24 03:59:25,941 INFO org.apache.hadoop.yarn.server.resourcemanager.ClientRMService: Application with id 2 submitted by user ubuntu
2022-11-24 03:59:25,942 INFO org.apache.hadoop.yarn.server.resourcemanager.rmapp.RMAppImpl: Storing application with id application_1669261047644_0002
2022-11-24 03:59:25,943 INFO org.apache.hadoop.yarn.server.resourcemanager.RMAuditLogger: USER=ubuntu	IP=172.31.11.48	OPERATION=Submit Application Request	TARGET=ClientRMService	RESULT=SUCCESS	APPID=application_1669261047644_0002
2022-11-24 03:59:25,943 INFO org.apache.hadoop.yarn.server.resourcemanager.rmapp.RMAppImpl: application_1669261047644_0002 State change from NEW to NEW_SAVING
2022-11-24 03:59:25,964 INFO org.apache.hadoop.yarn.server.resourcemanager.recovery.RMStateStore: Storing info for app: application_1669261047644_0002
2022-11-24 03:59:25,998 INFO org.apache.hadoop.yarn.server.resourcemanager.rmapp.RMAppImpl: application_1669261047644_0002 State change from NEW_SAVING to SUBMITTED
2022-11-24 03:59:26,000 INFO org.apache.hadoop.yarn.server.resourcemanager.scheduler.capacity.ParentQueue: Application added - appId: application_1669261047644_0002 user: ubuntu leaf-queue of parent: root #applications: 1
2022-11-24 03:59:26,000 INFO org.apache.hadoop.yarn.server.resourcemanager.scheduler.capacity.CapacityScheduler: Accepted application application_1669261047644_0002 from user: ubuntu, in queue: default
2022-11-24 03:59:26,003 INFO org.apache.hadoop.yarn.server.resourcemanager.rmapp.RMAppImpl: application_1669261047644_0002 State change from SUBMITTED to ACCEPTED
2022-11-24 03:59:26,035 INFO org.apache.hadoop.yarn.server.resourcemanager.ApplicationMasterService: Registering app attempt : appattempt_1669261047644_0002_000001
2022-11-24 03:59:26,036 INFO org.apache.hadoop.yarn.server.resourcemanager.rmapp.attempt.RMAppAttemptImpl: appattempt_1669261047644_0002_000001 State change from NEW to SUBMITTED
2022-11-24 03:59:26,047 INFO org.apache.hadoop.yarn.server.resourcemanager.scheduler.capacity.LeafQueue: Application application_1669261047644_0002 from user: ubuntu activated in queue: default
2022-11-24 03:59:26,047 INFO org.apache.hadoop.yarn.server.resourcemanager.scheduler.capacity.LeafQueue: Application added - appId: application_1669261047644_0002 user: org.apache.hadoop.yarn.server.resourcemanager.scheduler.capacity.LeafQueue$User@3607880d, leaf-queue: default #user-pending-applications: 0 #user-active-applications: 1 #queue-pending-applications: 0 #queue-active-applications: 1
2022-11-24 03:59:26,047 INFO org.apache.hadoop.yarn.server.resourcemanager.scheduler.capacity.CapacityScheduler: Added Application Attempt appattempt_1669261047644_0002_000001 to scheduler from user ubuntu in queue default
2022-11-24 03:59:26,051 INFO org.apache.hadoop.yarn.server.resourcemanager.rmapp.attempt.RMAppAttemptImpl: appattempt_1669261047644_0002_000001 State change from SUBMITTED to SCHEDULED
2022-11-24 03:59:26,402 INFO org.apache.hadoop.yarn.server.resourcemanager.rmcontainer.RMContainerImpl: container_1669261047644_0002_01_000001 Container Transitioned from NEW to ALLOCATED
2022-11-24 03:59:26,402 INFO org.apache.hadoop.yarn.server.resourcemanager.RMAuditLogger: USER=ubuntu	OPERATION=AM Allocated Container	TARGET=SchedulerApp	RESULT=SUCCESS	APPID=application_1669261047644_0002	CONTAINERID=container_1669261047644_0002_01_000001
2022-11-24 03:59:26,403 INFO org.apache.hadoop.yarn.server.resourcemanager.scheduler.SchedulerNode: Assigned container container_1669261047644_0002_01_000001 of capacity <memory:2048, vCores:1> on host ip-172-31-0-65.ec2.internal:34785, which has 1 containers, <memory:2048, vCores:1> used and <memory:6144, vCores:7> available after allocation
2022-11-24 03:59:26,403 INFO org.apache.hadoop.yarn.server.resourcemanager.scheduler.capacity.LeafQueue: assignedContainer application attempt=appattempt_1669261047644_0002_000001 container=Container: [ContainerId: container_1669261047644_0002_01_000001, NodeId: ip-172-31-0-65.ec2.internal:34785, NodeHttpAddress: ip-172-31-0-65.ec2.internal:8042, Resource: <memory:2048, vCores:1>, Priority: 0, Token: null, ] queue=default: capacity=1.0, absoluteCapacity=1.0, usedResources=<memory:0, vCores:0>, usedCapacity=0.0, absoluteUsedCapacity=0.0, numApps=1, numContainers=0 clusterResource=<memory:16384, vCores:16>
2022-11-24 03:59:26,403 INFO org.apache.hadoop.yarn.server.resourcemanager.scheduler.capacity.ParentQueue: Re-sorting assigned queue: root.default stats: default: capacity=1.0, absoluteCapacity=1.0, usedResources=<memory:2048, vCores:1>, usedCapacity=0.125, absoluteUsedCapacity=0.125, numApps=1, numContainers=1
2022-11-24 03:59:26,404 INFO org.apache.hadoop.yarn.server.resourcemanager.scheduler.capacity.ParentQueue: assignedContainer queue=root usedCapacity=0.125 absoluteUsedCapacity=0.125 used=<memory:2048, vCores:1> cluster=<memory:16384, vCores:16>
2022-11-24 03:59:26,419 INFO org.apache.hadoop.yarn.server.resourcemanager.security.NMTokenSecretManagerInRM: Sending NMToken for nodeId : ip-172-31-0-65.ec2.internal:34785 for container : container_1669261047644_0002_01_000001
2022-11-24 03:59:26,427 INFO org.apache.hadoop.yarn.server.resourcemanager.rmcontainer.RMContainerImpl: container_1669261047644_0002_01_000001 Container Transitioned from ALLOCATED to ACQUIRED
2022-11-24 03:59:26,427 INFO org.apache.hadoop.yarn.server.resourcemanager.security.NMTokenSecretManagerInRM: Clear node set for appattempt_1669261047644_0002_000001
2022-11-24 03:59:26,430 INFO org.apache.hadoop.yarn.server.resourcemanager.rmapp.attempt.RMAppAttemptImpl: Storing attempt: AppId: application_1669261047644_0002 AttemptId: appattempt_1669261047644_0002_000001 MasterContainer: Container: [ContainerId: container_1669261047644_0002_01_000001, NodeId: ip-172-31-0-65.ec2.internal:34785, NodeHttpAddress: ip-172-31-0-65.ec2.internal:8042, Resource: <memory:2048, vCores:1>, Priority: 0, Token: Token { kind: ContainerToken, service: 172.31.0.65:34785 }, ]
2022-11-24 03:59:26,433 INFO org.apache.hadoop.yarn.server.resourcemanager.rmapp.attempt.RMAppAttemptImpl: appattempt_1669261047644_0002_000001 State change from SCHEDULED to ALLOCATED_SAVING
2022-11-24 03:59:26,441 INFO org.apache.hadoop.yarn.server.resourcemanager.rmapp.attempt.RMAppAttemptImpl: appattempt_1669261047644_0002_000001 State change from ALLOCATED_SAVING to ALLOCATED
2022-11-24 03:59:26,444 INFO org.apache.hadoop.yarn.server.resourcemanager.amlauncher.AMLauncher: Launching masterappattempt_1669261047644_0002_000001
2022-11-24 03:59:26,474 INFO org.apache.hadoop.yarn.server.resourcemanager.amlauncher.AMLauncher: Setting up container Container: [ContainerId: container_1669261047644_0002_01_000001, NodeId: ip-172-31-0-65.ec2.internal:34785, NodeHttpAddress: ip-172-31-0-65.ec2.internal:8042, Resource: <memory:2048, vCores:1>, Priority: 0, Token: Token { kind: ContainerToken, service: 172.31.0.65:34785 }, ] for AM appattempt_1669261047644_0002_000001
2022-11-24 03:59:26,474 INFO org.apache.hadoop.yarn.server.resourcemanager.amlauncher.AMLauncher: Command to launch container container_1669261047644_0002_01_000001 : $JAVA_HOME/bin/java -Dlog4j.configuration=container-log4j.properties -Dyarn.app.container.log.dir=<LOG_DIR> -Dyarn.app.container.log.filesize=0 -Dhadoop.root.logger=INFO,CLA  -Xmx1024m org.apache.hadoop.mapreduce.v2.app.MRAppMaster 1><LOG_DIR>/stdout 2><LOG_DIR>/stderr 
2022-11-24 03:59:26,477 INFO org.apache.hadoop.yarn.server.resourcemanager.security.AMRMTokenSecretManager: Create AMRMToken for ApplicationAttempt: appattempt_1669261047644_0002_000001
2022-11-24 03:59:26,480 INFO org.apache.hadoop.yarn.server.resourcemanager.security.AMRMTokenSecretManager: Creating password for appattempt_1669261047644_0002_000001
2022-11-24 03:59:26,750 INFO org.apache.hadoop.yarn.server.resourcemanager.amlauncher.AMLauncher: Done launching container Container: [ContainerId: container_1669261047644_0002_01_000001, NodeId: ip-172-31-0-65.ec2.internal:34785, NodeHttpAddress: ip-172-31-0-65.ec2.internal:8042, Resource: <memory:2048, vCores:1>, Priority: 0, Token: Token { kind: ContainerToken, service: 172.31.0.65:34785 }, ] for AM appattempt_1669261047644_0002_000001
2022-11-24 03:59:26,750 INFO org.apache.hadoop.yarn.server.resourcemanager.rmapp.attempt.RMAppAttemptImpl: appattempt_1669261047644_0002_000001 State change from ALLOCATED to LAUNCHED
2022-11-24 03:59:27,399 INFO org.apache.hadoop.yarn.server.resourcemanager.rmcontainer.RMContainerImpl: container_1669261047644_0002_01_000001 Container Transitioned from ACQUIRED to RUNNING
2022-11-24 03:59:30,809 INFO SecurityLogger.org.apache.hadoop.ipc.Server: Auth successful for appattempt_1669261047644_0002_000001 (auth:SIMPLE)
2022-11-24 03:59:30,817 INFO org.apache.hadoop.yarn.server.resourcemanager.ApplicationMasterService: AM registration appattempt_1669261047644_0002_000001
2022-11-24 03:59:30,818 INFO org.apache.hadoop.yarn.server.resourcemanager.RMAuditLogger: USER=ubuntu	IP=172.31.0.65	OPERATION=Register App Master	TARGET=ApplicationMasterService	RESULT=SUCCESS	APPID=application_1669261047644_0002	APPATTEMPTID=appattempt_1669261047644_0002_000001
2022-11-24 03:59:30,818 INFO org.apache.hadoop.yarn.server.resourcemanager.rmapp.attempt.RMAppAttemptImpl: appattempt_1669261047644_0002_000001 State change from LAUNCHED to RUNNING
2022-11-24 03:59:30,818 INFO org.apache.hadoop.yarn.server.resourcemanager.rmapp.RMAppImpl: application_1669261047644_0002 State change from ACCEPTED to RUNNING
2022-11-24 03:59:32,056 INFO org.apache.hadoop.yarn.server.resourcemanager.rmcontainer.RMContainerImpl: container_1669261047644_0002_01_000002 Container Transitioned from NEW to ALLOCATED
2022-11-24 03:59:32,056 INFO org.apache.hadoop.yarn.server.resourcemanager.RMAuditLogger: USER=ubuntu	OPERATION=AM Allocated Container	TARGET=SchedulerApp	RESULT=SUCCESS	APPID=application_1669261047644_0002	CONTAINERID=container_1669261047644_0002_01_000002
2022-11-24 03:59:32,057 INFO org.apache.hadoop.yarn.server.resourcemanager.scheduler.SchedulerNode: Assigned container container_1669261047644_0002_01_000002 of capacity <memory:1024, vCores:1> on host ip-172-31-3-214.ec2.internal:41855, which has 1 containers, <memory:1024, vCores:1> used and <memory:7168, vCores:7> available after allocation
2022-11-24 03:59:32,057 INFO org.apache.hadoop.yarn.server.resourcemanager.scheduler.capacity.LeafQueue: assignedContainer application attempt=appattempt_1669261047644_0002_000001 container=Container: [ContainerId: container_1669261047644_0002_01_000002, NodeId: ip-172-31-3-214.ec2.internal:41855, NodeHttpAddress: ip-172-31-3-214.ec2.internal:8042, Resource: <memory:1024, vCores:1>, Priority: 20, Token: null, ] queue=default: capacity=1.0, absoluteCapacity=1.0, usedResources=<memory:2048, vCores:1>, usedCapacity=0.125, absoluteUsedCapacity=0.125, numApps=1, numContainers=1 clusterResource=<memory:16384, vCores:16>
2022-11-24 03:59:32,057 INFO org.apache.hadoop.yarn.server.resourcemanager.scheduler.capacity.ParentQueue: Re-sorting assigned queue: root.default stats: default: capacity=1.0, absoluteCapacity=1.0, usedResources=<memory:3072, vCores:2>, usedCapacity=0.1875, absoluteUsedCapacity=0.1875, numApps=1, numContainers=2
2022-11-24 03:59:32,057 INFO org.apache.hadoop.yarn.server.resourcemanager.scheduler.capacity.ParentQueue: assignedContainer queue=root usedCapacity=0.1875 absoluteUsedCapacity=0.1875 used=<memory:3072, vCores:2> cluster=<memory:16384, vCores:16>
2022-11-24 03:59:32,929 INFO org.apache.hadoop.yarn.server.resourcemanager.security.NMTokenSecretManagerInRM: Sending NMToken for nodeId : ip-172-31-3-214.ec2.internal:41855 for container : container_1669261047644_0002_01_000002
2022-11-24 03:59:32,930 INFO org.apache.hadoop.yarn.server.resourcemanager.rmcontainer.RMContainerImpl: container_1669261047644_0002_01_000002 Container Transitioned from ALLOCATED to ACQUIRED
2022-11-24 03:59:33,943 INFO org.apache.hadoop.yarn.server.resourcemanager.scheduler.AppSchedulingInfo: checking for deactivate... 
2022-11-24 03:59:34,072 INFO org.apache.hadoop.yarn.server.resourcemanager.rmcontainer.RMContainerImpl: container_1669261047644_0002_01_000002 Container Transitioned from ACQUIRED to RUNNING
2022-11-24 03:59:40,432 INFO org.apache.hadoop.yarn.server.resourcemanager.rmcontainer.RMContainerImpl: container_1669261047644_0002_01_000003 Container Transitioned from NEW to ALLOCATED
2022-11-24 03:59:40,432 INFO org.apache.hadoop.yarn.server.resourcemanager.RMAuditLogger: USER=ubuntu	OPERATION=AM Allocated Container	TARGET=SchedulerApp	RESULT=SUCCESS	APPID=application_1669261047644_0002	CONTAINERID=container_1669261047644_0002_01_000003
2022-11-24 03:59:40,432 INFO org.apache.hadoop.yarn.server.resourcemanager.scheduler.SchedulerNode: Assigned container container_1669261047644_0002_01_000003 of capacity <memory:1024, vCores:1> on host ip-172-31-0-65.ec2.internal:34785, which has 2 containers, <memory:3072, vCores:2> used and <memory:5120, vCores:6> available after allocation
2022-11-24 03:59:40,433 INFO org.apache.hadoop.yarn.server.resourcemanager.scheduler.capacity.LeafQueue: assignedContainer application attempt=appattempt_1669261047644_0002_000001 container=Container: [ContainerId: container_1669261047644_0002_01_000003, NodeId: ip-172-31-0-65.ec2.internal:34785, NodeHttpAddress: ip-172-31-0-65.ec2.internal:8042, Resource: <memory:1024, vCores:1>, Priority: 10, Token: null, ] queue=default: capacity=1.0, absoluteCapacity=1.0, usedResources=<memory:3072, vCores:2>, usedCapacity=0.1875, absoluteUsedCapacity=0.1875, numApps=1, numContainers=2 clusterResource=<memory:16384, vCores:16>
2022-11-24 03:59:40,433 INFO org.apache.hadoop.yarn.server.resourcemanager.scheduler.capacity.ParentQueue: Re-sorting assigned queue: root.default stats: default: capacity=1.0, absoluteCapacity=1.0, usedResources=<memory:4096, vCores:3>, usedCapacity=0.25, absoluteUsedCapacity=0.25, numApps=1, numContainers=3
2022-11-24 03:59:40,433 INFO org.apache.hadoop.yarn.server.resourcemanager.scheduler.capacity.ParentQueue: assignedContainer queue=root usedCapacity=0.25 absoluteUsedCapacity=0.25 used=<memory:4096, vCores:3> cluster=<memory:16384, vCores:16>
2022-11-24 03:59:40,964 INFO org.apache.hadoop.yarn.server.resourcemanager.security.NMTokenSecretManagerInRM: Sending NMToken for nodeId : ip-172-31-0-65.ec2.internal:34785 for container : container_1669261047644_0002_01_000003
2022-11-24 03:59:40,965 INFO org.apache.hadoop.yarn.server.resourcemanager.rmcontainer.RMContainerImpl: container_1669261047644_0002_01_000003 Container Transitioned from ALLOCATED to ACQUIRED
2022-11-24 03:59:41,437 INFO org.apache.hadoop.yarn.server.resourcemanager.rmcontainer.RMContainerImpl: container_1669261047644_0002_01_000003 Container Transitioned from ACQUIRED to RUNNING
2022-11-24 03:59:41,968 INFO org.apache.hadoop.yarn.server.resourcemanager.scheduler.AppSchedulingInfo: checking for deactivate... 
2022-11-24 04:01:20,422 INFO org.apache.hadoop.yarn.server.resourcemanager.ClientRMService: Allocated new applicationId: 3
2022-11-24 04:01:21,094 INFO org.apache.hadoop.yarn.server.resourcemanager.ClientRMService: Application with id 3 submitted by user ubuntu
2022-11-24 04:01:21,094 INFO org.apache.hadoop.yarn.server.resourcemanager.RMAuditLogger: USER=ubuntu	IP=172.31.11.48	OPERATION=Submit Application Request	TARGET=ClientRMService	RESULT=SUCCESS	APPID=application_1669261047644_0003
2022-11-24 04:01:21,094 INFO org.apache.hadoop.yarn.server.resourcemanager.rmapp.RMAppImpl: Storing application with id application_1669261047644_0003
2022-11-24 04:01:21,095 INFO org.apache.hadoop.yarn.server.resourcemanager.rmapp.RMAppImpl: application_1669261047644_0003 State change from NEW to NEW_SAVING
2022-11-24 04:01:21,095 INFO org.apache.hadoop.yarn.server.resourcemanager.recovery.RMStateStore: Storing info for app: application_1669261047644_0003
2022-11-24 04:01:21,096 INFO org.apache.hadoop.yarn.server.resourcemanager.rmapp.RMAppImpl: application_1669261047644_0003 State change from NEW_SAVING to SUBMITTED
2022-11-24 04:01:21,096 INFO org.apache.hadoop.yarn.server.resourcemanager.scheduler.capacity.ParentQueue: Application added - appId: application_1669261047644_0003 user: ubuntu leaf-queue of parent: root #applications: 2
2022-11-24 04:01:21,096 INFO org.apache.hadoop.yarn.server.resourcemanager.scheduler.capacity.CapacityScheduler: Accepted application application_1669261047644_0003 from user: ubuntu, in queue: default
2022-11-24 04:01:21,097 INFO org.apache.hadoop.yarn.server.resourcemanager.rmapp.RMAppImpl: application_1669261047644_0003 State change from SUBMITTED to ACCEPTED
2022-11-24 04:01:21,097 INFO org.apache.hadoop.yarn.server.resourcemanager.ApplicationMasterService: Registering app attempt : appattempt_1669261047644_0003_000001
2022-11-24 04:01:21,097 INFO org.apache.hadoop.yarn.server.resourcemanager.rmapp.attempt.RMAppAttemptImpl: appattempt_1669261047644_0003_000001 State change from NEW to SUBMITTED
2022-11-24 04:01:21,097 INFO org.apache.hadoop.yarn.server.resourcemanager.scheduler.capacity.LeafQueue: not starting application as amIfStarted exceeds amLimit
2022-11-24 04:01:21,097 INFO org.apache.hadoop.yarn.server.resourcemanager.scheduler.capacity.LeafQueue: Application added - appId: application_1669261047644_0003 user: org.apache.hadoop.yarn.server.resourcemanager.scheduler.capacity.LeafQueue$User@3607880d, leaf-queue: default #user-pending-applications: 1 #user-active-applications: 1 #queue-pending-applications: 1 #queue-active-applications: 1
2022-11-24 04:01:21,098 INFO org.apache.hadoop.yarn.server.resourcemanager.scheduler.capacity.CapacityScheduler: Added Application Attempt appattempt_1669261047644_0003_000001 to scheduler from user ubuntu in queue default
2022-11-24 04:01:21,098 INFO org.apache.hadoop.yarn.server.resourcemanager.rmapp.attempt.RMAppAttemptImpl: appattempt_1669261047644_0003_000001 State change from SUBMITTED to SCHEDULED
2022-11-24 04:03:09,963 INFO org.apache.hadoop.yarn.server.resourcemanager.ClientRMService: Allocated new applicationId: 4
2022-11-24 04:03:10,631 INFO org.apache.hadoop.yarn.server.resourcemanager.ClientRMService: Application with id 4 submitted by user ubuntu
2022-11-24 04:03:10,631 INFO org.apache.hadoop.yarn.server.resourcemanager.RMAuditLogger: USER=ubuntu	IP=172.31.11.48	OPERATION=Submit Application Request	TARGET=ClientRMService	RESULT=SUCCESS	APPID=application_1669261047644_0004
2022-11-24 04:03:10,631 INFO org.apache.hadoop.yarn.server.resourcemanager.rmapp.RMAppImpl: Storing application with id application_1669261047644_0004
2022-11-24 04:03:10,631 INFO org.apache.hadoop.yarn.server.resourcemanager.rmapp.RMAppImpl: application_1669261047644_0004 State change from NEW to NEW_SAVING
2022-11-24 04:03:10,631 INFO org.apache.hadoop.yarn.server.resourcemanager.recovery.RMStateStore: Storing info for app: application_1669261047644_0004
2022-11-24 04:03:10,631 INFO org.apache.hadoop.yarn.server.resourcemanager.rmapp.RMAppImpl: application_1669261047644_0004 State change from NEW_SAVING to SUBMITTED
2022-11-24 04:03:10,631 INFO org.apache.hadoop.yarn.server.resourcemanager.scheduler.capacity.ParentQueue: Application added - appId: application_1669261047644_0004 user: ubuntu leaf-queue of parent: root #applications: 3
2022-11-24 04:03:10,631 INFO org.apache.hadoop.yarn.server.resourcemanager.scheduler.capacity.CapacityScheduler: Accepted application application_1669261047644_0004 from user: ubuntu, in queue: default
2022-11-24 04:03:10,632 INFO org.apache.hadoop.yarn.server.resourcemanager.rmapp.RMAppImpl: application_1669261047644_0004 State change from SUBMITTED to ACCEPTED
2022-11-24 04:03:10,632 INFO org.apache.hadoop.yarn.server.resourcemanager.ApplicationMasterService: Registering app attempt : appattempt_1669261047644_0004_000001
2022-11-24 04:03:10,632 INFO org.apache.hadoop.yarn.server.resourcemanager.rmapp.attempt.RMAppAttemptImpl: appattempt_1669261047644_0004_000001 State change from NEW to SUBMITTED
2022-11-24 04:03:10,632 INFO org.apache.hadoop.yarn.server.resourcemanager.scheduler.capacity.LeafQueue: not starting application as amIfStarted exceeds amLimit
2022-11-24 04:03:10,632 INFO org.apache.hadoop.yarn.server.resourcemanager.scheduler.capacity.LeafQueue: not starting application as amIfStarted exceeds amLimit
2022-11-24 04:03:10,632 INFO org.apache.hadoop.yarn.server.resourcemanager.scheduler.capacity.LeafQueue: Application added - appId: application_1669261047644_0004 user: org.apache.hadoop.yarn.server.resourcemanager.scheduler.capacity.LeafQueue$User@3607880d, leaf-queue: default #user-pending-applications: 2 #user-active-applications: 1 #queue-pending-applications: 2 #queue-active-applications: 1
2022-11-24 04:03:10,632 INFO org.apache.hadoop.yarn.server.resourcemanager.scheduler.capacity.CapacityScheduler: Added Application Attempt appattempt_1669261047644_0004_000001 to scheduler from user ubuntu in queue default
2022-11-24 04:03:10,632 INFO org.apache.hadoop.yarn.server.resourcemanager.rmapp.attempt.RMAppAttemptImpl: appattempt_1669261047644_0004_000001 State change from SUBMITTED to SCHEDULED
2022-11-24 04:03:21,933 INFO org.apache.hadoop.yarn.server.resourcemanager.ClientRMService: Allocated new applicationId: 5
2022-11-24 04:03:22,568 INFO org.apache.hadoop.yarn.server.resourcemanager.ClientRMService: Application with id 5 submitted by user ubuntu
2022-11-24 04:03:22,568 INFO org.apache.hadoop.yarn.server.resourcemanager.rmapp.RMAppImpl: Storing application with id application_1669261047644_0005
2022-11-24 04:03:22,568 INFO org.apache.hadoop.yarn.server.resourcemanager.rmapp.RMAppImpl: application_1669261047644_0005 State change from NEW to NEW_SAVING
2022-11-24 04:03:22,568 INFO org.apache.hadoop.yarn.server.resourcemanager.recovery.RMStateStore: Storing info for app: application_1669261047644_0005
2022-11-24 04:03:22,568 INFO org.apache.hadoop.yarn.server.resourcemanager.rmapp.RMAppImpl: application_1669261047644_0005 State change from NEW_SAVING to SUBMITTED
2022-11-24 04:03:22,568 INFO org.apache.hadoop.yarn.server.resourcemanager.RMAuditLogger: USER=ubuntu	IP=172.31.11.48	OPERATION=Submit Application Request	TARGET=ClientRMService	RESULT=SUCCESS	APPID=application_1669261047644_0005
2022-11-24 04:03:22,568 INFO org.apache.hadoop.yarn.server.resourcemanager.scheduler.capacity.ParentQueue: Application added - appId: application_1669261047644_0005 user: ubuntu leaf-queue of parent: root #applications: 4
2022-11-24 04:03:22,568 INFO org.apache.hadoop.yarn.server.resourcemanager.scheduler.capacity.CapacityScheduler: Accepted application application_1669261047644_0005 from user: ubuntu, in queue: default
2022-11-24 04:03:22,570 INFO org.apache.hadoop.yarn.server.resourcemanager.rmapp.RMAppImpl: application_1669261047644_0005 State change from SUBMITTED to ACCEPTED
2022-11-24 04:03:22,570 INFO org.apache.hadoop.yarn.server.resourcemanager.ApplicationMasterService: Registering app attempt : appattempt_1669261047644_0005_000001
2022-11-24 04:03:22,571 INFO org.apache.hadoop.yarn.server.resourcemanager.rmapp.attempt.RMAppAttemptImpl: appattempt_1669261047644_0005_000001 State change from NEW to SUBMITTED
2022-11-24 04:03:22,574 INFO org.apache.hadoop.yarn.server.resourcemanager.scheduler.capacity.LeafQueue: not starting application as amIfStarted exceeds amLimit
2022-11-24 04:03:22,574 INFO org.apache.hadoop.yarn.server.resourcemanager.scheduler.capacity.LeafQueue: not starting application as amIfStarted exceeds amLimit
2022-11-24 04:03:22,574 INFO org.apache.hadoop.yarn.server.resourcemanager.scheduler.capacity.LeafQueue: not starting application as amIfStarted exceeds amLimit
2022-11-24 04:03:22,574 INFO org.apache.hadoop.yarn.server.resourcemanager.scheduler.capacity.LeafQueue: Application added - appId: application_1669261047644_0005 user: org.apache.hadoop.yarn.server.resourcemanager.scheduler.capacity.LeafQueue$User@3607880d, leaf-queue: default #user-pending-applications: 3 #user-active-applications: 1 #queue-pending-applications: 3 #queue-active-applications: 1
2022-11-24 04:03:22,574 INFO org.apache.hadoop.yarn.server.resourcemanager.scheduler.capacity.CapacityScheduler: Added Application Attempt appattempt_1669261047644_0005_000001 to scheduler from user ubuntu in queue default
2022-11-24 04:03:22,575 INFO org.apache.hadoop.yarn.server.resourcemanager.rmapp.attempt.RMAppAttemptImpl: appattempt_1669261047644_0005_000001 State change from SUBMITTED to SCHEDULED
2022-11-24 04:04:58,386 INFO org.apache.hadoop.yarn.server.resourcemanager.ClientRMService: Allocated new applicationId: 6
2022-11-24 04:04:59,045 INFO org.apache.hadoop.yarn.server.resourcemanager.ClientRMService: Application with id 6 submitted by user ubuntu
2022-11-24 04:04:59,045 INFO org.apache.hadoop.yarn.server.resourcemanager.rmapp.RMAppImpl: Storing application with id application_1669261047644_0006
2022-11-24 04:04:59,045 INFO org.apache.hadoop.yarn.server.resourcemanager.RMAuditLogger: USER=ubuntu	IP=172.31.11.48	OPERATION=Submit Application Request	TARGET=ClientRMService	RESULT=SUCCESS	APPID=application_1669261047644_0006
2022-11-24 04:04:59,045 INFO org.apache.hadoop.yarn.server.resourcemanager.recovery.RMStateStore: Storing info for app: application_1669261047644_0006
2022-11-24 04:04:59,045 INFO org.apache.hadoop.yarn.server.resourcemanager.rmapp.RMAppImpl: application_1669261047644_0006 State change from NEW to NEW_SAVING
2022-11-24 04:04:59,045 INFO org.apache.hadoop.yarn.server.resourcemanager.rmapp.RMAppImpl: application_1669261047644_0006 State change from NEW_SAVING to SUBMITTED
2022-11-24 04:04:59,045 INFO org.apache.hadoop.yarn.server.resourcemanager.scheduler.capacity.ParentQueue: Application added - appId: application_1669261047644_0006 user: ubuntu leaf-queue of parent: root #applications: 5
2022-11-24 04:04:59,045 INFO org.apache.hadoop.yarn.server.resourcemanager.scheduler.capacity.CapacityScheduler: Accepted application application_1669261047644_0006 from user: ubuntu, in queue: default
2022-11-24 04:04:59,046 INFO org.apache.hadoop.yarn.server.resourcemanager.rmapp.RMAppImpl: application_1669261047644_0006 State change from SUBMITTED to ACCEPTED
2022-11-24 04:04:59,046 INFO org.apache.hadoop.yarn.server.resourcemanager.ApplicationMasterService: Registering app attempt : appattempt_1669261047644_0006_000001
2022-11-24 04:04:59,046 INFO org.apache.hadoop.yarn.server.resourcemanager.rmapp.attempt.RMAppAttemptImpl: appattempt_1669261047644_0006_000001 State change from NEW to SUBMITTED
2022-11-24 04:04:59,046 INFO org.apache.hadoop.yarn.server.resourcemanager.scheduler.capacity.LeafQueue: not starting application as amIfStarted exceeds amLimit
2022-11-24 04:04:59,046 INFO org.apache.hadoop.yarn.server.resourcemanager.scheduler.capacity.LeafQueue: not starting application as amIfStarted exceeds amLimit
2022-11-24 04:04:59,046 INFO org.apache.hadoop.yarn.server.resourcemanager.scheduler.capacity.LeafQueue: not starting application as amIfStarted exceeds amLimit
2022-11-24 04:04:59,046 INFO org.apache.hadoop.yarn.server.resourcemanager.scheduler.capacity.LeafQueue: not starting application as amIfStarted exceeds amLimit
2022-11-24 04:04:59,046 INFO org.apache.hadoop.yarn.server.resourcemanager.scheduler.capacity.LeafQueue: Application added - appId: application_1669261047644_0006 user: org.apache.hadoop.yarn.server.resourcemanager.scheduler.capacity.LeafQueue$User@3607880d, leaf-queue: default #user-pending-applications: 4 #user-active-applications: 1 #queue-pending-applications: 4 #queue-active-applications: 1
2022-11-24 04:04:59,046 INFO org.apache.hadoop.yarn.server.resourcemanager.scheduler.capacity.CapacityScheduler: Added Application Attempt appattempt_1669261047644_0006_000001 to scheduler from user ubuntu in queue default
2022-11-24 04:04:59,047 INFO org.apache.hadoop.yarn.server.resourcemanager.rmapp.attempt.RMAppAttemptImpl: appattempt_1669261047644_0006_000001 State change from SUBMITTED to SCHEDULED
2022-11-24 04:07:27,658 INFO org.apache.hadoop.yarn.server.resourcemanager.ClientRMService: Allocated new applicationId: 7
2022-11-24 04:10:47,680 INFO org.apache.hadoop.yarn.util.AbstractLivelinessMonitor: Expired:ip-172-31-0-65.ec2.internal:34785 Timed out after 600 secs
2022-11-24 04:10:47,680 INFO org.apache.hadoop.yarn.util.AbstractLivelinessMonitor: Expired:ip-172-31-3-214.ec2.internal:41855 Timed out after 600 secs
2022-11-24 04:10:47,681 INFO org.apache.hadoop.yarn.server.resourcemanager.rmnode.RMNodeImpl: Deactivating Node ip-172-31-0-65.ec2.internal:34785 as it is now LOST
2022-11-24 04:10:47,682 INFO org.apache.hadoop.yarn.server.resourcemanager.rmnode.RMNodeImpl: ip-172-31-0-65.ec2.internal:34785 Node Transitioned from RUNNING to LOST
2022-11-24 04:10:47,682 INFO org.apache.hadoop.yarn.server.resourcemanager.rmnode.RMNodeImpl: Deactivating Node ip-172-31-3-214.ec2.internal:41855 as it is now LOST
2022-11-24 04:10:47,682 INFO org.apache.hadoop.yarn.server.resourcemanager.rmnode.RMNodeImpl: ip-172-31-3-214.ec2.internal:41855 Node Transitioned from RUNNING to LOST
2022-11-24 04:10:47,682 INFO org.apache.hadoop.yarn.server.resourcemanager.scheduler.capacity.LeafQueue: not starting application as amIfStarted exceeds amLimit
2022-11-24 04:10:47,682 INFO org.apache.hadoop.yarn.server.resourcemanager.scheduler.capacity.LeafQueue: not starting application as amIfStarted exceeds amLimit
2022-11-24 04:10:47,682 INFO org.apache.hadoop.yarn.server.resourcemanager.scheduler.capacity.LeafQueue: not starting application as amIfStarted exceeds amLimit
2022-11-24 04:10:47,682 INFO org.apache.hadoop.yarn.server.resourcemanager.scheduler.capacity.LeafQueue: not starting application as amIfStarted exceeds amLimit
2022-11-24 04:10:47,684 INFO org.apache.hadoop.yarn.server.resourcemanager.rmcontainer.RMContainerImpl: container_1669261047644_0002_01_000001 Container Transitioned from RUNNING to KILLED
2022-11-24 04:10:47,685 INFO org.apache.hadoop.yarn.server.resourcemanager.scheduler.common.fica.FiCaSchedulerApp: Completed container: container_1669261047644_0002_01_000001 in state: KILLED event:KILL
2022-11-24 04:10:47,685 INFO org.apache.hadoop.yarn.server.resourcemanager.RMAuditLogger: USER=ubuntu	OPERATION=AM Released Container	TARGET=SchedulerApp	RESULT=SUCCESS	APPID=application_1669261047644_0002	CONTAINERID=container_1669261047644_0002_01_000001
2022-11-24 04:10:47,685 INFO org.apache.hadoop.yarn.server.resourcemanager.scheduler.SchedulerNode: Released container container_1669261047644_0002_01_000001 of capacity <memory:2048, vCores:1> on host ip-172-31-0-65.ec2.internal:34785, which currently has 1 containers, <memory:1024, vCores:1> used and <memory:7168, vCores:7> available, release resources=true
2022-11-24 04:10:47,685 INFO org.apache.hadoop.yarn.server.resourcemanager.scheduler.capacity.LeafQueue: default used=<memory:2048, vCores:2> numContainers=2 user=ubuntu user-resources=<memory:2048, vCores:2>
2022-11-24 04:10:47,685 INFO org.apache.hadoop.yarn.server.resourcemanager.scheduler.capacity.LeafQueue: completedContainer container=Container: [ContainerId: container_1669261047644_0002_01_000001, NodeId: ip-172-31-0-65.ec2.internal:34785, NodeHttpAddress: ip-172-31-0-65.ec2.internal:8042, Resource: <memory:2048, vCores:1>, Priority: 0, Token: Token { kind: ContainerToken, service: 172.31.0.65:34785 }, ] queue=default: capacity=1.0, absoluteCapacity=1.0, usedResources=<memory:2048, vCores:2>, usedCapacity=0.25, absoluteUsedCapacity=0.25, numApps=5, numContainers=2 cluster=<memory:8192, vCores:8>
2022-11-24 04:10:47,686 INFO org.apache.hadoop.yarn.server.resourcemanager.scheduler.capacity.ParentQueue: completedContainer queue=root usedCapacity=0.25 absoluteUsedCapacity=0.25 used=<memory:2048, vCores:2> cluster=<memory:8192, vCores:8>
2022-11-24 04:10:47,686 INFO org.apache.hadoop.yarn.server.resourcemanager.scheduler.capacity.ParentQueue: Re-sorting completed queue: root.default stats: default: capacity=1.0, absoluteCapacity=1.0, usedResources=<memory:2048, vCores:2>, usedCapacity=0.25, absoluteUsedCapacity=0.25, numApps=5, numContainers=2
2022-11-24 04:10:47,687 INFO org.apache.hadoop.yarn.server.resourcemanager.scheduler.capacity.CapacityScheduler: Application attempt appattempt_1669261047644_0002_000001 released container container_1669261047644_0002_01_000001 on node: host: ip-172-31-0-65.ec2.internal:34785 #containers=1 available=7168 used=1024 with event: KILL
2022-11-24 04:10:47,687 INFO org.apache.hadoop.yarn.server.resourcemanager.rmcontainer.RMContainerImpl: container_1669261047644_0002_01_000003 Container Transitioned from RUNNING to KILLED
2022-11-24 04:10:47,687 INFO org.apache.hadoop.yarn.server.resourcemanager.scheduler.common.fica.FiCaSchedulerApp: Completed container: container_1669261047644_0002_01_000003 in state: KILLED event:KILL
2022-11-24 04:10:47,687 INFO org.apache.hadoop.yarn.server.resourcemanager.RMAuditLogger: USER=ubuntu	OPERATION=AM Released Container	TARGET=SchedulerApp	RESULT=SUCCESS	APPID=application_1669261047644_0002	CONTAINERID=container_1669261047644_0002_01_000003
2022-11-24 04:10:47,687 INFO org.apache.hadoop.yarn.server.resourcemanager.scheduler.SchedulerNode: Released container container_1669261047644_0002_01_000003 of capacity <memory:1024, vCores:1> on host ip-172-31-0-65.ec2.internal:34785, which currently has 0 containers, <memory:0, vCores:0> used and <memory:8192, vCores:8> available, release resources=true
2022-11-24 04:10:47,687 INFO org.apache.hadoop.yarn.server.resourcemanager.scheduler.capacity.LeafQueue: default used=<memory:1024, vCores:1> numContainers=1 user=ubuntu user-resources=<memory:1024, vCores:1>
2022-11-24 04:10:47,689 INFO org.apache.hadoop.yarn.server.resourcemanager.rmapp.attempt.RMAppAttemptImpl: Updating application attempt appattempt_1669261047644_0002_000001 with final state: FAILED, and exit status: -100
2022-11-24 04:10:47,690 INFO org.apache.hadoop.yarn.server.resourcemanager.scheduler.capacity.LeafQueue: completedContainer container=Container: [ContainerId: container_1669261047644_0002_01_000003, NodeId: ip-172-31-0-65.ec2.internal:34785, NodeHttpAddress: ip-172-31-0-65.ec2.internal:8042, Resource: <memory:1024, vCores:1>, Priority: 10, Token: Token { kind: ContainerToken, service: 172.31.0.65:34785 }, ] queue=default: capacity=1.0, absoluteCapacity=1.0, usedResources=<memory:1024, vCores:1>, usedCapacity=0.125, absoluteUsedCapacity=0.125, numApps=5, numContainers=1 cluster=<memory:8192, vCores:8>
2022-11-24 04:10:47,691 INFO org.apache.hadoop.yarn.server.resourcemanager.scheduler.capacity.ParentQueue: completedContainer queue=root usedCapacity=0.125 absoluteUsedCapacity=0.125 used=<memory:1024, vCores:1> cluster=<memory:8192, vCores:8>
2022-11-24 04:10:47,691 INFO org.apache.hadoop.yarn.server.resourcemanager.scheduler.capacity.ParentQueue: Re-sorting completed queue: root.default stats: default: capacity=1.0, absoluteCapacity=1.0, usedResources=<memory:1024, vCores:1>, usedCapacity=0.125, absoluteUsedCapacity=0.125, numApps=5, numContainers=1
2022-11-24 04:10:47,691 INFO org.apache.hadoop.yarn.server.resourcemanager.scheduler.capacity.CapacityScheduler: Application attempt appattempt_1669261047644_0002_000001 released container container_1669261047644_0002_01_000003 on node: host: ip-172-31-0-65.ec2.internal:34785 #containers=0 available=8192 used=0 with event: KILL
2022-11-24 04:10:47,691 INFO org.apache.hadoop.yarn.server.resourcemanager.scheduler.capacity.CapacityScheduler: Removed node ip-172-31-0-65.ec2.internal:34785 clusterResource: <memory:8192, vCores:8>
2022-11-24 04:10:47,692 INFO org.apache.hadoop.yarn.server.resourcemanager.scheduler.capacity.LeafQueue: not starting application as amIfStarted exceeds amLimit
2022-11-24 04:10:47,692 INFO org.apache.hadoop.yarn.server.resourcemanager.scheduler.capacity.LeafQueue: not starting application as amIfStarted exceeds amLimit
2022-11-24 04:10:47,692 INFO org.apache.hadoop.yarn.server.resourcemanager.scheduler.capacity.LeafQueue: not starting application as amIfStarted exceeds amLimit
2022-11-24 04:10:47,692 INFO org.apache.hadoop.yarn.server.resourcemanager.scheduler.capacity.LeafQueue: not starting application as amIfStarted exceeds amLimit
2022-11-24 04:10:47,692 INFO org.apache.hadoop.yarn.server.resourcemanager.rmcontainer.RMContainerImpl: container_1669261047644_0002_01_000002 Container Transitioned from RUNNING to KILLED
2022-11-24 04:10:47,692 INFO org.apache.hadoop.yarn.server.resourcemanager.scheduler.common.fica.FiCaSchedulerApp: Completed container: container_1669261047644_0002_01_000002 in state: KILLED event:KILL
2022-11-24 04:10:47,692 INFO org.apache.hadoop.yarn.server.resourcemanager.RMAuditLogger: USER=ubuntu	OPERATION=AM Released Container	TARGET=SchedulerApp	RESULT=SUCCESS	APPID=application_1669261047644_0002	CONTAINERID=container_1669261047644_0002_01_000002
2022-11-24 04:10:47,692 INFO org.apache.hadoop.yarn.server.resourcemanager.scheduler.SchedulerNode: Released container container_1669261047644_0002_01_000002 of capacity <memory:1024, vCores:1> on host ip-172-31-3-214.ec2.internal:41855, which currently has 0 containers, <memory:0, vCores:0> used and <memory:8192, vCores:8> available, release resources=true
2022-11-24 04:10:47,692 INFO org.apache.hadoop.yarn.server.resourcemanager.scheduler.capacity.LeafQueue: default used=<memory:0, vCores:0> numContainers=0 user=ubuntu user-resources=<memory:0, vCores:0>
2022-11-24 04:10:47,692 INFO org.apache.hadoop.yarn.server.resourcemanager.rmapp.attempt.RMAppAttemptImpl: appattempt_1669261047644_0002_000001 State change from RUNNING to FINAL_SAVING
2022-11-24 04:10:47,694 INFO org.apache.hadoop.yarn.server.resourcemanager.ApplicationMasterService: Unregistering app attempt : appattempt_1669261047644_0002_000001
2022-11-24 04:10:47,695 INFO org.apache.hadoop.yarn.server.resourcemanager.scheduler.capacity.LeafQueue: completedContainer container=Container: [ContainerId: container_1669261047644_0002_01_000002, NodeId: ip-172-31-3-214.ec2.internal:41855, NodeHttpAddress: ip-172-31-3-214.ec2.internal:8042, Resource: <memory:1024, vCores:1>, Priority: 20, Token: Token { kind: ContainerToken, service: 172.31.3.214:41855 }, ] queue=default: capacity=1.0, absoluteCapacity=1.0, usedResources=<memory:0, vCores:0>, usedCapacity=0.0, absoluteUsedCapacity=0.0, numApps=5, numContainers=0 cluster=<memory:0, vCores:0>
2022-11-24 04:10:47,695 INFO org.apache.hadoop.yarn.server.resourcemanager.scheduler.capacity.ParentQueue: completedContainer queue=root usedCapacity=0.0 absoluteUsedCapacity=0.0 used=<memory:0, vCores:0> cluster=<memory:0, vCores:0>
2022-11-24 04:10:47,695 INFO org.apache.hadoop.yarn.server.resourcemanager.scheduler.capacity.ParentQueue: Re-sorting completed queue: root.default stats: default: capacity=1.0, absoluteCapacity=1.0, usedResources=<memory:0, vCores:0>, usedCapacity=0.0, absoluteUsedCapacity=0.0, numApps=5, numContainers=0
2022-11-24 04:10:47,695 INFO org.apache.hadoop.yarn.server.resourcemanager.scheduler.capacity.CapacityScheduler: Application attempt appattempt_1669261047644_0002_000001 released container container_1669261047644_0002_01_000002 on node: host: ip-172-31-3-214.ec2.internal:41855 #containers=0 available=8192 used=0 with event: KILL
2022-11-24 04:10:47,695 INFO org.apache.hadoop.yarn.server.resourcemanager.security.AMRMTokenSecretManager: Application finished, removing password for appattempt_1669261047644_0002_000001
2022-11-24 04:10:47,695 INFO org.apache.hadoop.yarn.server.resourcemanager.scheduler.capacity.CapacityScheduler: Removed node ip-172-31-3-214.ec2.internal:41855 clusterResource: <memory:0, vCores:0>
2022-11-24 04:10:47,696 INFO org.apache.hadoop.yarn.server.resourcemanager.rmapp.attempt.RMAppAttemptImpl: appattempt_1669261047644_0002_000001 State change from FINAL_SAVING to FAILED
2022-11-24 04:10:47,696 INFO org.apache.hadoop.yarn.server.resourcemanager.rmapp.RMAppImpl: The number of failed attempts is 0. The max attempts is 2
2022-11-24 04:10:47,696 INFO org.apache.hadoop.yarn.server.resourcemanager.rmapp.RMAppImpl: application_1669261047644_0002 State change from RUNNING to ACCEPTED
2022-11-24 04:10:47,696 INFO org.apache.hadoop.yarn.server.resourcemanager.scheduler.capacity.CapacityScheduler: Application Attempt appattempt_1669261047644_0002_000001 is done. finalState=FAILED
2022-11-24 04:10:47,696 INFO org.apache.hadoop.yarn.server.resourcemanager.ApplicationMasterService: Registering app attempt : appattempt_1669261047644_0002_000002
2022-11-24 04:10:47,696 INFO org.apache.hadoop.yarn.server.resourcemanager.scheduler.AppSchedulingInfo: Application application_1669261047644_0002 requests cleared
2022-11-24 04:10:47,696 INFO org.apache.hadoop.yarn.server.resourcemanager.rmapp.attempt.RMAppAttemptImpl: appattempt_1669261047644_0002_000002 State change from NEW to SUBMITTED
2022-11-24 04:10:47,697 WARN org.apache.hadoop.yarn.server.resourcemanager.scheduler.capacity.LeafQueue: maximum-am-resource-percent is insufficient to start a single application in queue, it is likely set too low. skipping enforcement to allow at least one application to start
2022-11-24 04:10:47,697 WARN org.apache.hadoop.yarn.server.resourcemanager.scheduler.capacity.LeafQueue: maximum-am-resource-percent is insufficient to start a single application in queue for user, it is likely set too low. skipping enforcement to allow at least one application to start
2022-11-24 04:10:47,697 INFO org.apache.hadoop.yarn.server.resourcemanager.scheduler.capacity.LeafQueue: Application application_1669261047644_0003 from user: ubuntu activated in queue: default
2022-11-24 04:10:47,697 INFO org.apache.hadoop.yarn.server.resourcemanager.scheduler.capacity.LeafQueue: not starting application as amIfStarted exceeds amLimit
2022-11-24 04:10:47,698 INFO org.apache.hadoop.yarn.server.resourcemanager.scheduler.capacity.LeafQueue: not starting application as amIfStarted exceeds amLimit
2022-11-24 04:10:47,698 INFO org.apache.hadoop.yarn.server.resourcemanager.scheduler.capacity.LeafQueue: not starting application as amIfStarted exceeds amLimit
2022-11-24 04:10:47,698 INFO org.apache.hadoop.yarn.server.resourcemanager.scheduler.capacity.LeafQueue: Application removed - appId: application_1669261047644_0002 user: ubuntu queue: default #user-pending-applications: 3 #user-active-applications: 1 #queue-pending-applications: 3 #queue-active-applications: 1
2022-11-24 04:10:47,698 INFO org.apache.hadoop.yarn.server.resourcemanager.scheduler.capacity.LeafQueue: not starting application as amIfStarted exceeds amLimit
2022-11-24 04:10:47,698 INFO org.apache.hadoop.yarn.server.resourcemanager.scheduler.capacity.LeafQueue: not starting application as amIfStarted exceeds amLimit
2022-11-24 04:10:47,698 INFO org.apache.hadoop.yarn.server.resourcemanager.scheduler.capacity.LeafQueue: not starting application as amIfStarted exceeds amLimit
2022-11-24 04:10:47,698 INFO org.apache.hadoop.yarn.server.resourcemanager.scheduler.capacity.LeafQueue: not starting application as amIfStarted exceeds amLimit
2022-11-24 04:10:47,698 INFO org.apache.hadoop.yarn.server.resourcemanager.scheduler.capacity.LeafQueue: Application added - appId: application_1669261047644_0002 user: org.apache.hadoop.yarn.server.resourcemanager.scheduler.capacity.LeafQueue$User@3607880d, leaf-queue: default #user-pending-applications: 4 #user-active-applications: 1 #queue-pending-applications: 4 #queue-active-applications: 1
2022-11-24 04:10:47,698 INFO org.apache.hadoop.yarn.server.resourcemanager.scheduler.capacity.CapacityScheduler: Added Application Attempt appattempt_1669261047644_0002_000002 to scheduler from user ubuntu in queue default
2022-11-24 04:10:47,697 INFO org.apache.hadoop.yarn.server.resourcemanager.amlauncher.AMLauncher: Cleaning master appattempt_1669261047644_0002_000001
2022-11-24 04:10:47,699 INFO org.apache.hadoop.yarn.server.resourcemanager.rmapp.attempt.RMAppAttemptImpl: appattempt_1669261047644_0002_000002 State change from SUBMITTED to SCHEDULED
2022-11-24 04:10:48,209 ERROR org.apache.hadoop.yarn.server.resourcemanager.ApplicationMasterService: Application attempt appattempt_1669261047644_0002_000001 doesn't exist in ApplicationMasterService cache.
2022-11-24 04:10:48,210 INFO org.apache.hadoop.ipc.Server: IPC Server handler 2 on 8030, call org.apache.hadoop.yarn.api.ApplicationMasterProtocolPB.allocate from 172.31.0.65:46738 Call#731 Retry#0
org.apache.hadoop.yarn.exceptions.ApplicationAttemptNotFoundException: Application attempt appattempt_1669261047644_0002_000001 doesn't exist in ApplicationMasterService cache.
	at org.apache.hadoop.yarn.server.resourcemanager.ApplicationMasterService.allocate(ApplicationMasterService.java:436)
	at org.apache.hadoop.yarn.api.impl.pb.service.ApplicationMasterProtocolPBServiceImpl.allocate(ApplicationMasterProtocolPBServiceImpl.java:60)
	at org.apache.hadoop.yarn.proto.ApplicationMasterProtocol$ApplicationMasterProtocolService$2.callBlockingMethod(ApplicationMasterProtocol.java:99)
	at org.apache.hadoop.ipc.ProtobufRpcEngine$Server$ProtoBufRpcInvoker.call(ProtobufRpcEngine.java:619)
	at org.apache.hadoop.ipc.RPC$Server.call(RPC.java:975)
	at org.apache.hadoop.ipc.Server$Handler$1.run(Server.java:2040)
	at org.apache.hadoop.ipc.Server$Handler$1.run(Server.java:2036)
	at java.security.AccessController.doPrivileged(Native Method)
	at javax.security.auth.Subject.doAs(Subject.java:422)
	at org.apache.hadoop.security.UserGroupInformation.doAs(UserGroupInformation.java:1692)
	at org.apache.hadoop.ipc.Server$Handler.run(Server.java:2034)
2022-11-24 04:10:57,461 INFO org.apache.hadoop.yarn.server.resourcemanager.ClientRMService: Allocated new applicationId: 8
2022-11-24 04:10:58,096 INFO org.apache.hadoop.yarn.server.resourcemanager.ClientRMService: Application with id 8 submitted by user ubuntu
2022-11-24 04:10:58,096 INFO org.apache.hadoop.yarn.server.resourcemanager.rmapp.RMAppImpl: Storing application with id application_1669261047644_0008
2022-11-24 04:10:58,096 INFO org.apache.hadoop.yarn.server.resourcemanager.RMAuditLogger: USER=ubuntu	IP=172.31.11.48	OPERATION=Submit Application Request	TARGET=ClientRMService	RESULT=SUCCESS	APPID=application_1669261047644_0008
2022-11-24 04:10:58,097 INFO org.apache.hadoop.yarn.server.resourcemanager.recovery.RMStateStore: Storing info for app: application_1669261047644_0008
2022-11-24 04:10:58,096 INFO org.apache.hadoop.yarn.server.resourcemanager.rmapp.RMAppImpl: application_1669261047644_0008 State change from NEW to NEW_SAVING
2022-11-24 04:10:58,097 INFO org.apache.hadoop.yarn.server.resourcemanager.rmapp.RMAppImpl: application_1669261047644_0008 State change from NEW_SAVING to SUBMITTED
2022-11-24 04:10:58,097 INFO org.apache.hadoop.yarn.server.resourcemanager.scheduler.capacity.ParentQueue: Application added - appId: application_1669261047644_0008 user: ubuntu leaf-queue of parent: root #applications: 6
2022-11-24 04:10:58,097 INFO org.apache.hadoop.yarn.server.resourcemanager.scheduler.capacity.CapacityScheduler: Accepted application application_1669261047644_0008 from user: ubuntu, in queue: default
2022-11-24 04:10:58,097 INFO org.apache.hadoop.yarn.server.resourcemanager.rmapp.RMAppImpl: application_1669261047644_0008 State change from SUBMITTED to ACCEPTED
2022-11-24 04:10:58,097 INFO org.apache.hadoop.yarn.server.resourcemanager.ApplicationMasterService: Registering app attempt : appattempt_1669261047644_0008_000001
2022-11-24 04:10:58,097 INFO org.apache.hadoop.yarn.server.resourcemanager.rmapp.attempt.RMAppAttemptImpl: appattempt_1669261047644_0008_000001 State change from NEW to SUBMITTED
2022-11-24 04:10:58,098 INFO org.apache.hadoop.yarn.server.resourcemanager.scheduler.capacity.LeafQueue: not starting application as amIfStarted exceeds amLimit
2022-11-24 04:10:58,098 INFO org.apache.hadoop.yarn.server.resourcemanager.scheduler.capacity.LeafQueue: not starting application as amIfStarted exceeds amLimit
2022-11-24 04:10:58,098 INFO org.apache.hadoop.yarn.server.resourcemanager.scheduler.capacity.LeafQueue: not starting application as amIfStarted exceeds amLimit
2022-11-24 04:10:58,098 INFO org.apache.hadoop.yarn.server.resourcemanager.scheduler.capacity.LeafQueue: not starting application as amIfStarted exceeds amLimit
2022-11-24 04:10:58,098 INFO org.apache.hadoop.yarn.server.resourcemanager.scheduler.capacity.LeafQueue: not starting application as amIfStarted exceeds amLimit
2022-11-24 04:10:58,098 INFO org.apache.hadoop.yarn.server.resourcemanager.scheduler.capacity.LeafQueue: Application added - appId: application_1669261047644_0008 user: org.apache.hadoop.yarn.server.resourcemanager.scheduler.capacity.LeafQueue$User@3607880d, leaf-queue: default #user-pending-applications: 5 #user-active-applications: 1 #queue-pending-applications: 5 #queue-active-applications: 1
2022-11-24 04:10:58,098 INFO org.apache.hadoop.yarn.server.resourcemanager.scheduler.capacity.CapacityScheduler: Added Application Attempt appattempt_1669261047644_0008_000001 to scheduler from user ubuntu in queue default
2022-11-24 04:10:58,099 INFO org.apache.hadoop.yarn.server.resourcemanager.rmapp.attempt.RMAppAttemptImpl: appattempt_1669261047644_0008_000001 State change from SUBMITTED to SCHEDULED
2022-11-24 04:13:47,750 INFO org.apache.hadoop.yarn.server.resourcemanager.amlauncher.AMLauncher: Error cleaning master 
java.net.ConnectException: Call From ip-172-31-11-48/172.31.11.48 to ip-172-31-0-65.ec2.internal:34785 failed on connection exception: java.net.ConnectException: Connection refused; For more details see:  http://wiki.apache.org/hadoop/ConnectionRefused
	at sun.reflect.GeneratedConstructorAccessor20.newInstance(Unknown Source)
	at sun.reflect.DelegatingConstructorAccessorImpl.newInstance(DelegatingConstructorAccessorImpl.java:45)
	at java.lang.reflect.Constructor.newInstance(Constructor.java:423)
	at org.apache.hadoop.net.NetUtils.wrapWithMessage(NetUtils.java:791)
	at org.apache.hadoop.net.NetUtils.wrapException(NetUtils.java:731)
	at org.apache.hadoop.ipc.Client.call(Client.java:1474)
	at org.apache.hadoop.ipc.Client.call(Client.java:1401)
	at org.apache.hadoop.ipc.ProtobufRpcEngine$Invoker.invoke(ProtobufRpcEngine.java:232)
	at com.sun.proxy.$Proxy32.stopContainers(Unknown Source)
	at org.apache.hadoop.yarn.api.impl.pb.client.ContainerManagementProtocolPBClientImpl.stopContainers(ContainerManagementProtocolPBClientImpl.java:110)
	at sun.reflect.GeneratedMethodAccessor10.invoke(Unknown Source)
	at sun.reflect.DelegatingMethodAccessorImpl.invoke(DelegatingMethodAccessorImpl.java:43)
	at java.lang.reflect.Method.invoke(Method.java:498)
	at org.apache.hadoop.io.retry.RetryInvocationHandler.invokeMethod(RetryInvocationHandler.java:187)
	at org.apache.hadoop.io.retry.RetryInvocationHandler.invoke(RetryInvocationHandler.java:102)
	at com.sun.proxy.$Proxy33.stopContainers(Unknown Source)
	at org.apache.hadoop.yarn.server.resourcemanager.amlauncher.AMLauncher.cleanup(AMLauncher.java:139)
	at org.apache.hadoop.yarn.server.resourcemanager.amlauncher.AMLauncher.run(AMLauncher.java:265)
	at java.util.concurrent.ThreadPoolExecutor.runWorker(ThreadPoolExecutor.java:1149)
	at java.util.concurrent.ThreadPoolExecutor$Worker.run(ThreadPoolExecutor.java:624)
	at java.lang.Thread.run(Thread.java:750)
Caused by: java.net.ConnectException: Connection refused
	at sun.nio.ch.SocketChannelImpl.checkConnect(Native Method)
	at sun.nio.ch.SocketChannelImpl.finishConnect(SocketChannelImpl.java:716)
	at org.apache.hadoop.net.SocketIOWithTimeout.connect(SocketIOWithTimeout.java:206)
	at org.apache.hadoop.net.NetUtils.connect(NetUtils.java:530)
	at org.apache.hadoop.net.NetUtils.connect(NetUtils.java:494)
	at org.apache.hadoop.ipc.Client$Connection.setupConnection(Client.java:609)
	at org.apache.hadoop.ipc.Client$Connection.setupIOstreams(Client.java:707)
	at org.apache.hadoop.ipc.Client$Connection.access$2800(Client.java:370)
	at org.apache.hadoop.ipc.Client.getConnection(Client.java:1523)
	at org.apache.hadoop.ipc.Client.call(Client.java:1440)
	... 15 more
2022-11-24 04:16:16,667 INFO org.apache.hadoop.yarn.server.resourcemanager.ClientRMService: Allocated new applicationId: 9
2022-11-24 04:16:17,288 INFO org.apache.hadoop.yarn.server.resourcemanager.ClientRMService: Application with id 9 submitted by user ubuntu
2022-11-24 04:16:17,288 INFO org.apache.hadoop.yarn.server.resourcemanager.rmapp.RMAppImpl: Storing application with id application_1669261047644_0009
2022-11-24 04:16:17,289 INFO org.apache.hadoop.yarn.server.resourcemanager.rmapp.RMAppImpl: application_1669261047644_0009 State change from NEW to NEW_SAVING
2022-11-24 04:16:17,289 INFO org.apache.hadoop.yarn.server.resourcemanager.recovery.RMStateStore: Storing info for app: application_1669261047644_0009
2022-11-24 04:16:17,289 INFO org.apache.hadoop.yarn.server.resourcemanager.rmapp.RMAppImpl: application_1669261047644_0009 State change from NEW_SAVING to SUBMITTED
2022-11-24 04:16:17,289 INFO org.apache.hadoop.yarn.server.resourcemanager.RMAuditLogger: USER=ubuntu	IP=172.31.11.48	OPERATION=Submit Application Request	TARGET=ClientRMService	RESULT=SUCCESS	APPID=application_1669261047644_0009
2022-11-24 04:16:17,289 INFO org.apache.hadoop.yarn.server.resourcemanager.scheduler.capacity.ParentQueue: Application added - appId: application_1669261047644_0009 user: ubuntu leaf-queue of parent: root #applications: 7
2022-11-24 04:16:17,289 INFO org.apache.hadoop.yarn.server.resourcemanager.scheduler.capacity.CapacityScheduler: Accepted application application_1669261047644_0009 from user: ubuntu, in queue: default
2022-11-24 04:16:17,289 INFO org.apache.hadoop.yarn.server.resourcemanager.rmapp.RMAppImpl: application_1669261047644_0009 State change from SUBMITTED to ACCEPTED
2022-11-24 04:16:17,290 INFO org.apache.hadoop.yarn.server.resourcemanager.ApplicationMasterService: Registering app attempt : appattempt_1669261047644_0009_000001
2022-11-24 04:16:17,290 INFO org.apache.hadoop.yarn.server.resourcemanager.rmapp.attempt.RMAppAttemptImpl: appattempt_1669261047644_0009_000001 State change from NEW to SUBMITTED
2022-11-24 04:16:17,290 INFO org.apache.hadoop.yarn.server.resourcemanager.scheduler.capacity.LeafQueue: not starting application as amIfStarted exceeds amLimit
2022-11-24 04:16:17,290 INFO org.apache.hadoop.yarn.server.resourcemanager.scheduler.capacity.LeafQueue: not starting application as amIfStarted exceeds amLimit
2022-11-24 04:16:17,290 INFO org.apache.hadoop.yarn.server.resourcemanager.scheduler.capacity.LeafQueue: not starting application as amIfStarted exceeds amLimit
2022-11-24 04:16:17,290 INFO org.apache.hadoop.yarn.server.resourcemanager.scheduler.capacity.LeafQueue: not starting application as amIfStarted exceeds amLimit
2022-11-24 04:16:17,290 INFO org.apache.hadoop.yarn.server.resourcemanager.scheduler.capacity.LeafQueue: not starting application as amIfStarted exceeds amLimit
2022-11-24 04:16:17,290 INFO org.apache.hadoop.yarn.server.resourcemanager.scheduler.capacity.LeafQueue: not starting application as amIfStarted exceeds amLimit
2022-11-24 04:16:17,290 INFO org.apache.hadoop.yarn.server.resourcemanager.scheduler.capacity.LeafQueue: Application added - appId: application_1669261047644_0009 user: org.apache.hadoop.yarn.server.resourcemanager.scheduler.capacity.LeafQueue$User@3607880d, leaf-queue: default #user-pending-applications: 6 #user-active-applications: 1 #queue-pending-applications: 6 #queue-active-applications: 1
2022-11-24 04:16:17,290 INFO org.apache.hadoop.yarn.server.resourcemanager.scheduler.capacity.CapacityScheduler: Added Application Attempt appattempt_1669261047644_0009_000001 to scheduler from user ubuntu in queue default
2022-11-24 04:16:17,291 INFO org.apache.hadoop.yarn.server.resourcemanager.rmapp.attempt.RMAppAttemptImpl: appattempt_1669261047644_0009_000001 State change from SUBMITTED to SCHEDULED
2022-11-24 04:20:52,752 INFO org.apache.hadoop.yarn.server.resourcemanager.ClientRMService: Allocated new applicationId: 10
2022-11-24 04:20:53,416 INFO org.apache.hadoop.yarn.server.resourcemanager.ClientRMService: Application with id 10 submitted by user ubuntu
2022-11-24 04:20:53,416 INFO org.apache.hadoop.yarn.server.resourcemanager.RMAuditLogger: USER=ubuntu	IP=172.31.11.48	OPERATION=Submit Application Request	TARGET=ClientRMService	RESULT=SUCCESS	APPID=application_1669261047644_0010
2022-11-24 04:20:53,418 INFO org.apache.hadoop.yarn.server.resourcemanager.rmapp.RMAppImpl: Storing application with id application_1669261047644_0010
2022-11-24 04:20:53,418 INFO org.apache.hadoop.yarn.server.resourcemanager.rmapp.RMAppImpl: application_1669261047644_0010 State change from NEW to NEW_SAVING
2022-11-24 04:20:53,418 INFO org.apache.hadoop.yarn.server.resourcemanager.recovery.RMStateStore: Storing info for app: application_1669261047644_0010
2022-11-24 04:20:53,418 INFO org.apache.hadoop.yarn.server.resourcemanager.rmapp.RMAppImpl: application_1669261047644_0010 State change from NEW_SAVING to SUBMITTED
2022-11-24 04:20:53,418 INFO org.apache.hadoop.yarn.server.resourcemanager.scheduler.capacity.ParentQueue: Application added - appId: application_1669261047644_0010 user: ubuntu leaf-queue of parent: root #applications: 8
2022-11-24 04:20:53,418 INFO org.apache.hadoop.yarn.server.resourcemanager.scheduler.capacity.CapacityScheduler: Accepted application application_1669261047644_0010 from user: ubuntu, in queue: default
2022-11-24 04:20:53,419 INFO org.apache.hadoop.yarn.server.resourcemanager.rmapp.RMAppImpl: application_1669261047644_0010 State change from SUBMITTED to ACCEPTED
2022-11-24 04:20:53,419 INFO org.apache.hadoop.yarn.server.resourcemanager.ApplicationMasterService: Registering app attempt : appattempt_1669261047644_0010_000001
2022-11-24 04:20:53,419 INFO org.apache.hadoop.yarn.server.resourcemanager.rmapp.attempt.RMAppAttemptImpl: appattempt_1669261047644_0010_000001 State change from NEW to SUBMITTED
2022-11-24 04:20:53,419 INFO org.apache.hadoop.yarn.server.resourcemanager.scheduler.capacity.LeafQueue: not starting application as amIfStarted exceeds amLimit
2022-11-24 04:20:53,419 INFO org.apache.hadoop.yarn.server.resourcemanager.scheduler.capacity.LeafQueue: not starting application as amIfStarted exceeds amLimit
2022-11-24 04:20:53,419 INFO org.apache.hadoop.yarn.server.resourcemanager.scheduler.capacity.LeafQueue: not starting application as amIfStarted exceeds amLimit
2022-11-24 04:20:53,419 INFO org.apache.hadoop.yarn.server.resourcemanager.scheduler.capacity.LeafQueue: not starting application as amIfStarted exceeds amLimit
2022-11-24 04:20:53,419 INFO org.apache.hadoop.yarn.server.resourcemanager.scheduler.capacity.LeafQueue: not starting application as amIfStarted exceeds amLimit
2022-11-24 04:20:53,419 INFO org.apache.hadoop.yarn.server.resourcemanager.scheduler.capacity.LeafQueue: not starting application as amIfStarted exceeds amLimit
2022-11-24 04:20:53,419 INFO org.apache.hadoop.yarn.server.resourcemanager.scheduler.capacity.LeafQueue: not starting application as amIfStarted exceeds amLimit
2022-11-24 04:20:53,419 INFO org.apache.hadoop.yarn.server.resourcemanager.scheduler.capacity.LeafQueue: Application added - appId: application_1669261047644_0010 user: org.apache.hadoop.yarn.server.resourcemanager.scheduler.capacity.LeafQueue$User@3607880d, leaf-queue: default #user-pending-applications: 7 #user-active-applications: 1 #queue-pending-applications: 7 #queue-active-applications: 1
2022-11-24 04:20:53,419 INFO org.apache.hadoop.yarn.server.resourcemanager.scheduler.capacity.CapacityScheduler: Added Application Attempt appattempt_1669261047644_0010_000001 to scheduler from user ubuntu in queue default
2022-11-24 04:20:53,419 INFO org.apache.hadoop.yarn.server.resourcemanager.rmapp.attempt.RMAppAttemptImpl: appattempt_1669261047644_0010_000001 State change from SUBMITTED to SCHEDULED
2022-11-24 04:23:50,343 INFO org.apache.hadoop.yarn.server.resourcemanager.ClientRMService: Allocated new applicationId: 11
2022-11-24 04:23:50,964 INFO org.apache.hadoop.yarn.server.resourcemanager.ClientRMService: Application with id 11 submitted by user ubuntu
2022-11-24 04:23:50,964 INFO org.apache.hadoop.yarn.server.resourcemanager.RMAuditLogger: USER=ubuntu	IP=172.31.11.48	OPERATION=Submit Application Request	TARGET=ClientRMService	RESULT=SUCCESS	APPID=application_1669261047644_0011
2022-11-24 04:23:50,964 INFO org.apache.hadoop.yarn.server.resourcemanager.rmapp.RMAppImpl: Storing application with id application_1669261047644_0011
2022-11-24 04:23:50,964 INFO org.apache.hadoop.yarn.server.resourcemanager.rmapp.RMAppImpl: application_1669261047644_0011 State change from NEW to NEW_SAVING
2022-11-24 04:23:50,967 INFO org.apache.hadoop.yarn.server.resourcemanager.recovery.RMStateStore: Storing info for app: application_1669261047644_0011
2022-11-24 04:23:50,967 INFO org.apache.hadoop.yarn.server.resourcemanager.rmapp.RMAppImpl: application_1669261047644_0011 State change from NEW_SAVING to SUBMITTED
2022-11-24 04:23:50,967 INFO org.apache.hadoop.yarn.server.resourcemanager.scheduler.capacity.ParentQueue: Application added - appId: application_1669261047644_0011 user: ubuntu leaf-queue of parent: root #applications: 9
2022-11-24 04:23:50,967 INFO org.apache.hadoop.yarn.server.resourcemanager.scheduler.capacity.CapacityScheduler: Accepted application application_1669261047644_0011 from user: ubuntu, in queue: default
2022-11-24 04:23:50,967 INFO org.apache.hadoop.yarn.server.resourcemanager.rmapp.RMAppImpl: application_1669261047644_0011 State change from SUBMITTED to ACCEPTED
2022-11-24 04:23:50,967 INFO org.apache.hadoop.yarn.server.resourcemanager.ApplicationMasterService: Registering app attempt : appattempt_1669261047644_0011_000001
2022-11-24 04:23:50,967 INFO org.apache.hadoop.yarn.server.resourcemanager.rmapp.attempt.RMAppAttemptImpl: appattempt_1669261047644_0011_000001 State change from NEW to SUBMITTED
2022-11-24 04:23:50,967 INFO org.apache.hadoop.yarn.server.resourcemanager.scheduler.capacity.LeafQueue: not starting application as amIfStarted exceeds amLimit
2022-11-24 04:23:50,968 INFO org.apache.hadoop.yarn.server.resourcemanager.scheduler.capacity.LeafQueue: not starting application as amIfStarted exceeds amLimit
2022-11-24 04:23:50,968 INFO org.apache.hadoop.yarn.server.resourcemanager.scheduler.capacity.LeafQueue: not starting application as amIfStarted exceeds amLimit
2022-11-24 04:23:50,968 INFO org.apache.hadoop.yarn.server.resourcemanager.scheduler.capacity.LeafQueue: not starting application as amIfStarted exceeds amLimit
2022-11-24 04:23:50,968 INFO org.apache.hadoop.yarn.server.resourcemanager.scheduler.capacity.LeafQueue: not starting application as amIfStarted exceeds amLimit
2022-11-24 04:23:50,968 INFO org.apache.hadoop.yarn.server.resourcemanager.scheduler.capacity.LeafQueue: not starting application as amIfStarted exceeds amLimit
2022-11-24 04:23:50,968 INFO org.apache.hadoop.yarn.server.resourcemanager.scheduler.capacity.LeafQueue: not starting application as amIfStarted exceeds amLimit
2022-11-24 04:23:50,968 INFO org.apache.hadoop.yarn.server.resourcemanager.scheduler.capacity.LeafQueue: not starting application as amIfStarted exceeds amLimit
2022-11-24 04:23:50,968 INFO org.apache.hadoop.yarn.server.resourcemanager.scheduler.capacity.LeafQueue: Application added - appId: application_1669261047644_0011 user: org.apache.hadoop.yarn.server.resourcemanager.scheduler.capacity.LeafQueue$User@3607880d, leaf-queue: default #user-pending-applications: 8 #user-active-applications: 1 #queue-pending-applications: 8 #queue-active-applications: 1
2022-11-24 04:23:50,968 INFO org.apache.hadoop.yarn.server.resourcemanager.scheduler.capacity.CapacityScheduler: Added Application Attempt appattempt_1669261047644_0011_000001 to scheduler from user ubuntu in queue default
2022-11-24 04:23:50,973 INFO org.apache.hadoop.yarn.server.resourcemanager.rmapp.attempt.RMAppAttemptImpl: appattempt_1669261047644_0011_000001 State change from SUBMITTED to SCHEDULED
2022-11-24 04:24:59,129 INFO org.apache.hadoop.yarn.server.resourcemanager.ClientRMService: Allocated new applicationId: 12
2022-11-24 04:24:59,737 INFO org.apache.hadoop.yarn.server.resourcemanager.ClientRMService: Application with id 12 submitted by user ubuntu
2022-11-24 04:24:59,737 INFO org.apache.hadoop.yarn.server.resourcemanager.rmapp.RMAppImpl: Storing application with id application_1669261047644_0012
2022-11-24 04:24:59,737 INFO org.apache.hadoop.yarn.server.resourcemanager.RMAuditLogger: USER=ubuntu	IP=172.31.11.48	OPERATION=Submit Application Request	TARGET=ClientRMService	RESULT=SUCCESS	APPID=application_1669261047644_0012
2022-11-24 04:24:59,737 INFO org.apache.hadoop.yarn.server.resourcemanager.rmapp.RMAppImpl: application_1669261047644_0012 State change from NEW to NEW_SAVING
2022-11-24 04:24:59,737 INFO org.apache.hadoop.yarn.server.resourcemanager.recovery.RMStateStore: Storing info for app: application_1669261047644_0012
2022-11-24 04:24:59,737 INFO org.apache.hadoop.yarn.server.resourcemanager.rmapp.RMAppImpl: application_1669261047644_0012 State change from NEW_SAVING to SUBMITTED
2022-11-24 04:24:59,737 INFO org.apache.hadoop.yarn.server.resourcemanager.scheduler.capacity.ParentQueue: Application added - appId: application_1669261047644_0012 user: ubuntu leaf-queue of parent: root #applications: 10
2022-11-24 04:24:59,737 INFO org.apache.hadoop.yarn.server.resourcemanager.scheduler.capacity.CapacityScheduler: Accepted application application_1669261047644_0012 from user: ubuntu, in queue: default
2022-11-24 04:24:59,737 INFO org.apache.hadoop.yarn.server.resourcemanager.rmapp.RMAppImpl: application_1669261047644_0012 State change from SUBMITTED to ACCEPTED
2022-11-24 04:24:59,738 INFO org.apache.hadoop.yarn.server.resourcemanager.ApplicationMasterService: Registering app attempt : appattempt_1669261047644_0012_000001
2022-11-24 04:24:59,738 INFO org.apache.hadoop.yarn.server.resourcemanager.rmapp.attempt.RMAppAttemptImpl: appattempt_1669261047644_0012_000001 State change from NEW to SUBMITTED
2022-11-24 04:24:59,738 INFO org.apache.hadoop.yarn.server.resourcemanager.scheduler.capacity.LeafQueue: not starting application as amIfStarted exceeds amLimit
2022-11-24 04:24:59,738 INFO org.apache.hadoop.yarn.server.resourcemanager.scheduler.capacity.LeafQueue: not starting application as amIfStarted exceeds amLimit
2022-11-24 04:24:59,738 INFO org.apache.hadoop.yarn.server.resourcemanager.scheduler.capacity.LeafQueue: not starting application as amIfStarted exceeds amLimit
2022-11-24 04:24:59,738 INFO org.apache.hadoop.yarn.server.resourcemanager.scheduler.capacity.LeafQueue: not starting application as amIfStarted exceeds amLimit
2022-11-24 04:24:59,738 INFO org.apache.hadoop.yarn.server.resourcemanager.scheduler.capacity.LeafQueue: not starting application as amIfStarted exceeds amLimit
2022-11-24 04:24:59,738 INFO org.apache.hadoop.yarn.server.resourcemanager.scheduler.capacity.LeafQueue: not starting application as amIfStarted exceeds amLimit
2022-11-24 04:24:59,738 INFO org.apache.hadoop.yarn.server.resourcemanager.scheduler.capacity.LeafQueue: not starting application as amIfStarted exceeds amLimit
2022-11-24 04:24:59,738 INFO org.apache.hadoop.yarn.server.resourcemanager.scheduler.capacity.LeafQueue: not starting application as amIfStarted exceeds amLimit
2022-11-24 04:24:59,738 INFO org.apache.hadoop.yarn.server.resourcemanager.scheduler.capacity.LeafQueue: not starting application as amIfStarted exceeds amLimit
2022-11-24 04:24:59,738 INFO org.apache.hadoop.yarn.server.resourcemanager.scheduler.capacity.LeafQueue: Application added - appId: application_1669261047644_0012 user: org.apache.hadoop.yarn.server.resourcemanager.scheduler.capacity.LeafQueue$User@3607880d, leaf-queue: default #user-pending-applications: 9 #user-active-applications: 1 #queue-pending-applications: 9 #queue-active-applications: 1
2022-11-24 04:24:59,738 INFO org.apache.hadoop.yarn.server.resourcemanager.scheduler.capacity.CapacityScheduler: Added Application Attempt appattempt_1669261047644_0012_000001 to scheduler from user ubuntu in queue default
2022-11-24 04:24:59,738 INFO org.apache.hadoop.yarn.server.resourcemanager.rmapp.attempt.RMAppAttemptImpl: appattempt_1669261047644_0012_000001 State change from SUBMITTED to SCHEDULED
2022-11-24 04:27:21,296 INFO org.apache.hadoop.yarn.server.resourcemanager.ClientRMService: Allocated new applicationId: 13
2022-11-24 04:27:21,990 INFO org.apache.hadoop.yarn.server.resourcemanager.ClientRMService: Application with id 13 submitted by user ubuntu
2022-11-24 04:27:21,990 INFO org.apache.hadoop.yarn.server.resourcemanager.RMAuditLogger: USER=ubuntu	IP=172.31.11.48	OPERATION=Submit Application Request	TARGET=ClientRMService	RESULT=SUCCESS	APPID=application_1669261047644_0013
2022-11-24 04:27:21,990 INFO org.apache.hadoop.yarn.server.resourcemanager.rmapp.RMAppImpl: Storing application with id application_1669261047644_0013
2022-11-24 04:27:21,990 INFO org.apache.hadoop.yarn.server.resourcemanager.rmapp.RMAppImpl: application_1669261047644_0013 State change from NEW to NEW_SAVING
2022-11-24 04:27:21,990 INFO org.apache.hadoop.yarn.server.resourcemanager.recovery.RMStateStore: Storing info for app: application_1669261047644_0013
2022-11-24 04:27:21,990 INFO org.apache.hadoop.yarn.server.resourcemanager.rmapp.RMAppImpl: application_1669261047644_0013 State change from NEW_SAVING to SUBMITTED
2022-11-24 04:27:21,990 INFO org.apache.hadoop.yarn.server.resourcemanager.scheduler.capacity.ParentQueue: Application added - appId: application_1669261047644_0013 user: ubuntu leaf-queue of parent: root #applications: 11
2022-11-24 04:27:21,990 INFO org.apache.hadoop.yarn.server.resourcemanager.scheduler.capacity.CapacityScheduler: Accepted application application_1669261047644_0013 from user: ubuntu, in queue: default
2022-11-24 04:27:21,990 INFO org.apache.hadoop.yarn.server.resourcemanager.rmapp.RMAppImpl: application_1669261047644_0013 State change from SUBMITTED to ACCEPTED
2022-11-24 04:27:21,991 INFO org.apache.hadoop.yarn.server.resourcemanager.ApplicationMasterService: Registering app attempt : appattempt_1669261047644_0013_000001
2022-11-24 04:27:21,991 INFO org.apache.hadoop.yarn.server.resourcemanager.rmapp.attempt.RMAppAttemptImpl: appattempt_1669261047644_0013_000001 State change from NEW to SUBMITTED
2022-11-24 04:27:21,992 INFO org.apache.hadoop.yarn.server.resourcemanager.scheduler.capacity.LeafQueue: not starting application as amIfStarted exceeds amLimit
2022-11-24 04:27:21,992 INFO org.apache.hadoop.yarn.server.resourcemanager.scheduler.capacity.LeafQueue: not starting application as amIfStarted exceeds amLimit
2022-11-24 04:27:21,992 INFO org.apache.hadoop.yarn.server.resourcemanager.scheduler.capacity.LeafQueue: not starting application as amIfStarted exceeds amLimit
2022-11-24 04:27:21,992 INFO org.apache.hadoop.yarn.server.resourcemanager.scheduler.capacity.LeafQueue: not starting application as amIfStarted exceeds amLimit
2022-11-24 04:27:21,992 INFO org.apache.hadoop.yarn.server.resourcemanager.scheduler.capacity.LeafQueue: not starting application as amIfStarted exceeds amLimit
2022-11-24 04:27:21,992 INFO org.apache.hadoop.yarn.server.resourcemanager.scheduler.capacity.LeafQueue: not starting application as amIfStarted exceeds amLimit
2022-11-24 04:27:21,992 INFO org.apache.hadoop.yarn.server.resourcemanager.scheduler.capacity.LeafQueue: not starting application as amIfStarted exceeds amLimit
2022-11-24 04:27:21,992 INFO org.apache.hadoop.yarn.server.resourcemanager.scheduler.capacity.LeafQueue: not starting application as amIfStarted exceeds amLimit
2022-11-24 04:27:21,992 INFO org.apache.hadoop.yarn.server.resourcemanager.scheduler.capacity.LeafQueue: not starting application as amIfStarted exceeds amLimit
2022-11-24 04:27:21,992 INFO org.apache.hadoop.yarn.server.resourcemanager.scheduler.capacity.LeafQueue: not starting application as amIfStarted exceeds amLimit
2022-11-24 04:27:21,992 INFO org.apache.hadoop.yarn.server.resourcemanager.scheduler.capacity.LeafQueue: Application added - appId: application_1669261047644_0013 user: org.apache.hadoop.yarn.server.resourcemanager.scheduler.capacity.LeafQueue$User@3607880d, leaf-queue: default #user-pending-applications: 10 #user-active-applications: 1 #queue-pending-applications: 10 #queue-active-applications: 1
2022-11-24 04:27:21,992 INFO org.apache.hadoop.yarn.server.resourcemanager.scheduler.capacity.CapacityScheduler: Added Application Attempt appattempt_1669261047644_0013_000001 to scheduler from user ubuntu in queue default
2022-11-24 04:27:21,992 INFO org.apache.hadoop.yarn.server.resourcemanager.rmapp.attempt.RMAppAttemptImpl: appattempt_1669261047644_0013_000001 State change from SUBMITTED to SCHEDULED
2022-11-24 04:27:30,825 INFO org.apache.hadoop.yarn.server.resourcemanager.ClientRMService: Allocated new applicationId: 14
2022-11-24 04:27:31,473 INFO org.apache.hadoop.yarn.server.resourcemanager.ClientRMService: Application with id 14 submitted by user ubuntu
2022-11-24 04:27:31,473 INFO org.apache.hadoop.yarn.server.resourcemanager.rmapp.RMAppImpl: Storing application with id application_1669261047644_0014
2022-11-24 04:27:31,473 INFO org.apache.hadoop.yarn.server.resourcemanager.rmapp.RMAppImpl: application_1669261047644_0014 State change from NEW to NEW_SAVING
2022-11-24 04:27:31,473 INFO org.apache.hadoop.yarn.server.resourcemanager.recovery.RMStateStore: Storing info for app: application_1669261047644_0014
2022-11-24 04:27:31,473 INFO org.apache.hadoop.yarn.server.resourcemanager.rmapp.RMAppImpl: application_1669261047644_0014 State change from NEW_SAVING to SUBMITTED
2022-11-24 04:27:31,473 INFO org.apache.hadoop.yarn.server.resourcemanager.scheduler.capacity.ParentQueue: Application added - appId: application_1669261047644_0014 user: ubuntu leaf-queue of parent: root #applications: 12
2022-11-24 04:27:31,473 INFO org.apache.hadoop.yarn.server.resourcemanager.scheduler.capacity.CapacityScheduler: Accepted application application_1669261047644_0014 from user: ubuntu, in queue: default
2022-11-24 04:27:31,473 INFO org.apache.hadoop.yarn.server.resourcemanager.RMAuditLogger: USER=ubuntu	IP=172.31.11.48	OPERATION=Submit Application Request	TARGET=ClientRMService	RESULT=SUCCESS	APPID=application_1669261047644_0014
2022-11-24 04:27:31,474 INFO org.apache.hadoop.yarn.server.resourcemanager.rmapp.RMAppImpl: application_1669261047644_0014 State change from SUBMITTED to ACCEPTED
2022-11-24 04:27:31,474 INFO org.apache.hadoop.yarn.server.resourcemanager.ApplicationMasterService: Registering app attempt : appattempt_1669261047644_0014_000001
2022-11-24 04:27:31,474 INFO org.apache.hadoop.yarn.server.resourcemanager.rmapp.attempt.RMAppAttemptImpl: appattempt_1669261047644_0014_000001 State change from NEW to SUBMITTED
2022-11-24 04:27:31,474 INFO org.apache.hadoop.yarn.server.resourcemanager.scheduler.capacity.LeafQueue: not starting application as amIfStarted exceeds amLimit
2022-11-24 04:27:31,474 INFO org.apache.hadoop.yarn.server.resourcemanager.scheduler.capacity.LeafQueue: not starting application as amIfStarted exceeds amLimit
2022-11-24 04:27:31,474 INFO org.apache.hadoop.yarn.server.resourcemanager.scheduler.capacity.LeafQueue: not starting application as amIfStarted exceeds amLimit
2022-11-24 04:27:31,474 INFO org.apache.hadoop.yarn.server.resourcemanager.scheduler.capacity.LeafQueue: not starting application as amIfStarted exceeds amLimit
2022-11-24 04:27:31,474 INFO org.apache.hadoop.yarn.server.resourcemanager.scheduler.capacity.LeafQueue: not starting application as amIfStarted exceeds amLimit
2022-11-24 04:27:31,474 INFO org.apache.hadoop.yarn.server.resourcemanager.scheduler.capacity.LeafQueue: not starting application as amIfStarted exceeds amLimit
2022-11-24 04:27:31,474 INFO org.apache.hadoop.yarn.server.resourcemanager.scheduler.capacity.LeafQueue: not starting application as amIfStarted exceeds amLimit
2022-11-24 04:27:31,474 INFO org.apache.hadoop.yarn.server.resourcemanager.scheduler.capacity.LeafQueue: not starting application as amIfStarted exceeds amLimit
2022-11-24 04:27:31,474 INFO org.apache.hadoop.yarn.server.resourcemanager.scheduler.capacity.LeafQueue: not starting application as amIfStarted exceeds amLimit
2022-11-24 04:27:31,474 INFO org.apache.hadoop.yarn.server.resourcemanager.scheduler.capacity.LeafQueue: not starting application as amIfStarted exceeds amLimit
2022-11-24 04:27:31,474 INFO org.apache.hadoop.yarn.server.resourcemanager.scheduler.capacity.LeafQueue: not starting application as amIfStarted exceeds amLimit
2022-11-24 04:27:31,474 INFO org.apache.hadoop.yarn.server.resourcemanager.scheduler.capacity.LeafQueue: Application added - appId: application_1669261047644_0014 user: org.apache.hadoop.yarn.server.resourcemanager.scheduler.capacity.LeafQueue$User@3607880d, leaf-queue: default #user-pending-applications: 11 #user-active-applications: 1 #queue-pending-applications: 11 #queue-active-applications: 1
2022-11-24 04:27:31,474 INFO org.apache.hadoop.yarn.server.resourcemanager.scheduler.capacity.CapacityScheduler: Added Application Attempt appattempt_1669261047644_0014_000001 to scheduler from user ubuntu in queue default
2022-11-24 04:27:31,474 INFO org.apache.hadoop.yarn.server.resourcemanager.rmapp.attempt.RMAppAttemptImpl: appattempt_1669261047644_0014_000001 State change from SUBMITTED to SCHEDULED
2022-11-24 04:29:09,946 ERROR org.apache.hadoop.yarn.server.resourcemanager.ResourceManager: RECEIVED SIGNAL 15: SIGTERM
2022-11-24 04:29:09,948 ERROR org.apache.hadoop.security.token.delegation.AbstractDelegationTokenSecretManager: ExpiredTokenRemover received java.lang.InterruptedException: sleep interrupted
2022-11-24 04:29:09,949 INFO org.mortbay.log: Stopped HttpServer2$SelectChannelConnectorWithSafeStartup@172.31.11.48:8088
2022-11-24 04:29:09,949 ERROR org.apache.hadoop.security.token.delegation.AbstractDelegationTokenSecretManager: ExpiredTokenRemover received java.lang.InterruptedException: sleep interrupted
2022-11-24 04:29:09,958 ERROR org.apache.hadoop.security.token.delegation.AbstractDelegationTokenSecretManager: ExpiredTokenRemover received java.lang.InterruptedException: sleep interrupted
2022-11-24 04:29:10,060 INFO org.apache.hadoop.ipc.Server: Stopping server on 8032
2022-11-24 04:29:10,064 INFO org.apache.hadoop.ipc.Server: Stopping IPC Server listener on 8032
2022-11-24 04:29:10,066 INFO org.apache.hadoop.ipc.Server: Stopping IPC Server Responder
2022-11-24 04:29:10,066 INFO org.apache.hadoop.ipc.Server: Stopping server on 8033
2022-11-24 04:29:10,067 INFO org.apache.hadoop.ipc.Server: Stopping IPC Server listener on 8033
2022-11-24 04:29:10,067 INFO org.apache.hadoop.ipc.Server: Stopping IPC Server Responder
2022-11-24 04:29:10,070 INFO org.apache.hadoop.yarn.server.resourcemanager.ResourceManager: Transitioning to standby state
2022-11-24 04:29:10,070 WARN org.apache.hadoop.yarn.server.resourcemanager.amlauncher.ApplicationMasterLauncher: org.apache.hadoop.yarn.server.resourcemanager.amlauncher.ApplicationMasterLauncher$LauncherThread interrupted. Returning.
2022-11-24 04:29:10,071 INFO org.apache.hadoop.ipc.Server: Stopping server on 8030
2022-11-24 04:29:10,077 INFO org.apache.hadoop.ipc.Server: Stopping IPC Server listener on 8030
2022-11-24 04:29:10,077 INFO org.apache.hadoop.ipc.Server: Stopping IPC Server Responder
2022-11-24 04:29:10,077 INFO org.apache.hadoop.ipc.Server: Stopping server on 8031
2022-11-24 04:29:10,084 INFO org.apache.hadoop.ipc.Server: Stopping IPC Server listener on 8031
2022-11-24 04:29:10,084 INFO org.apache.hadoop.ipc.Server: Stopping IPC Server Responder
2022-11-24 04:29:10,085 INFO org.apache.hadoop.yarn.util.AbstractLivelinessMonitor: NMLivelinessMonitor thread interrupted
2022-11-24 04:29:10,085 ERROR org.apache.hadoop.yarn.server.resourcemanager.ResourceManager: Returning, interrupted : java.lang.InterruptedException
2022-11-24 04:29:10,085 INFO org.apache.hadoop.yarn.util.AbstractLivelinessMonitor: AMLivelinessMonitor thread interrupted
2022-11-24 04:29:10,085 INFO org.apache.hadoop.yarn.util.AbstractLivelinessMonitor: AMLivelinessMonitor thread interrupted
2022-11-24 04:29:10,085 INFO org.apache.hadoop.yarn.util.AbstractLivelinessMonitor: org.apache.hadoop.yarn.server.resourcemanager.rmcontainer.ContainerAllocationExpirer thread interrupted
2022-11-24 04:29:10,085 ERROR org.apache.hadoop.security.token.delegation.AbstractDelegationTokenSecretManager: ExpiredTokenRemover received java.lang.InterruptedException: sleep interrupted
2022-11-24 04:29:10,086 INFO org.apache.hadoop.metrics2.impl.MetricsSystemImpl: Stopping ResourceManager metrics system...
2022-11-24 04:29:10,086 INFO org.apache.hadoop.metrics2.impl.MetricsSystemImpl: ResourceManager metrics system stopped.
2022-11-24 04:29:10,086 INFO org.apache.hadoop.metrics2.impl.MetricsSystemImpl: ResourceManager metrics system shutdown complete.
2022-11-24 04:29:10,087 INFO org.apache.hadoop.yarn.event.AsyncDispatcher: AsyncDispatcher is draining to stop, igonring any new events.
2022-11-24 04:29:10,087 INFO org.apache.hadoop.yarn.server.resourcemanager.ResourceManager: Transitioned to standby state
2022-11-24 04:29:10,087 INFO org.apache.hadoop.yarn.server.resourcemanager.ResourceManager: SHUTDOWN_MSG: 
/************************************************************
SHUTDOWN_MSG: Shutting down ResourceManager at ip-172-31-11-48/172.31.11.48
************************************************************/
2022-11-24 04:30:48,855 INFO org.apache.hadoop.yarn.server.resourcemanager.ResourceManager: STARTUP_MSG: 
/************************************************************
STARTUP_MSG: Starting ResourceManager
STARTUP_MSG:   host = ip-172-31-11-48/172.31.11.48
STARTUP_MSG:   args = []
STARTUP_MSG:   version = 2.6.5
STARTUP_MSG:   build = https://github.com/apache/hadoop.git -r e8c9fe0b4c252caf2ebf1464220599650f119997; compiled by 'sjlee' on 2016-10-02T23:43Z
STARTUP_MSG:   java = 1.8.0_352
************************************************************/
2022-11-24 04:30:48,867 INFO org.apache.hadoop.yarn.server.resourcemanager.ResourceManager: registered UNIX signal handlers for [TERM, HUP, INT]
2022-11-24 04:30:49,119 INFO org.apache.hadoop.conf.Configuration: found resource core-site.xml at file:/usr/local/hadoop/etc/hadoop/core-site.xml
2022-11-24 04:30:49,200 INFO org.apache.hadoop.security.Groups: clearing userToGroupsMap cache
2022-11-24 04:30:49,257 INFO org.apache.hadoop.conf.Configuration: found resource yarn-site.xml at file:/usr/local/hadoop/etc/hadoop/yarn-site.xml
2022-11-24 04:30:49,436 INFO org.apache.hadoop.yarn.event.AsyncDispatcher: Registering class org.apache.hadoop.yarn.server.resourcemanager.RMFatalEventType for class org.apache.hadoop.yarn.server.resourcemanager.ResourceManager$RMFatalEventDispatcher
2022-11-24 04:30:49,525 INFO org.apache.hadoop.yarn.server.resourcemanager.security.NMTokenSecretManagerInRM: NMTokenKeyRollingInterval: 86400000ms and NMTokenKeyActivationDelay: 900000ms
2022-11-24 04:30:49,529 INFO org.apache.hadoop.yarn.server.resourcemanager.security.RMContainerTokenSecretManager: ContainerTokenKeyRollingInterval: 86400000ms and ContainerTokenKeyActivationDelay: 900000ms
2022-11-24 04:30:49,543 INFO org.apache.hadoop.yarn.server.resourcemanager.security.AMRMTokenSecretManager: AMRMTokenKeyRollingInterval: 86400000ms and AMRMTokenKeyActivationDelay: 900000 ms
2022-11-24 04:30:49,566 INFO org.apache.hadoop.yarn.event.AsyncDispatcher: Registering class org.apache.hadoop.yarn.server.resourcemanager.recovery.RMStateStoreEventType for class org.apache.hadoop.yarn.server.resourcemanager.recovery.RMStateStore$ForwardingEventHandler
2022-11-24 04:30:49,567 INFO org.apache.hadoop.yarn.event.AsyncDispatcher: Registering class org.apache.hadoop.yarn.server.resourcemanager.NodesListManagerEventType for class org.apache.hadoop.yarn.server.resourcemanager.NodesListManager
2022-11-24 04:30:49,567 INFO org.apache.hadoop.yarn.server.resourcemanager.ResourceManager: Using Scheduler: org.apache.hadoop.yarn.server.resourcemanager.scheduler.capacity.CapacityScheduler
2022-11-24 04:30:49,581 INFO org.apache.hadoop.yarn.event.AsyncDispatcher: Registering class org.apache.hadoop.yarn.server.resourcemanager.scheduler.event.SchedulerEventType for class org.apache.hadoop.yarn.server.resourcemanager.ResourceManager$SchedulerEventDispatcher
2022-11-24 04:30:49,581 INFO org.apache.hadoop.yarn.event.AsyncDispatcher: Registering class org.apache.hadoop.yarn.server.resourcemanager.rmapp.RMAppEventType for class org.apache.hadoop.yarn.server.resourcemanager.ResourceManager$ApplicationEventDispatcher
2022-11-24 04:30:49,582 INFO org.apache.hadoop.yarn.event.AsyncDispatcher: Registering class org.apache.hadoop.yarn.server.resourcemanager.rmapp.attempt.RMAppAttemptEventType for class org.apache.hadoop.yarn.server.resourcemanager.ResourceManager$ApplicationAttemptEventDispatcher
2022-11-24 04:30:49,583 INFO org.apache.hadoop.yarn.event.AsyncDispatcher: Registering class org.apache.hadoop.yarn.server.resourcemanager.rmnode.RMNodeEventType for class org.apache.hadoop.yarn.server.resourcemanager.ResourceManager$NodeEventDispatcher
2022-11-24 04:30:49,638 INFO org.apache.hadoop.metrics2.impl.MetricsConfig: loaded properties from hadoop-metrics2.properties
2022-11-24 04:30:49,731 INFO org.apache.hadoop.metrics2.impl.MetricsSystemImpl: Scheduled snapshot period at 10 second(s).
2022-11-24 04:30:49,731 INFO org.apache.hadoop.metrics2.impl.MetricsSystemImpl: ResourceManager metrics system started
2022-11-24 04:30:49,744 INFO org.apache.hadoop.yarn.event.AsyncDispatcher: Registering class org.apache.hadoop.yarn.server.resourcemanager.RMAppManagerEventType for class org.apache.hadoop.yarn.server.resourcemanager.RMAppManager
2022-11-24 04:30:49,759 INFO org.apache.hadoop.yarn.event.AsyncDispatcher: Registering class org.apache.hadoop.yarn.server.resourcemanager.amlauncher.AMLauncherEventType for class org.apache.hadoop.yarn.server.resourcemanager.amlauncher.ApplicationMasterLauncher
2022-11-24 04:30:49,762 INFO org.apache.hadoop.yarn.server.resourcemanager.RMNMInfo: Registered RMNMInfo MBean
2022-11-24 04:30:49,763 INFO org.apache.hadoop.util.HostsFileReader: Refreshing hosts (include/exclude) list
2022-11-24 04:30:49,767 INFO org.apache.hadoop.conf.Configuration: found resource capacity-scheduler.xml at file:/usr/local/hadoop/etc/hadoop/capacity-scheduler.xml
2022-11-24 04:30:49,818 INFO org.apache.hadoop.yarn.server.resourcemanager.scheduler.capacity.ParentQueue: root, capacity=1.0, asboluteCapacity=1.0, maxCapacity=1.0, asboluteMaxCapacity=1.0, state=RUNNING, acls=SUBMIT_APPLICATIONS:*ADMINISTER_QUEUE:*, labels=*,
, reservationsContinueLooking=true
2022-11-24 04:30:49,818 INFO org.apache.hadoop.yarn.server.resourcemanager.scheduler.capacity.ParentQueue: Initialized parent-queue root name=root, fullname=root
2022-11-24 04:30:49,826 INFO org.apache.hadoop.yarn.server.resourcemanager.scheduler.capacity.LeafQueue: Initializing default
capacity = 1.0 [= (float) configuredCapacity / 100 ]
asboluteCapacity = 1.0 [= parentAbsoluteCapacity * capacity ]
maxCapacity = 1.0 [= configuredMaxCapacity ]
absoluteMaxCapacity = 1.0 [= 1.0 maximumCapacity undefined, (parentAbsoluteMaxCapacity * maximumCapacity) / 100 otherwise ]
userLimit = 100 [= configuredUserLimit ]
userLimitFactor = 1.0 [= configuredUserLimitFactor ]
maxApplications = 10000 [= configuredMaximumSystemApplicationsPerQueue or (int)(configuredMaximumSystemApplications * absoluteCapacity)]
maxApplicationsPerUser = 10000 [= (int)(maxApplications * (userLimit / 100.0f) * userLimitFactor) ]
usedCapacity = 0.0 [= usedResourcesMemory / (clusterResourceMemory * absoluteCapacity)]
absoluteUsedCapacity = 0.0 [= usedResourcesMemory / clusterResourceMemory]
maxAMResourcePerQueuePercent = 0.1 [= configuredMaximumAMResourcePercent ]
minimumAllocationFactor = 0.875 [= (float)(maximumAllocationMemory - minimumAllocationMemory) / maximumAllocationMemory ]
numContainers = 0 [= currentNumContainers ]
state = RUNNING [= configuredState ]
acls = SUBMIT_APPLICATIONS:*ADMINISTER_QUEUE:* [= configuredAcls ]
nodeLocalityDelay = 40
labels=*,
nodeLocalityDelay = 40
reservationsContinueLooking = true

2022-11-24 04:30:49,826 INFO org.apache.hadoop.yarn.server.resourcemanager.scheduler.capacity.CapacityScheduler: Initialized queue: default: capacity=1.0, absoluteCapacity=1.0, usedResources=<memory:0, vCores:0>, usedCapacity=0.0, absoluteUsedCapacity=0.0, numApps=0, numContainers=0
2022-11-24 04:30:49,827 INFO org.apache.hadoop.yarn.server.resourcemanager.scheduler.capacity.CapacityScheduler: Initialized queue: root: numChildQueue= 1, capacity=1.0, absoluteCapacity=1.0, usedResources=<memory:0, vCores:0>usedCapacity=0.0, numApps=0, numContainers=0
2022-11-24 04:30:49,828 INFO org.apache.hadoop.yarn.server.resourcemanager.scheduler.capacity.CapacityScheduler: Initialized root queue root: numChildQueue= 1, capacity=1.0, absoluteCapacity=1.0, usedResources=<memory:0, vCores:0>usedCapacity=0.0, numApps=0, numContainers=0
2022-11-24 04:30:49,828 INFO org.apache.hadoop.yarn.server.resourcemanager.scheduler.capacity.CapacityScheduler: Initialized queue mappings, override: false
2022-11-24 04:30:49,828 INFO org.apache.hadoop.yarn.server.resourcemanager.scheduler.capacity.CapacityScheduler: Initialized CapacityScheduler with calculator=class org.apache.hadoop.yarn.util.resource.DefaultResourceCalculator, minimumAllocation=<<memory:1024, vCores:1>>, maximumAllocation=<<memory:8192, vCores:32>>, asynchronousScheduling=false, asyncScheduleInterval=5ms
2022-11-24 04:30:49,835 INFO org.apache.hadoop.yarn.server.resourcemanager.metrics.SystemMetricsPublisher: YARN system metrics publishing service is not enabled
2022-11-24 04:30:49,835 INFO org.apache.hadoop.yarn.server.resourcemanager.ResourceManager: Transitioning to active state
2022-11-24 04:30:49,849 INFO org.apache.hadoop.yarn.server.resourcemanager.security.RMContainerTokenSecretManager: Rolling master-key for container-tokens
2022-11-24 04:30:49,849 INFO org.apache.hadoop.yarn.server.resourcemanager.security.NMTokenSecretManagerInRM: Rolling master-key for nm-tokens
2022-11-24 04:30:49,849 INFO org.apache.hadoop.security.token.delegation.AbstractDelegationTokenSecretManager: Updating the current master key for generating delegation tokens
2022-11-24 04:30:49,850 INFO org.apache.hadoop.yarn.server.resourcemanager.security.RMDelegationTokenSecretManager: storing master key with keyID 1
2022-11-24 04:30:49,852 INFO org.apache.hadoop.security.token.delegation.AbstractDelegationTokenSecretManager: Starting expired delegation token remover thread, tokenRemoverScanInterval=60 min(s)
2022-11-24 04:30:49,852 INFO org.apache.hadoop.security.token.delegation.AbstractDelegationTokenSecretManager: Updating the current master key for generating delegation tokens
2022-11-24 04:30:49,852 INFO org.apache.hadoop.yarn.server.resourcemanager.security.RMDelegationTokenSecretManager: storing master key with keyID 2
2022-11-24 04:30:49,878 INFO org.apache.hadoop.ipc.CallQueueManager: Using callQueue: class java.util.concurrent.LinkedBlockingQueue queueCapacity: 5000
2022-11-24 04:30:49,889 INFO org.apache.hadoop.ipc.Server: Starting Socket Reader #1 for port 8031
2022-11-24 04:30:49,906 INFO org.apache.hadoop.yarn.factories.impl.pb.RpcServerFactoryPBImpl: Adding protocol org.apache.hadoop.yarn.server.api.ResourceTrackerPB to the server
2022-11-24 04:30:49,906 INFO org.apache.hadoop.ipc.Server: IPC Server Responder: starting
2022-11-24 04:30:49,910 INFO org.apache.hadoop.ipc.Server: IPC Server listener on 8031: starting
2022-11-24 04:30:49,934 INFO org.apache.hadoop.ipc.CallQueueManager: Using callQueue: class java.util.concurrent.LinkedBlockingQueue queueCapacity: 5000
2022-11-24 04:30:49,940 INFO org.apache.hadoop.ipc.Server: Starting Socket Reader #1 for port 8030
2022-11-24 04:30:49,948 INFO org.apache.hadoop.yarn.factories.impl.pb.RpcServerFactoryPBImpl: Adding protocol org.apache.hadoop.yarn.api.ApplicationMasterProtocolPB to the server
2022-11-24 04:30:49,950 INFO org.apache.hadoop.ipc.Server: IPC Server Responder: starting
2022-11-24 04:30:49,950 INFO org.apache.hadoop.ipc.Server: IPC Server listener on 8030: starting
2022-11-24 04:30:50,005 INFO org.apache.hadoop.ipc.CallQueueManager: Using callQueue: class java.util.concurrent.LinkedBlockingQueue queueCapacity: 5000
2022-11-24 04:30:50,006 INFO org.apache.hadoop.ipc.Server: Starting Socket Reader #1 for port 8032
2022-11-24 04:30:50,008 INFO org.apache.hadoop.yarn.factories.impl.pb.RpcServerFactoryPBImpl: Adding protocol org.apache.hadoop.yarn.api.ApplicationClientProtocolPB to the server
2022-11-24 04:30:50,009 INFO org.apache.hadoop.ipc.Server: IPC Server Responder: starting
2022-11-24 04:30:50,009 INFO org.apache.hadoop.ipc.Server: IPC Server listener on 8032: starting
2022-11-24 04:30:50,025 INFO org.apache.hadoop.yarn.server.resourcemanager.ResourceManager: Transitioned to active state
2022-11-24 04:30:50,076 INFO org.mortbay.log: Logging to org.slf4j.impl.Log4jLoggerAdapter(org.mortbay.log) via org.mortbay.log.Slf4jLog
2022-11-24 04:30:50,079 INFO org.apache.hadoop.http.HttpRequestLog: Http request log for http.requests.resourcemanager is not defined
2022-11-24 04:30:50,088 INFO org.apache.hadoop.http.HttpServer2: Added global filter 'safety' (class=org.apache.hadoop.http.HttpServer2$QuotingInputFilter)
2022-11-24 04:30:50,095 INFO org.apache.hadoop.http.HttpServer2: Added filter RMAuthenticationFilter (class=org.apache.hadoop.yarn.server.security.http.RMAuthenticationFilter) to context cluster
2022-11-24 04:30:50,095 INFO org.apache.hadoop.http.HttpServer2: Added filter RMAuthenticationFilter (class=org.apache.hadoop.yarn.server.security.http.RMAuthenticationFilter) to context logs
2022-11-24 04:30:50,095 INFO org.apache.hadoop.http.HttpServer2: Added filter RMAuthenticationFilter (class=org.apache.hadoop.yarn.server.security.http.RMAuthenticationFilter) to context static
2022-11-24 04:30:50,095 INFO org.apache.hadoop.http.HttpServer2: Added filter static_user_filter (class=org.apache.hadoop.http.lib.StaticUserWebFilter$StaticUserFilter) to context cluster
2022-11-24 04:30:50,095 INFO org.apache.hadoop.http.HttpServer2: Added filter static_user_filter (class=org.apache.hadoop.http.lib.StaticUserWebFilter$StaticUserFilter) to context logs
2022-11-24 04:30:50,095 INFO org.apache.hadoop.http.HttpServer2: Added filter static_user_filter (class=org.apache.hadoop.http.lib.StaticUserWebFilter$StaticUserFilter) to context static
2022-11-24 04:30:50,098 INFO org.apache.hadoop.http.HttpServer2: adding path spec: /cluster/*
2022-11-24 04:30:50,099 INFO org.apache.hadoop.http.HttpServer2: adding path spec: /ws/*
2022-11-24 04:30:50,108 INFO org.apache.hadoop.http.HttpServer2: Jetty bound to port 8088
2022-11-24 04:30:50,108 INFO org.mortbay.log: jetty-6.1.26
2022-11-24 04:30:50,134 INFO org.mortbay.log: Extract jar:file:/usr/local/hadoop/share/hadoop/yarn/hadoop-yarn-common-2.6.5.jar!/webapps/cluster to /tmp/Jetty_172_31_11_48_8088_cluster____.cj96d9/webapp
2022-11-24 04:30:50,283 INFO org.apache.hadoop.security.token.delegation.AbstractDelegationTokenSecretManager: Updating the current master key for generating delegation tokens
2022-11-24 04:30:50,284 INFO org.apache.hadoop.security.token.delegation.AbstractDelegationTokenSecretManager: Starting expired delegation token remover thread, tokenRemoverScanInterval=60 min(s)
2022-11-24 04:30:50,284 INFO org.apache.hadoop.security.token.delegation.AbstractDelegationTokenSecretManager: Updating the current master key for generating delegation tokens
2022-11-24 04:30:50,310 INFO org.apache.hadoop.security.token.delegation.AbstractDelegationTokenSecretManager: Updating the current master key for generating delegation tokens
2022-11-24 04:30:50,311 INFO org.apache.hadoop.security.token.delegation.AbstractDelegationTokenSecretManager: Starting expired delegation token remover thread, tokenRemoverScanInterval=60 min(s)
2022-11-24 04:30:50,311 INFO org.apache.hadoop.security.token.delegation.AbstractDelegationTokenSecretManager: Updating the current master key for generating delegation tokens
2022-11-24 04:30:50,314 INFO org.apache.hadoop.security.token.delegation.AbstractDelegationTokenSecretManager: Updating the current master key for generating delegation tokens
2022-11-24 04:30:50,315 INFO org.apache.hadoop.security.token.delegation.AbstractDelegationTokenSecretManager: Starting expired delegation token remover thread, tokenRemoverScanInterval=60 min(s)
2022-11-24 04:30:50,315 INFO org.apache.hadoop.security.token.delegation.AbstractDelegationTokenSecretManager: Updating the current master key for generating delegation tokens
2022-11-24 04:30:50,323 INFO org.mortbay.log: Started HttpServer2$SelectChannelConnectorWithSafeStartup@172.31.11.48:8088
2022-11-24 04:30:50,323 INFO org.apache.hadoop.yarn.webapp.WebApps: Web app /cluster started at 8088
2022-11-24 04:30:50,672 INFO org.apache.hadoop.yarn.webapp.WebApps: Registered webapp guice modules
2022-11-24 04:30:50,694 INFO org.apache.hadoop.ipc.CallQueueManager: Using callQueue: class java.util.concurrent.LinkedBlockingQueue queueCapacity: 100
2022-11-24 04:30:50,694 INFO org.apache.hadoop.ipc.Server: Starting Socket Reader #1 for port 8033
2022-11-24 04:30:50,696 INFO org.apache.hadoop.yarn.factories.impl.pb.RpcServerFactoryPBImpl: Adding protocol org.apache.hadoop.yarn.server.api.ResourceManagerAdministrationProtocolPB to the server
2022-11-24 04:30:50,697 INFO org.apache.hadoop.ipc.Server: IPC Server Responder: starting
2022-11-24 04:30:50,698 INFO org.apache.hadoop.ipc.Server: IPC Server listener on 8033: starting
2022-11-24 04:30:51,833 INFO org.apache.hadoop.yarn.util.RackResolver: Resolved ip-172-31-3-214.ec2.internal to /default-rack
2022-11-24 04:30:51,833 INFO org.apache.hadoop.yarn.util.RackResolver: Resolved ip-172-31-0-65.ec2.internal to /default-rack
2022-11-24 04:30:51,835 INFO org.apache.hadoop.yarn.server.resourcemanager.ResourceTrackerService: NodeManager from node ip-172-31-0-65.ec2.internal(cmPort: 43515 httpPort: 8042) registered with capability: <memory:8192, vCores:8>, assigned nodeId ip-172-31-0-65.ec2.internal:43515
2022-11-24 04:30:51,836 INFO org.apache.hadoop.yarn.server.resourcemanager.rmnode.RMNodeImpl: ip-172-31-0-65.ec2.internal:43515 Node Transitioned from NEW to RUNNING
2022-11-24 04:30:51,836 INFO org.apache.hadoop.yarn.server.resourcemanager.rmnode.RMNodeImpl: ip-172-31-3-214.ec2.internal:43613 Node Transitioned from NEW to RUNNING
2022-11-24 04:30:51,837 INFO org.apache.hadoop.yarn.server.resourcemanager.ResourceTrackerService: NodeManager from node ip-172-31-3-214.ec2.internal(cmPort: 43613 httpPort: 8042) registered with capability: <memory:8192, vCores:8>, assigned nodeId ip-172-31-3-214.ec2.internal:43613
2022-11-24 04:30:51,838 INFO org.apache.hadoop.yarn.server.resourcemanager.scheduler.capacity.CapacityScheduler: Added node ip-172-31-0-65.ec2.internal:43515 clusterResource: <memory:8192, vCores:8>
2022-11-24 04:30:51,840 INFO org.apache.hadoop.yarn.server.resourcemanager.scheduler.capacity.CapacityScheduler: Added node ip-172-31-3-214.ec2.internal:43613 clusterResource: <memory:16384, vCores:16>
2022-11-24 04:38:30,331 ERROR org.apache.hadoop.yarn.server.resourcemanager.ResourceManager: RECEIVED SIGNAL 15: SIGTERM
2022-11-24 04:38:30,339 ERROR org.apache.hadoop.security.token.delegation.AbstractDelegationTokenSecretManager: ExpiredTokenRemover received java.lang.InterruptedException: sleep interrupted
2022-11-24 04:38:30,340 INFO org.mortbay.log: Stopped HttpServer2$SelectChannelConnectorWithSafeStartup@172.31.11.48:8088
2022-11-24 04:38:30,340 ERROR org.apache.hadoop.security.token.delegation.AbstractDelegationTokenSecretManager: ExpiredTokenRemover received java.lang.InterruptedException: sleep interrupted
2022-11-24 04:38:30,341 ERROR org.apache.hadoop.security.token.delegation.AbstractDelegationTokenSecretManager: ExpiredTokenRemover received java.lang.InterruptedException: sleep interrupted
2022-11-24 04:38:30,441 INFO org.apache.hadoop.ipc.Server: Stopping server on 8032
2022-11-24 04:38:30,443 INFO org.apache.hadoop.ipc.Server: Stopping IPC Server listener on 8032
2022-11-24 04:38:30,444 INFO org.apache.hadoop.ipc.Server: Stopping IPC Server Responder
2022-11-24 04:38:30,444 INFO org.apache.hadoop.ipc.Server: Stopping server on 8033
2022-11-24 04:38:30,444 INFO org.apache.hadoop.ipc.Server: Stopping IPC Server listener on 8033
2022-11-24 04:38:30,445 INFO org.apache.hadoop.ipc.Server: Stopping IPC Server Responder
2022-11-24 04:38:30,445 INFO org.apache.hadoop.yarn.server.resourcemanager.ResourceManager: Transitioning to standby state
2022-11-24 04:38:30,445 WARN org.apache.hadoop.yarn.server.resourcemanager.amlauncher.ApplicationMasterLauncher: org.apache.hadoop.yarn.server.resourcemanager.amlauncher.ApplicationMasterLauncher$LauncherThread interrupted. Returning.
2022-11-24 04:38:30,446 INFO org.apache.hadoop.ipc.Server: Stopping server on 8030
2022-11-24 04:38:30,448 INFO org.apache.hadoop.ipc.Server: Stopping IPC Server listener on 8030
2022-11-24 04:38:30,448 INFO org.apache.hadoop.ipc.Server: Stopping server on 8031
2022-11-24 04:38:30,448 INFO org.apache.hadoop.ipc.Server: Stopping IPC Server Responder
2022-11-24 04:38:30,452 INFO org.apache.hadoop.ipc.Server: Stopping IPC Server listener on 8031
2022-11-24 04:38:30,453 ERROR org.apache.hadoop.yarn.server.resourcemanager.ResourceManager: Returning, interrupted : java.lang.InterruptedException
2022-11-24 04:38:30,454 INFO org.apache.hadoop.ipc.Server: Stopping IPC Server Responder
2022-11-24 04:38:30,454 INFO org.apache.hadoop.yarn.util.AbstractLivelinessMonitor: NMLivelinessMonitor thread interrupted
2022-11-24 04:38:30,454 INFO org.apache.hadoop.yarn.util.AbstractLivelinessMonitor: org.apache.hadoop.yarn.server.resourcemanager.rmcontainer.ContainerAllocationExpirer thread interrupted
2022-11-24 04:38:30,454 INFO org.apache.hadoop.yarn.util.AbstractLivelinessMonitor: AMLivelinessMonitor thread interrupted
2022-11-24 04:38:30,454 ERROR org.apache.hadoop.security.token.delegation.AbstractDelegationTokenSecretManager: ExpiredTokenRemover received java.lang.InterruptedException: sleep interrupted
2022-11-24 04:38:30,454 INFO org.apache.hadoop.yarn.util.AbstractLivelinessMonitor: AMLivelinessMonitor thread interrupted
2022-11-24 04:38:30,456 INFO org.apache.hadoop.metrics2.impl.MetricsSystemImpl: Stopping ResourceManager metrics system...
2022-11-24 04:38:30,457 INFO org.apache.hadoop.metrics2.impl.MetricsSystemImpl: ResourceManager metrics system stopped.
2022-11-24 04:38:30,458 INFO org.apache.hadoop.metrics2.impl.MetricsSystemImpl: ResourceManager metrics system shutdown complete.
2022-11-24 04:38:30,458 INFO org.apache.hadoop.yarn.event.AsyncDispatcher: AsyncDispatcher is draining to stop, igonring any new events.
2022-11-24 04:38:30,459 INFO org.apache.hadoop.yarn.server.resourcemanager.ResourceManager: Transitioned to standby state
2022-11-24 04:38:30,459 INFO org.apache.hadoop.yarn.server.resourcemanager.ResourceManager: SHUTDOWN_MSG: 
/************************************************************
SHUTDOWN_MSG: Shutting down ResourceManager at ip-172-31-11-48/172.31.11.48
************************************************************/
2022-11-24 04:39:59,344 INFO org.apache.hadoop.yarn.server.resourcemanager.ResourceManager: STARTUP_MSG: 
/************************************************************
STARTUP_MSG: Starting ResourceManager
STARTUP_MSG:   host = ip-172-31-11-48/172.31.11.48
STARTUP_MSG:   args = []
STARTUP_MSG:   version = 2.6.5
STARTUP_MSG:   build = https://github.com/apache/hadoop.git -r e8c9fe0b4c252caf2ebf1464220599650f119997; compiled by 'sjlee' on 2016-10-02T23:43Z
STARTUP_MSG:   java = 1.8.0_352
************************************************************/
2022-11-24 04:39:59,352 INFO org.apache.hadoop.yarn.server.resourcemanager.ResourceManager: registered UNIX signal handlers for [TERM, HUP, INT]
2022-11-24 04:39:59,595 INFO org.apache.hadoop.conf.Configuration: found resource core-site.xml at file:/usr/local/hadoop/etc/hadoop/core-site.xml
2022-11-24 04:39:59,656 INFO org.apache.hadoop.security.Groups: clearing userToGroupsMap cache
2022-11-24 04:39:59,708 INFO org.apache.hadoop.conf.Configuration: found resource yarn-site.xml at file:/usr/local/hadoop/etc/hadoop/yarn-site.xml
2022-11-24 04:39:59,850 INFO org.apache.hadoop.yarn.event.AsyncDispatcher: Registering class org.apache.hadoop.yarn.server.resourcemanager.RMFatalEventType for class org.apache.hadoop.yarn.server.resourcemanager.ResourceManager$RMFatalEventDispatcher
2022-11-24 04:39:59,907 INFO org.apache.hadoop.yarn.server.resourcemanager.security.NMTokenSecretManagerInRM: NMTokenKeyRollingInterval: 86400000ms and NMTokenKeyActivationDelay: 900000ms
2022-11-24 04:39:59,910 INFO org.apache.hadoop.yarn.server.resourcemanager.security.RMContainerTokenSecretManager: ContainerTokenKeyRollingInterval: 86400000ms and ContainerTokenKeyActivationDelay: 900000ms
2022-11-24 04:39:59,918 INFO org.apache.hadoop.yarn.server.resourcemanager.security.AMRMTokenSecretManager: AMRMTokenKeyRollingInterval: 86400000ms and AMRMTokenKeyActivationDelay: 900000 ms
2022-11-24 04:39:59,954 INFO org.apache.hadoop.yarn.event.AsyncDispatcher: Registering class org.apache.hadoop.yarn.server.resourcemanager.recovery.RMStateStoreEventType for class org.apache.hadoop.yarn.server.resourcemanager.recovery.RMStateStore$ForwardingEventHandler
2022-11-24 04:39:59,956 INFO org.apache.hadoop.yarn.event.AsyncDispatcher: Registering class org.apache.hadoop.yarn.server.resourcemanager.NodesListManagerEventType for class org.apache.hadoop.yarn.server.resourcemanager.NodesListManager
2022-11-24 04:39:59,956 INFO org.apache.hadoop.yarn.server.resourcemanager.ResourceManager: Using Scheduler: org.apache.hadoop.yarn.server.resourcemanager.scheduler.capacity.CapacityScheduler
2022-11-24 04:39:59,972 INFO org.apache.hadoop.yarn.event.AsyncDispatcher: Registering class org.apache.hadoop.yarn.server.resourcemanager.scheduler.event.SchedulerEventType for class org.apache.hadoop.yarn.server.resourcemanager.ResourceManager$SchedulerEventDispatcher
2022-11-24 04:39:59,973 INFO org.apache.hadoop.yarn.event.AsyncDispatcher: Registering class org.apache.hadoop.yarn.server.resourcemanager.rmapp.RMAppEventType for class org.apache.hadoop.yarn.server.resourcemanager.ResourceManager$ApplicationEventDispatcher
2022-11-24 04:39:59,973 INFO org.apache.hadoop.yarn.event.AsyncDispatcher: Registering class org.apache.hadoop.yarn.server.resourcemanager.rmapp.attempt.RMAppAttemptEventType for class org.apache.hadoop.yarn.server.resourcemanager.ResourceManager$ApplicationAttemptEventDispatcher
2022-11-24 04:39:59,976 INFO org.apache.hadoop.yarn.event.AsyncDispatcher: Registering class org.apache.hadoop.yarn.server.resourcemanager.rmnode.RMNodeEventType for class org.apache.hadoop.yarn.server.resourcemanager.ResourceManager$NodeEventDispatcher
2022-11-24 04:40:00,053 INFO org.apache.hadoop.metrics2.impl.MetricsConfig: loaded properties from hadoop-metrics2.properties
2022-11-24 04:40:00,167 INFO org.apache.hadoop.metrics2.impl.MetricsSystemImpl: Scheduled snapshot period at 10 second(s).
2022-11-24 04:40:00,168 INFO org.apache.hadoop.metrics2.impl.MetricsSystemImpl: ResourceManager metrics system started
2022-11-24 04:40:00,217 INFO org.apache.hadoop.yarn.event.AsyncDispatcher: Registering class org.apache.hadoop.yarn.server.resourcemanager.RMAppManagerEventType for class org.apache.hadoop.yarn.server.resourcemanager.RMAppManager
2022-11-24 04:40:00,257 INFO org.apache.hadoop.yarn.event.AsyncDispatcher: Registering class org.apache.hadoop.yarn.server.resourcemanager.amlauncher.AMLauncherEventType for class org.apache.hadoop.yarn.server.resourcemanager.amlauncher.ApplicationMasterLauncher
2022-11-24 04:40:00,261 INFO org.apache.hadoop.yarn.server.resourcemanager.RMNMInfo: Registered RMNMInfo MBean
2022-11-24 04:40:00,263 INFO org.apache.hadoop.util.HostsFileReader: Refreshing hosts (include/exclude) list
2022-11-24 04:40:00,269 INFO org.apache.hadoop.conf.Configuration: found resource capacity-scheduler.xml at file:/usr/local/hadoop/etc/hadoop/capacity-scheduler.xml
2022-11-24 04:40:00,319 INFO org.apache.hadoop.yarn.server.resourcemanager.scheduler.capacity.ParentQueue: root, capacity=1.0, asboluteCapacity=1.0, maxCapacity=1.0, asboluteMaxCapacity=1.0, state=RUNNING, acls=SUBMIT_APPLICATIONS:*ADMINISTER_QUEUE:*, labels=*,
, reservationsContinueLooking=true
2022-11-24 04:40:00,319 INFO org.apache.hadoop.yarn.server.resourcemanager.scheduler.capacity.ParentQueue: Initialized parent-queue root name=root, fullname=root
2022-11-24 04:40:00,329 INFO org.apache.hadoop.yarn.server.resourcemanager.scheduler.capacity.LeafQueue: Initializing default
capacity = 1.0 [= (float) configuredCapacity / 100 ]
asboluteCapacity = 1.0 [= parentAbsoluteCapacity * capacity ]
maxCapacity = 1.0 [= configuredMaxCapacity ]
absoluteMaxCapacity = 1.0 [= 1.0 maximumCapacity undefined, (parentAbsoluteMaxCapacity * maximumCapacity) / 100 otherwise ]
userLimit = 100 [= configuredUserLimit ]
userLimitFactor = 1.0 [= configuredUserLimitFactor ]
maxApplications = 10000 [= configuredMaximumSystemApplicationsPerQueue or (int)(configuredMaximumSystemApplications * absoluteCapacity)]
maxApplicationsPerUser = 10000 [= (int)(maxApplications * (userLimit / 100.0f) * userLimitFactor) ]
usedCapacity = 0.0 [= usedResourcesMemory / (clusterResourceMemory * absoluteCapacity)]
absoluteUsedCapacity = 0.0 [= usedResourcesMemory / clusterResourceMemory]
maxAMResourcePerQueuePercent = 0.1 [= configuredMaximumAMResourcePercent ]
minimumAllocationFactor = 0.875 [= (float)(maximumAllocationMemory - minimumAllocationMemory) / maximumAllocationMemory ]
numContainers = 0 [= currentNumContainers ]
state = RUNNING [= configuredState ]
acls = SUBMIT_APPLICATIONS:*ADMINISTER_QUEUE:* [= configuredAcls ]
nodeLocalityDelay = 40
labels=*,
nodeLocalityDelay = 40
reservationsContinueLooking = true

2022-11-24 04:40:00,329 INFO org.apache.hadoop.yarn.server.resourcemanager.scheduler.capacity.CapacityScheduler: Initialized queue: default: capacity=1.0, absoluteCapacity=1.0, usedResources=<memory:0, vCores:0>, usedCapacity=0.0, absoluteUsedCapacity=0.0, numApps=0, numContainers=0
2022-11-24 04:40:00,330 INFO org.apache.hadoop.yarn.server.resourcemanager.scheduler.capacity.CapacityScheduler: Initialized queue: root: numChildQueue= 1, capacity=1.0, absoluteCapacity=1.0, usedResources=<memory:0, vCores:0>usedCapacity=0.0, numApps=0, numContainers=0
2022-11-24 04:40:00,331 INFO org.apache.hadoop.yarn.server.resourcemanager.scheduler.capacity.CapacityScheduler: Initialized root queue root: numChildQueue= 1, capacity=1.0, absoluteCapacity=1.0, usedResources=<memory:0, vCores:0>usedCapacity=0.0, numApps=0, numContainers=0
2022-11-24 04:40:00,331 INFO org.apache.hadoop.yarn.server.resourcemanager.scheduler.capacity.CapacityScheduler: Initialized queue mappings, override: false
2022-11-24 04:40:00,331 INFO org.apache.hadoop.yarn.server.resourcemanager.scheduler.capacity.CapacityScheduler: Initialized CapacityScheduler with calculator=class org.apache.hadoop.yarn.util.resource.DefaultResourceCalculator, minimumAllocation=<<memory:1024, vCores:1>>, maximumAllocation=<<memory:8192, vCores:32>>, asynchronousScheduling=false, asyncScheduleInterval=5ms
2022-11-24 04:40:00,339 INFO org.apache.hadoop.yarn.server.resourcemanager.metrics.SystemMetricsPublisher: YARN system metrics publishing service is not enabled
2022-11-24 04:40:00,339 INFO org.apache.hadoop.yarn.server.resourcemanager.ResourceManager: Transitioning to active state
2022-11-24 04:40:00,351 INFO org.apache.hadoop.yarn.server.resourcemanager.security.RMContainerTokenSecretManager: Rolling master-key for container-tokens
2022-11-24 04:40:00,351 INFO org.apache.hadoop.yarn.server.resourcemanager.security.NMTokenSecretManagerInRM: Rolling master-key for nm-tokens
2022-11-24 04:40:00,352 INFO org.apache.hadoop.security.token.delegation.AbstractDelegationTokenSecretManager: Updating the current master key for generating delegation tokens
2022-11-24 04:40:00,352 INFO org.apache.hadoop.yarn.server.resourcemanager.security.RMDelegationTokenSecretManager: storing master key with keyID 1
2022-11-24 04:40:00,354 INFO org.apache.hadoop.security.token.delegation.AbstractDelegationTokenSecretManager: Starting expired delegation token remover thread, tokenRemoverScanInterval=60 min(s)
2022-11-24 04:40:00,354 INFO org.apache.hadoop.security.token.delegation.AbstractDelegationTokenSecretManager: Updating the current master key for generating delegation tokens
2022-11-24 04:40:00,354 INFO org.apache.hadoop.yarn.server.resourcemanager.security.RMDelegationTokenSecretManager: storing master key with keyID 2
2022-11-24 04:40:00,380 INFO org.apache.hadoop.ipc.CallQueueManager: Using callQueue: class java.util.concurrent.LinkedBlockingQueue queueCapacity: 5000
2022-11-24 04:40:00,392 INFO org.apache.hadoop.ipc.Server: Starting Socket Reader #1 for port 8031
2022-11-24 04:40:00,410 INFO org.apache.hadoop.yarn.factories.impl.pb.RpcServerFactoryPBImpl: Adding protocol org.apache.hadoop.yarn.server.api.ResourceTrackerPB to the server
2022-11-24 04:40:00,410 INFO org.apache.hadoop.ipc.Server: IPC Server Responder: starting
2022-11-24 04:40:00,412 INFO org.apache.hadoop.ipc.Server: IPC Server listener on 8031: starting
2022-11-24 04:40:00,438 INFO org.apache.hadoop.ipc.CallQueueManager: Using callQueue: class java.util.concurrent.LinkedBlockingQueue queueCapacity: 5000
2022-11-24 04:40:00,446 INFO org.apache.hadoop.ipc.Server: Starting Socket Reader #1 for port 8030
2022-11-24 04:40:00,458 INFO org.apache.hadoop.yarn.factories.impl.pb.RpcServerFactoryPBImpl: Adding protocol org.apache.hadoop.yarn.api.ApplicationMasterProtocolPB to the server
2022-11-24 04:40:00,459 INFO org.apache.hadoop.ipc.Server: IPC Server Responder: starting
2022-11-24 04:40:00,459 INFO org.apache.hadoop.ipc.Server: IPC Server listener on 8030: starting
2022-11-24 04:40:00,523 INFO org.apache.hadoop.ipc.CallQueueManager: Using callQueue: class java.util.concurrent.LinkedBlockingQueue queueCapacity: 5000
2022-11-24 04:40:00,524 INFO org.apache.hadoop.ipc.Server: Starting Socket Reader #1 for port 8032
2022-11-24 04:40:00,526 INFO org.apache.hadoop.yarn.factories.impl.pb.RpcServerFactoryPBImpl: Adding protocol org.apache.hadoop.yarn.api.ApplicationClientProtocolPB to the server
2022-11-24 04:40:00,526 INFO org.apache.hadoop.ipc.Server: IPC Server Responder: starting
2022-11-24 04:40:00,526 INFO org.apache.hadoop.ipc.Server: IPC Server listener on 8032: starting
2022-11-24 04:40:00,543 INFO org.apache.hadoop.yarn.server.resourcemanager.ResourceManager: Transitioned to active state
2022-11-24 04:40:00,594 INFO org.mortbay.log: Logging to org.slf4j.impl.Log4jLoggerAdapter(org.mortbay.log) via org.mortbay.log.Slf4jLog
2022-11-24 04:40:00,597 INFO org.apache.hadoop.http.HttpRequestLog: Http request log for http.requests.resourcemanager is not defined
2022-11-24 04:40:00,605 INFO org.apache.hadoop.http.HttpServer2: Added global filter 'safety' (class=org.apache.hadoop.http.HttpServer2$QuotingInputFilter)
2022-11-24 04:40:00,611 INFO org.apache.hadoop.http.HttpServer2: Added filter RMAuthenticationFilter (class=org.apache.hadoop.yarn.server.security.http.RMAuthenticationFilter) to context cluster
2022-11-24 04:40:00,611 INFO org.apache.hadoop.http.HttpServer2: Added filter RMAuthenticationFilter (class=org.apache.hadoop.yarn.server.security.http.RMAuthenticationFilter) to context logs
2022-11-24 04:40:00,611 INFO org.apache.hadoop.http.HttpServer2: Added filter RMAuthenticationFilter (class=org.apache.hadoop.yarn.server.security.http.RMAuthenticationFilter) to context static
2022-11-24 04:40:00,612 INFO org.apache.hadoop.http.HttpServer2: Added filter static_user_filter (class=org.apache.hadoop.http.lib.StaticUserWebFilter$StaticUserFilter) to context cluster
2022-11-24 04:40:00,612 INFO org.apache.hadoop.http.HttpServer2: Added filter static_user_filter (class=org.apache.hadoop.http.lib.StaticUserWebFilter$StaticUserFilter) to context logs
2022-11-24 04:40:00,612 INFO org.apache.hadoop.http.HttpServer2: Added filter static_user_filter (class=org.apache.hadoop.http.lib.StaticUserWebFilter$StaticUserFilter) to context static
2022-11-24 04:40:00,615 INFO org.apache.hadoop.http.HttpServer2: adding path spec: /cluster/*
2022-11-24 04:40:00,615 INFO org.apache.hadoop.http.HttpServer2: adding path spec: /ws/*
2022-11-24 04:40:00,624 INFO org.apache.hadoop.http.HttpServer2: Jetty bound to port 8088
2022-11-24 04:40:00,624 INFO org.mortbay.log: jetty-6.1.26
2022-11-24 04:40:00,650 INFO org.mortbay.log: Extract jar:file:/usr/local/hadoop/share/hadoop/yarn/hadoop-yarn-common-2.6.5.jar!/webapps/cluster to /tmp/Jetty_172_31_11_48_8088_cluster____.cj96d9/webapp
2022-11-24 04:40:00,776 INFO org.apache.hadoop.security.token.delegation.AbstractDelegationTokenSecretManager: Updating the current master key for generating delegation tokens
2022-11-24 04:40:00,777 INFO org.apache.hadoop.security.token.delegation.AbstractDelegationTokenSecretManager: Starting expired delegation token remover thread, tokenRemoverScanInterval=60 min(s)
2022-11-24 04:40:00,777 INFO org.apache.hadoop.security.token.delegation.AbstractDelegationTokenSecretManager: Updating the current master key for generating delegation tokens
2022-11-24 04:40:00,803 INFO org.apache.hadoop.security.token.delegation.AbstractDelegationTokenSecretManager: Updating the current master key for generating delegation tokens
2022-11-24 04:40:00,806 INFO org.apache.hadoop.security.token.delegation.AbstractDelegationTokenSecretManager: Starting expired delegation token remover thread, tokenRemoverScanInterval=60 min(s)
2022-11-24 04:40:00,806 INFO org.apache.hadoop.security.token.delegation.AbstractDelegationTokenSecretManager: Updating the current master key for generating delegation tokens
2022-11-24 04:40:00,810 INFO org.apache.hadoop.security.token.delegation.AbstractDelegationTokenSecretManager: Updating the current master key for generating delegation tokens
2022-11-24 04:40:00,811 INFO org.apache.hadoop.security.token.delegation.AbstractDelegationTokenSecretManager: Starting expired delegation token remover thread, tokenRemoverScanInterval=60 min(s)
2022-11-24 04:40:00,811 INFO org.apache.hadoop.security.token.delegation.AbstractDelegationTokenSecretManager: Updating the current master key for generating delegation tokens
2022-11-24 04:40:00,820 INFO org.mortbay.log: Started HttpServer2$SelectChannelConnectorWithSafeStartup@172.31.11.48:8088
2022-11-24 04:40:00,820 INFO org.apache.hadoop.yarn.webapp.WebApps: Web app /cluster started at 8088
2022-11-24 04:40:01,174 INFO org.apache.hadoop.yarn.webapp.WebApps: Registered webapp guice modules
2022-11-24 04:40:01,196 INFO org.apache.hadoop.ipc.CallQueueManager: Using callQueue: class java.util.concurrent.LinkedBlockingQueue queueCapacity: 100
2022-11-24 04:40:01,197 INFO org.apache.hadoop.ipc.Server: Starting Socket Reader #1 for port 8033
2022-11-24 04:40:01,198 INFO org.apache.hadoop.yarn.factories.impl.pb.RpcServerFactoryPBImpl: Adding protocol org.apache.hadoop.yarn.server.api.ResourceManagerAdministrationProtocolPB to the server
2022-11-24 04:40:01,200 INFO org.apache.hadoop.ipc.Server: IPC Server Responder: starting
2022-11-24 04:40:01,200 INFO org.apache.hadoop.ipc.Server: IPC Server listener on 8033: starting
2022-11-24 04:40:02,662 INFO org.apache.hadoop.yarn.util.RackResolver: Resolved ip-172-31-0-65.ec2.internal to /default-rack
2022-11-24 04:40:02,662 INFO org.apache.hadoop.yarn.util.RackResolver: Resolved ip-172-31-3-214.ec2.internal to /default-rack
2022-11-24 04:40:02,664 INFO org.apache.hadoop.yarn.server.resourcemanager.ResourceTrackerService: NodeManager from node ip-172-31-0-65.ec2.internal(cmPort: 46455 httpPort: 8042) registered with capability: <memory:8192, vCores:8>, assigned nodeId ip-172-31-0-65.ec2.internal:46455
2022-11-24 04:40:02,665 INFO org.apache.hadoop.yarn.server.resourcemanager.rmnode.RMNodeImpl: ip-172-31-3-214.ec2.internal:33939 Node Transitioned from NEW to RUNNING
2022-11-24 04:40:02,666 INFO org.apache.hadoop.yarn.server.resourcemanager.rmnode.RMNodeImpl: ip-172-31-0-65.ec2.internal:46455 Node Transitioned from NEW to RUNNING
2022-11-24 04:40:02,666 INFO org.apache.hadoop.yarn.server.resourcemanager.ResourceTrackerService: NodeManager from node ip-172-31-3-214.ec2.internal(cmPort: 33939 httpPort: 8042) registered with capability: <memory:8192, vCores:8>, assigned nodeId ip-172-31-3-214.ec2.internal:33939
2022-11-24 04:40:02,667 INFO org.apache.hadoop.yarn.server.resourcemanager.scheduler.capacity.CapacityScheduler: Added node ip-172-31-3-214.ec2.internal:33939 clusterResource: <memory:8192, vCores:8>
2022-11-24 04:40:02,669 INFO org.apache.hadoop.yarn.server.resourcemanager.scheduler.capacity.CapacityScheduler: Added node ip-172-31-0-65.ec2.internal:46455 clusterResource: <memory:16384, vCores:16>
2022-11-24 04:50:00,332 INFO org.apache.hadoop.yarn.server.resourcemanager.scheduler.AbstractYarnScheduler: Release request cache is cleaned up
2022-11-24 04:51:55,315 INFO org.apache.hadoop.yarn.util.RackResolver: Resolved ip-172-31-11-48 to /default-rack
2022-11-24 04:51:55,315 INFO org.apache.hadoop.yarn.server.resourcemanager.ResourceTrackerService: NodeManager from node ip-172-31-11-48(cmPort: 41289 httpPort: 8042) registered with capability: <memory:8192, vCores:8>, assigned nodeId ip-172-31-11-48:41289
2022-11-24 04:51:55,315 INFO org.apache.hadoop.yarn.server.resourcemanager.rmnode.RMNodeImpl: ip-172-31-11-48:41289 Node Transitioned from NEW to RUNNING
2022-11-24 04:51:55,315 INFO org.apache.hadoop.yarn.server.resourcemanager.scheduler.capacity.CapacityScheduler: Added node ip-172-31-11-48:41289 clusterResource: <memory:24576, vCores:24>
2022-11-24 05:00:36,265 INFO org.apache.hadoop.yarn.server.resourcemanager.ClientRMService: Allocated new applicationId: 1
2022-11-24 05:00:37,035 INFO org.apache.hadoop.yarn.server.resourcemanager.ClientRMService: Application with id 1 submitted by user ubuntu
2022-11-24 05:00:37,035 INFO org.apache.hadoop.yarn.server.resourcemanager.rmapp.RMAppImpl: Storing application with id application_1669264800340_0001
2022-11-24 05:00:37,036 INFO org.apache.hadoop.yarn.server.resourcemanager.RMAuditLogger: USER=ubuntu	IP=172.31.11.48	OPERATION=Submit Application Request	TARGET=ClientRMService	RESULT=SUCCESS	APPID=application_1669264800340_0001
2022-11-24 05:00:37,037 INFO org.apache.hadoop.yarn.server.resourcemanager.rmapp.RMAppImpl: application_1669264800340_0001 State change from NEW to NEW_SAVING
2022-11-24 05:00:37,043 INFO org.apache.hadoop.yarn.server.resourcemanager.recovery.RMStateStore: Storing info for app: application_1669264800340_0001
2022-11-24 05:00:37,043 INFO org.apache.hadoop.yarn.server.resourcemanager.rmapp.RMAppImpl: application_1669264800340_0001 State change from NEW_SAVING to SUBMITTED
2022-11-24 05:00:37,046 INFO org.apache.hadoop.yarn.server.resourcemanager.scheduler.capacity.ParentQueue: Application added - appId: application_1669264800340_0001 user: ubuntu leaf-queue of parent: root #applications: 1
2022-11-24 05:00:37,046 INFO org.apache.hadoop.yarn.server.resourcemanager.scheduler.capacity.CapacityScheduler: Accepted application application_1669264800340_0001 from user: ubuntu, in queue: default
2022-11-24 05:00:37,055 INFO org.apache.hadoop.yarn.server.resourcemanager.rmapp.RMAppImpl: application_1669264800340_0001 State change from SUBMITTED to ACCEPTED
2022-11-24 05:00:37,082 INFO org.apache.hadoop.yarn.server.resourcemanager.ApplicationMasterService: Registering app attempt : appattempt_1669264800340_0001_000001
2022-11-24 05:00:37,085 INFO org.apache.hadoop.yarn.server.resourcemanager.rmapp.attempt.RMAppAttemptImpl: appattempt_1669264800340_0001_000001 State change from NEW to SUBMITTED
2022-11-24 05:00:37,114 INFO org.apache.hadoop.yarn.server.resourcemanager.scheduler.capacity.LeafQueue: Application application_1669264800340_0001 from user: ubuntu activated in queue: default
2022-11-24 05:00:37,114 INFO org.apache.hadoop.yarn.server.resourcemanager.scheduler.capacity.LeafQueue: Application added - appId: application_1669264800340_0001 user: org.apache.hadoop.yarn.server.resourcemanager.scheduler.capacity.LeafQueue$User@70c23f62, leaf-queue: default #user-pending-applications: 0 #user-active-applications: 1 #queue-pending-applications: 0 #queue-active-applications: 1
2022-11-24 05:00:37,114 INFO org.apache.hadoop.yarn.server.resourcemanager.scheduler.capacity.CapacityScheduler: Added Application Attempt appattempt_1669264800340_0001_000001 to scheduler from user ubuntu in queue default
2022-11-24 05:00:37,119 INFO org.apache.hadoop.yarn.server.resourcemanager.rmapp.attempt.RMAppAttemptImpl: appattempt_1669264800340_0001_000001 State change from SUBMITTED to SCHEDULED
2022-11-24 05:00:37,140 INFO org.apache.hadoop.yarn.server.resourcemanager.rmcontainer.RMContainerImpl: container_1669264800340_0001_01_000001 Container Transitioned from NEW to ALLOCATED
2022-11-24 05:00:37,140 INFO org.apache.hadoop.yarn.server.resourcemanager.RMAuditLogger: USER=ubuntu	OPERATION=AM Allocated Container	TARGET=SchedulerApp	RESULT=SUCCESS	APPID=application_1669264800340_0001	CONTAINERID=container_1669264800340_0001_01_000001
2022-11-24 05:00:37,140 INFO org.apache.hadoop.yarn.server.resourcemanager.scheduler.SchedulerNode: Assigned container container_1669264800340_0001_01_000001 of capacity <memory:2048, vCores:1> on host ip-172-31-11-48:41289, which has 1 containers, <memory:2048, vCores:1> used and <memory:6144, vCores:7> available after allocation
2022-11-24 05:00:37,141 INFO org.apache.hadoop.yarn.server.resourcemanager.scheduler.capacity.LeafQueue: assignedContainer application attempt=appattempt_1669264800340_0001_000001 container=Container: [ContainerId: container_1669264800340_0001_01_000001, NodeId: ip-172-31-11-48:41289, NodeHttpAddress: ip-172-31-11-48:8042, Resource: <memory:2048, vCores:1>, Priority: 0, Token: null, ] queue=default: capacity=1.0, absoluteCapacity=1.0, usedResources=<memory:0, vCores:0>, usedCapacity=0.0, absoluteUsedCapacity=0.0, numApps=1, numContainers=0 clusterResource=<memory:24576, vCores:24>
2022-11-24 05:00:37,150 INFO org.apache.hadoop.yarn.server.resourcemanager.scheduler.capacity.ParentQueue: Re-sorting assigned queue: root.default stats: default: capacity=1.0, absoluteCapacity=1.0, usedResources=<memory:2048, vCores:1>, usedCapacity=0.083333336, absoluteUsedCapacity=0.083333336, numApps=1, numContainers=1
2022-11-24 05:00:37,150 INFO org.apache.hadoop.yarn.server.resourcemanager.scheduler.capacity.ParentQueue: assignedContainer queue=root usedCapacity=0.083333336 absoluteUsedCapacity=0.083333336 used=<memory:2048, vCores:1> cluster=<memory:24576, vCores:24>
2022-11-24 05:00:37,158 INFO org.apache.hadoop.yarn.server.resourcemanager.security.NMTokenSecretManagerInRM: Sending NMToken for nodeId : ip-172-31-11-48:41289 for container : container_1669264800340_0001_01_000001
2022-11-24 05:00:37,168 INFO org.apache.hadoop.yarn.server.resourcemanager.rmcontainer.RMContainerImpl: container_1669264800340_0001_01_000001 Container Transitioned from ALLOCATED to ACQUIRED
2022-11-24 05:00:37,178 INFO org.apache.hadoop.yarn.server.resourcemanager.security.NMTokenSecretManagerInRM: Clear node set for appattempt_1669264800340_0001_000001
2022-11-24 05:00:37,181 INFO org.apache.hadoop.yarn.server.resourcemanager.rmapp.attempt.RMAppAttemptImpl: Storing attempt: AppId: application_1669264800340_0001 AttemptId: appattempt_1669264800340_0001_000001 MasterContainer: Container: [ContainerId: container_1669264800340_0001_01_000001, NodeId: ip-172-31-11-48:41289, NodeHttpAddress: ip-172-31-11-48:8042, Resource: <memory:2048, vCores:1>, Priority: 0, Token: Token { kind: ContainerToken, service: 172.31.11.48:41289 }, ]
2022-11-24 05:00:37,192 INFO org.apache.hadoop.yarn.server.resourcemanager.rmapp.attempt.RMAppAttemptImpl: appattempt_1669264800340_0001_000001 State change from SCHEDULED to ALLOCATED_SAVING
2022-11-24 05:00:37,205 INFO org.apache.hadoop.yarn.server.resourcemanager.rmapp.attempt.RMAppAttemptImpl: appattempt_1669264800340_0001_000001 State change from ALLOCATED_SAVING to ALLOCATED
2022-11-24 05:00:37,215 INFO org.apache.hadoop.yarn.server.resourcemanager.amlauncher.AMLauncher: Launching masterappattempt_1669264800340_0001_000001
2022-11-24 05:00:37,253 INFO org.apache.hadoop.yarn.server.resourcemanager.amlauncher.AMLauncher: Setting up container Container: [ContainerId: container_1669264800340_0001_01_000001, NodeId: ip-172-31-11-48:41289, NodeHttpAddress: ip-172-31-11-48:8042, Resource: <memory:2048, vCores:1>, Priority: 0, Token: Token { kind: ContainerToken, service: 172.31.11.48:41289 }, ] for AM appattempt_1669264800340_0001_000001
2022-11-24 05:00:37,253 INFO org.apache.hadoop.yarn.server.resourcemanager.amlauncher.AMLauncher: Command to launch container container_1669264800340_0001_01_000001 : $JAVA_HOME/bin/java -Dlog4j.configuration=container-log4j.properties -Dyarn.app.container.log.dir=<LOG_DIR> -Dyarn.app.container.log.filesize=0 -Dhadoop.root.logger=INFO,CLA  -Xmx1024m org.apache.hadoop.mapreduce.v2.app.MRAppMaster 1><LOG_DIR>/stdout 2><LOG_DIR>/stderr 
2022-11-24 05:00:37,255 INFO org.apache.hadoop.yarn.server.resourcemanager.security.AMRMTokenSecretManager: Create AMRMToken for ApplicationAttempt: appattempt_1669264800340_0001_000001
2022-11-24 05:00:37,258 INFO org.apache.hadoop.yarn.server.resourcemanager.security.AMRMTokenSecretManager: Creating password for appattempt_1669264800340_0001_000001
2022-11-24 05:00:37,583 INFO org.apache.hadoop.yarn.server.resourcemanager.amlauncher.AMLauncher: Done launching container Container: [ContainerId: container_1669264800340_0001_01_000001, NodeId: ip-172-31-11-48:41289, NodeHttpAddress: ip-172-31-11-48:8042, Resource: <memory:2048, vCores:1>, Priority: 0, Token: Token { kind: ContainerToken, service: 172.31.11.48:41289 }, ] for AM appattempt_1669264800340_0001_000001
2022-11-24 05:00:37,584 INFO org.apache.hadoop.yarn.server.resourcemanager.rmapp.attempt.RMAppAttemptImpl: appattempt_1669264800340_0001_000001 State change from ALLOCATED to LAUNCHED
2022-11-24 05:00:38,116 INFO org.apache.hadoop.yarn.server.resourcemanager.rmcontainer.RMContainerImpl: container_1669264800340_0001_01_000001 Container Transitioned from ACQUIRED to RUNNING
2022-11-24 05:00:41,771 INFO SecurityLogger.org.apache.hadoop.ipc.Server: Auth successful for appattempt_1669264800340_0001_000001 (auth:SIMPLE)
2022-11-24 05:00:41,779 INFO org.apache.hadoop.yarn.server.resourcemanager.ApplicationMasterService: AM registration appattempt_1669264800340_0001_000001
2022-11-24 05:00:41,781 INFO org.apache.hadoop.yarn.server.resourcemanager.rmapp.attempt.RMAppAttemptImpl: appattempt_1669264800340_0001_000001 State change from LAUNCHED to RUNNING
2022-11-24 05:00:41,781 INFO org.apache.hadoop.yarn.server.resourcemanager.rmapp.RMAppImpl: application_1669264800340_0001 State change from ACCEPTED to RUNNING
2022-11-24 05:00:41,782 INFO org.apache.hadoop.yarn.server.resourcemanager.RMAuditLogger: USER=ubuntu	IP=172.31.11.48	OPERATION=Register App Master	TARGET=ApplicationMasterService	RESULT=SUCCESS	APPID=application_1669264800340_0001	APPATTEMPTID=appattempt_1669264800340_0001_000001
2022-11-24 05:00:43,133 INFO org.apache.hadoop.yarn.server.resourcemanager.rmcontainer.RMContainerImpl: container_1669264800340_0001_01_000002 Container Transitioned from NEW to ALLOCATED
2022-11-24 05:00:43,133 INFO org.apache.hadoop.yarn.server.resourcemanager.RMAuditLogger: USER=ubuntu	OPERATION=AM Allocated Container	TARGET=SchedulerApp	RESULT=SUCCESS	APPID=application_1669264800340_0001	CONTAINERID=container_1669264800340_0001_01_000002
2022-11-24 05:00:43,133 INFO org.apache.hadoop.yarn.server.resourcemanager.scheduler.SchedulerNode: Assigned container container_1669264800340_0001_01_000002 of capacity <memory:1024, vCores:1> on host ip-172-31-11-48:41289, which has 2 containers, <memory:3072, vCores:2> used and <memory:5120, vCores:6> available after allocation
2022-11-24 05:00:43,133 INFO org.apache.hadoop.yarn.server.resourcemanager.scheduler.capacity.LeafQueue: assignedContainer application attempt=appattempt_1669264800340_0001_000001 container=Container: [ContainerId: container_1669264800340_0001_01_000002, NodeId: ip-172-31-11-48:41289, NodeHttpAddress: ip-172-31-11-48:8042, Resource: <memory:1024, vCores:1>, Priority: 20, Token: null, ] queue=default: capacity=1.0, absoluteCapacity=1.0, usedResources=<memory:2048, vCores:1>, usedCapacity=0.083333336, absoluteUsedCapacity=0.083333336, numApps=1, numContainers=1 clusterResource=<memory:24576, vCores:24>
2022-11-24 05:00:43,133 INFO org.apache.hadoop.yarn.server.resourcemanager.scheduler.capacity.ParentQueue: Re-sorting assigned queue: root.default stats: default: capacity=1.0, absoluteCapacity=1.0, usedResources=<memory:3072, vCores:2>, usedCapacity=0.125, absoluteUsedCapacity=0.125, numApps=1, numContainers=2
2022-11-24 05:00:43,133 INFO org.apache.hadoop.yarn.server.resourcemanager.scheduler.capacity.ParentQueue: assignedContainer queue=root usedCapacity=0.125 absoluteUsedCapacity=0.125 used=<memory:3072, vCores:2> cluster=<memory:24576, vCores:24>
2022-11-24 05:00:43,916 INFO org.apache.hadoop.yarn.server.resourcemanager.security.NMTokenSecretManagerInRM: Sending NMToken for nodeId : ip-172-31-11-48:41289 for container : container_1669264800340_0001_01_000002
2022-11-24 05:00:43,919 INFO org.apache.hadoop.yarn.server.resourcemanager.rmcontainer.RMContainerImpl: container_1669264800340_0001_01_000002 Container Transitioned from ALLOCATED to ACQUIRED
2022-11-24 05:00:44,138 INFO org.apache.hadoop.yarn.server.resourcemanager.rmcontainer.RMContainerImpl: container_1669264800340_0001_01_000002 Container Transitioned from ACQUIRED to RUNNING
2022-11-24 05:00:44,935 INFO org.apache.hadoop.yarn.server.resourcemanager.scheduler.AppSchedulingInfo: checking for deactivate... 
2022-11-24 05:00:49,157 INFO org.apache.hadoop.yarn.server.resourcemanager.rmcontainer.RMContainerImpl: container_1669264800340_0001_01_000003 Container Transitioned from NEW to ALLOCATED
2022-11-24 05:00:49,157 INFO org.apache.hadoop.yarn.server.resourcemanager.RMAuditLogger: USER=ubuntu	OPERATION=AM Allocated Container	TARGET=SchedulerApp	RESULT=SUCCESS	APPID=application_1669264800340_0001	CONTAINERID=container_1669264800340_0001_01_000003
2022-11-24 05:00:49,157 INFO org.apache.hadoop.yarn.server.resourcemanager.scheduler.SchedulerNode: Assigned container container_1669264800340_0001_01_000003 of capacity <memory:1024, vCores:1> on host ip-172-31-0-65.ec2.internal:46455, which has 1 containers, <memory:1024, vCores:1> used and <memory:7168, vCores:7> available after allocation
2022-11-24 05:00:49,157 INFO org.apache.hadoop.yarn.server.resourcemanager.scheduler.capacity.LeafQueue: assignedContainer application attempt=appattempt_1669264800340_0001_000001 container=Container: [ContainerId: container_1669264800340_0001_01_000003, NodeId: ip-172-31-0-65.ec2.internal:46455, NodeHttpAddress: ip-172-31-0-65.ec2.internal:8042, Resource: <memory:1024, vCores:1>, Priority: 10, Token: null, ] queue=default: capacity=1.0, absoluteCapacity=1.0, usedResources=<memory:3072, vCores:2>, usedCapacity=0.125, absoluteUsedCapacity=0.125, numApps=1, numContainers=2 clusterResource=<memory:24576, vCores:24>
2022-11-24 05:00:49,157 INFO org.apache.hadoop.yarn.server.resourcemanager.scheduler.capacity.ParentQueue: Re-sorting assigned queue: root.default stats: default: capacity=1.0, absoluteCapacity=1.0, usedResources=<memory:4096, vCores:3>, usedCapacity=0.16666667, absoluteUsedCapacity=0.16666667, numApps=1, numContainers=3
2022-11-24 05:00:49,157 INFO org.apache.hadoop.yarn.server.resourcemanager.scheduler.capacity.ParentQueue: assignedContainer queue=root usedCapacity=0.16666667 absoluteUsedCapacity=0.16666667 used=<memory:4096, vCores:3> cluster=<memory:24576, vCores:24>
2022-11-24 05:00:49,950 INFO org.apache.hadoop.yarn.server.resourcemanager.security.NMTokenSecretManagerInRM: Sending NMToken for nodeId : ip-172-31-0-65.ec2.internal:46455 for container : container_1669264800340_0001_01_000003
2022-11-24 05:00:49,952 INFO org.apache.hadoop.yarn.server.resourcemanager.rmcontainer.RMContainerImpl: container_1669264800340_0001_01_000003 Container Transitioned from ALLOCATED to ACQUIRED
2022-11-24 05:00:50,168 INFO org.apache.hadoop.yarn.server.resourcemanager.rmcontainer.RMContainerImpl: container_1669264800340_0001_01_000003 Container Transitioned from ACQUIRED to RUNNING
2022-11-24 05:00:50,960 INFO org.apache.hadoop.yarn.server.resourcemanager.scheduler.AppSchedulingInfo: checking for deactivate... 
2022-11-24 05:03:54,474 INFO org.apache.hadoop.yarn.server.resourcemanager.rmcontainer.RMContainerImpl: container_1669264800340_0001_01_000004 Container Transitioned from NEW to ALLOCATED
2022-11-24 05:03:54,474 INFO org.apache.hadoop.yarn.server.resourcemanager.RMAuditLogger: USER=ubuntu	OPERATION=AM Allocated Container	TARGET=SchedulerApp	RESULT=SUCCESS	APPID=application_1669264800340_0001	CONTAINERID=container_1669264800340_0001_01_000004
2022-11-24 05:03:54,474 INFO org.apache.hadoop.yarn.server.resourcemanager.scheduler.SchedulerNode: Assigned container container_1669264800340_0001_01_000004 of capacity <memory:1024, vCores:1> on host ip-172-31-3-214.ec2.internal:33939, which has 1 containers, <memory:1024, vCores:1> used and <memory:7168, vCores:7> available after allocation
2022-11-24 05:03:54,474 INFO org.apache.hadoop.yarn.server.resourcemanager.scheduler.capacity.LeafQueue: assignedContainer application attempt=appattempt_1669264800340_0001_000001 container=Container: [ContainerId: container_1669264800340_0001_01_000004, NodeId: ip-172-31-3-214.ec2.internal:33939, NodeHttpAddress: ip-172-31-3-214.ec2.internal:8042, Resource: <memory:1024, vCores:1>, Priority: 10, Token: null, ] queue=default: capacity=1.0, absoluteCapacity=1.0, usedResources=<memory:4096, vCores:3>, usedCapacity=0.16666667, absoluteUsedCapacity=0.16666667, numApps=1, numContainers=3 clusterResource=<memory:24576, vCores:24>
2022-11-24 05:03:54,474 INFO org.apache.hadoop.yarn.server.resourcemanager.scheduler.capacity.ParentQueue: Re-sorting assigned queue: root.default stats: default: capacity=1.0, absoluteCapacity=1.0, usedResources=<memory:5120, vCores:4>, usedCapacity=0.20833333, absoluteUsedCapacity=0.20833333, numApps=1, numContainers=4
2022-11-24 05:03:54,475 INFO org.apache.hadoop.yarn.server.resourcemanager.scheduler.capacity.ParentQueue: assignedContainer queue=root usedCapacity=0.20833333 absoluteUsedCapacity=0.20833333 used=<memory:5120, vCores:4> cluster=<memory:24576, vCores:24>
2022-11-24 05:03:55,289 INFO org.apache.hadoop.yarn.server.resourcemanager.security.NMTokenSecretManagerInRM: Sending NMToken for nodeId : ip-172-31-3-214.ec2.internal:33939 for container : container_1669264800340_0001_01_000004
2022-11-24 05:03:55,291 INFO org.apache.hadoop.yarn.server.resourcemanager.rmcontainer.RMContainerImpl: container_1669264800340_0001_01_000004 Container Transitioned from ALLOCATED to ACQUIRED
2022-11-24 05:03:56,293 INFO org.apache.hadoop.yarn.server.resourcemanager.scheduler.AppSchedulingInfo: checking for deactivate... 
2022-11-24 05:03:56,483 INFO org.apache.hadoop.yarn.server.resourcemanager.rmcontainer.RMContainerImpl: container_1669264800340_0001_01_000004 Container Transitioned from ACQUIRED to RUNNING
